Workbook
Name \0: #REF!
Name \0: #REF!
Name \a: #REF!
Name \a: #REF!
Name \B: #REF!
Name \B: #REF!
Name \c: #N/A
Name \D: #REF!
Name \DD: #REF!
Name \E: #REF!
Name \f: #N/A
Name \G: #REF!
Name \H: #REF!
Name \I: #REF!
Name \J: #REF!
Name \K: #REF!
Name \l: #N/A
Name \m: #N/A
Name \N: #REF!
Name \O: #REF!
Name \P: #REF!
Name \q: #N/A
Name \r: #N/A
Name \S: #REF!
Name \t: #N/A
Name \U: #REF!
Name \V: #REF!
Name \w: #N/A
Name \X: #REF!
Name \Z: #REF!
Name _________________________vvv1: {"bbtday",#N/A,FALSE,"ban0930";"banksday",#N/A,FALSE,"ban0930";"compday",#N/A,FALSE,"ban0930"}
Name _________________________vvv1: {"bbtday",#N/A,FALSE,"ban0930";"banksday",#N/A,FALSE,"ban0930";"compday",#N/A,FALSE,"ban0930"}
Name _________________________vvv1: {"bbtday",#N/A,FALSE,"ban0930";"banksday",#N/A,FALSE,"ban0930";"compday",#N/A,FALSE,"ban0930"}
Name _________________________vvv1: {"bbtday",#N/A,FALSE,"ban0930";"banksday",#N/A,FALSE,"ban0930";"compday",#N/A,FALSE,"ban0930"}
Name _________________________x1: {"compweek",#N/A,FALSE,"ban0930";"bankweek",#N/A,FALSE,"ban0930"}
Name _________________________x1: {"compweek",#N/A,FALSE,"ban0930";"bankweek",#N/A,FALSE,"ban0930"}
Name _________________________x1: {"compweek",#N/A,FALSE,"ban0930";"bankweek",#N/A,FALSE,"ban0930"}
Name _________________________x1: {"compweek",#N/A,FALSE,"ban0930";"bankweek",#N/A,FALSE,"ban0930"}
Name _________________________y1: {"bbtday",#N/A,FALSE,"ban0930";"banksday",#N/A,FALSE,"ban0930";"compday",#N/A,FALSE,"ban0930"}
Name _________________________y1: {"bbtday",#N/A,FALSE,"ban0930";"banksday",#N/A,FALSE,"ban0930";"compday",#N/A,FALSE,"ban0930"}
Name _________________________y1: {"bbtday",#N/A,FALSE,"ban0930";"banksday",#N/A,FALSE,"ban0930";"compday",#N/A,FALSE,"ban0930"}
Name _________________________y1: {"bbtday",#N/A,FALSE,"ban0930";"banksday",#N/A,FALSE,"ban0930";"compday",#N/A,FALSE,"ban0930"}
Name ________________________vvv1: {"bbtday",#N/A,FALSE,"ban0930";"banksday",#N/A,FALSE,"ban0930";"compday",#N/A,FALSE,"ban0930"}
Name ________________________vvv1: {"bbtday",#N/A,FALSE,"ban0930";"banksday",#N/A,FALSE,"ban0930";"compday",#N/A,FALSE,"ban0930"}
Name ________________________vvv1: {"bbtday",#N/A,FALSE,"ban0930";"banksday",#N/A,FALSE,"ban0930";"compday",#N/A,FALSE,"ban0930"}
Name ________________________vvv1: {"bbtday",#N/A,FALSE,"ban0930";"banksday",#N/A,FALSE,"ban0930";"compday",#N/A,FALSE,"ban0930"}
Name ________________________x1: {"compweek",#N/A,FALSE,"ban0930";"bankweek",#N/A,FALSE,"ban0930"}
Name ________________________x1: {"compweek",#N/A,FALSE,"ban0930";"bankweek",#N/A,FALSE,"ban0930"}
Name ________________________x1: {"compweek",#N/A,FALSE,"ban0930";"bankweek",#N/A,FALSE,"ban0930"}
Name ________________________x1: {"compweek",#N/A,FALSE,"ban0930";"bankweek",#N/A,FALSE,"ban0930"}
Name ________________________y1: {"bbtday",#N/A,FALSE,"ban0930";"banksday",#N/A,FALSE,"ban0930";"compday",#N/A,FALSE,"ban0930"}
Name ________________________y1: {"bbtday",#N/A,FALSE,"ban0930";"banksday",#N/A,FALSE,"ban0930";"compday",#N/A,FALSE,"ban0930"}
Name ________________________y1: {"bbtday",#N/A,FALSE,"ban0930";"banksday",#N/A,FALSE,"ban0930";"compday",#N/A,FALSE,"ban0930"}
Name ________________________y1: {"bbtday",#N/A,FALSE,"ban0930";"banksday",#N/A,FALSE,"ban0930";"compday",#N/A,FALSE,"ban0930"}
Name _______________________vvv1: {"bbtday",#N/A,FALSE,"ban0930";"banksday",#N/A,FALSE,"ban0930";"compday",#N/A,FALSE,"ban0930"}
Name _______________________vvv1: {"bbtday",#N/A,FALSE,"ban0930";"banksday",#N/A,FALSE,"ban0930";"compday",#N/A,FALSE,"ban0930"}
Name _______________________vvv1: {"bbtday",#N/A,FALSE,"ban0930";"banksday",#N/A,FALSE,"ban0930";"compday",#N/A,FALSE,"ban0930"}
Name _______________________vvv1: {"bbtday",#N/A,FALSE,"ban0930";"banksday",#N/A,FALSE,"ban0930";"compday",#N/A,FALSE,"ban0930"}
Name _______________________x1: {"compweek",#N/A,FALSE,"ban0930";"bankweek",#N/A,FALSE,"ban0930"}
Name _______________________x1: {"compweek",#N/A,FALSE,"ban0930";"bankweek",#N/A,FALSE,"ban0930"}

Sheet Capital Structure
D3: Bingo Industries | L3: DRAFT
D4: Capital Structure | L4: CONFIDENTIAL
D5: Data as of December 31, 2025
D6: (A$ millions)
D8: AUD to USD conversion | E8: 0.7
D9: SOFR / Libor | E9: 0.0434
D10: TLB Hedge % | E10: 0.55
D11: Swap Rate | E11: 0.0524
E13: Face | F13: Leverage | G13: Interest | H13: Effective | I13: Annual | K13: Credit | L13: Trading | P13: Effective | R13: Quarterly | S13: FY'25
D14: Description | E14: Value | F14: (Face) | G14: Rate | H14: Rate(1) | I14: Interest | J14: Maturity | K14: Rating | L14: Price | O14: Spread | P14: Rate | R14: Amort. | S14: Balances
D16: AUD RCF (A$75mm)(2) | E16: 29 | F16: =SUM($E$16:E16)/$E$27 -> 0.28199967 | G16: NA | H16: NA | I16: 0 | J16: 46217 | K16: Caa2/CCC+ | L16: =Pricing!E12 -> 67.75
D17: AUD United Asset Financing | E17: 2.671 | F17: =SUM($E$16:E17)/$E$27 -> 0.30797281 | G17: NA | H17: NA | I17: 0 | J17: 46948 | K17: Caa2/CCC+ | L17: NA
D18: $325 A$mm AUD Term Loan B First Lien (3) | E18: 311 | F18: =SUM($E$16:E18)/$E$27 -> 3.3321762 | G18: 350 | H18: =P18 -> 0.0641 | I18: =H18*E18 -> 19.9351 | J18: 46948 | K18: Caa2/CCC+ | L18: =Pricing!F12 -> 68.5 | O18: =G18/10000 -> 0.035 | P18: =$E$10*$E$11+(1-$E$10)*($E$9+O18) -> 0.0641 | R18: =(2.3*E18)/SUM($E$18:$E$20) -> 0.75853659 | S18: 312.813
D19: $100 A$mm AUD DDTL First Lien | E19: 96 | F19: =SUM($E$16:E19)/$E$27 -> 4.2656923 | G19: 350 | H19: =P19 -> 0.0641 | I19: =H19*E19 -> 6.1536 | J19: 46948 | K19: Caa2/CCC+ | L19: =Pricing!H12 -> 68.5 | O19: =G19/10000 -> 0.035 | P19: =$E$10*$E$11+(1-$E$10)*($E$9+O19) -> 0.0641 | R19: =(2.3*E19)/SUM($E$18:$E$20) -> 0.23414634 | S19: 96.75
D20: $375mm USD Term Loan B First Lien (3) | E20: 536 | F20: =SUM($E$16:E20)/$E$27 -> 9.4778241 | G20: 350 | H20: =P20 -> 0.0641 | I20: =H20*E20 -> 34.3576 | J20: 46948 | K20: Caa2/CCC+ | L20: =Pricing!G12 -> 67.75 | O20: =G20/10000 -> 0.035 | P20: =$E$10*$E$11+(1-$E$10)*($E$9+O20) -> 0.0641 | R20: =(2.3*E20)/SUM($E$18:$E$20) -> 1.3073171 | S20: 360.938
D21: SHL DDTL (A$100mm)(4) | E21: 51.2 | F21: =SUM($E$16:E21)/$E$27 -> 9.9756994 | G21: PIK | H21: 0.13 | I21: 0 | J21: 49188 | K21: Caa2/CCC+ | L21: NA
D22: Total Debt | E22: =SUM(E16:E21) -> 1025.871 | F22: =E22/E27 -> 9.9756994 | I22: =SUM(I16:I21) -> 60.4463 | K22: Caa2/CCC+
D23: Less: Cash and Equivalents(2) | E23: =-E35 -> -52
D24: Net Debt | E24: =SUM(E22:E23) -> 973.871 | F24: =E24/$E$27 -> 9.4700448
D26: Memo:
D27: LTM 2Q'26 Adj EBITDA | E27: =SUM(Historicals!U84:X84) -> 102.837
D29: Current Liquidity
D30: RCF Capacity | E30: 75
D31: Less: Outstanding Borrowings | E31: =-E16 -> -29
D32: Less: Covenant Trigger(5) | E32: -45
D33: RCF Availability (Pre-Covenant Trigger) | E33: =SUM(E30:E32) -> 1
D34: Plus: Remaining SHL DDTL (A$100mm) | E34: 60
D35: Plus: Cash and Equivalents(2) | E35: 52
D36: Total Liquidity | E36: =SUM(E33:E35) -> 113

Sheet Historicals
D3: ='Capital Structure'!D3 -> Bingo Industries | AD3: DRAFT
D4: Spread Financials | AD4: CONFIDENTIAL
D5: Data as of 2Q'26
D6: ($ millions)
D9: Start | F9: 44287 | G9: =EOMONTH(F9,2)+1 -> 44378 | H9: =EOMONTH(G9,2)+1 -> 44470 | I9: =EOMONTH(H9,2)+1 -> 44562 | J9: =EOMONTH(I9,2)+1 -> 44652 | K9: =EOMONTH(J9,2)+1 -> 44743 | L9: =EOMONTH(K9,2)+1 -> 44835 | M9: =EOMONTH(L9,2)+1 -> 44927 | N9: =EOMONTH(M9,2)+1 -> 45017 | ... X9: =EOMONTH(W9,2)+1 -> 45931 | Z9: 44562 | AA9: =EOMONTH(Z9,12) -> 44957 | AB9: =EOMONTH(AA9,12) -> 45322 | AC9: =EOMONTH(AB9,12) -> 45688 | AD9: =EOMONTH(AC9,12) -> 46053
D10: End | F10: =EOMONTH(F9,2) -> 44377 | G10: =EOMONTH(F10,3) -> 44469 | H10: =EOMONTH(G10,3) -> 44561 | I10: =EOMONTH(H10,3) -> 44651 | J10: =EOMONTH(I10,3) -> 44742 | K10: =EOMONTH(J10,3) -> 44834 | L10: =EOMONTH(K10,3) -> 44926 | M10: =EOMONTH(L10,3) -> 45016 | N10: =EOMONTH(M10,3) -> 45107 | ... X10: =EOMONTH(W10,3) -> 46022 | Z10: 44926 | AA10: =EOMONTH(Z10,12) -> 45291 | AB10: =EOMONTH(AA10,12) -> 45657 | AC10: =EOMONTH(AB10,12) -> 46022 | AD10: =EOMONTH(AC10,12) -> 46387
D11: Fiscal Year | F11: 2022 | G11: 2022 | H11: 2022 | I11: 2022 | J11: 2022 | K11: 2023 | L11: 2023 | M11: 2023 | N11: 2023 | O11: 2024 | P11: 2024 | Q11: 2024 | R11: 2024 | S11: 2025 | T11: 2025 | U11: 2025 | V11: 2025 | W11: 2026 | X11: 2026 | Z11: 2022 | AA11: 2023 | AB11: 2024 | AC11: 2025 | AD11: LTM
D12: Quarter | F12: 1Q | G12: 1Q | H12: 2Q | I12: 3Q | J12: 4Q | K12: 1Q | L12: 2Q | M12: 3Q | N12: 4Q | O12: 1Q | P12: 2Q | Q12: 3Q | R12: 4Q | S12: 1Q | T12: 2Q | U12: 3Q | V12: 4Q | W12: 4Q | X12: 4Q
D13: Identifier (Qtr) | F13: =F12&RIGHT(F11,2) -> 1Q22 | G13: =G12&RIGHT(G11,2) -> 1Q22 | H13: =H12&RIGHT(H11,2) -> 2Q22 | I13: =I12&RIGHT(I11,2) -> 3Q22 | J13: =J12&RIGHT(J11,2) -> 4Q22 | K13: =K12&RIGHT(K11,2) -> 1Q23 | L13: =L12&RIGHT(L11,2) -> 2Q23 | M13: =M12&RIGHT(M11,2) -> 3Q23 | ... Y13: =Y12&RIGHT(Y11,2) | Z13: ="FY-"&RIGHT(Z11,2) -> FY-22 | AA13: ="FY-"&RIGHT(AA11,2) -> FY-23 | AB13: ="FY-"&RIGHT(AB11,2) -> FY-24 | AC13: ="FY-"&RIGHT(AC11,2) -> FY-25 | AD13: ="FY-"&RIGHT(AD11,2) -> FY-TM
F15: 4Q21 | G15: 1Q22 | H15: 2Q22 | I15: 3Q22 | J15: 4Q22 | K15: 1Q23 | L15: 2Q23 | M15: 3Q23 | N15: 4Q23 | O15: 1Q24 | P15: 2Q24 | Q15: 3Q24 | R15: 4Q24 | S15: 1Q25 | T15: 2Q25 | U15: 3Q25 | V15: 4Q25 | W15: 1Q26 | X15: 2Q26 | Z15: =Z13 -> FY-22 | AA15: =AA13 -> FY-23 | AB15: =AB13 -> FY-24 | AC15: =AC13 -> FY-25 | AD15: LTM 2Q26
F16: 44377 | G16: 44469 | H16: 44561 | I16: 44651 | J16: 44742 | K16: 44834 | L16: 44926 | M16: 45016 | N16: 45107 | O16: 45199 | P16: 45291 | Q16: 45382 | R16: 45473 | S16: 45565 | T16: 45657 | U16: 45747 | V16: 45838 | W16: =W10 -> 45930 | X16: =X10 -> 46022 | Z16: =J16 -> 44742 | AA16: =N16 -> 45107 | AB16: =R16 -> 45473 | AC16: =V16 -> 45838 | AD16: =X16 -> 46022
C18: x | D18: Income Statement
D20: Revenues
D21: Collections revenue | I21: 49.3 | J21: 54.8 | K21: 66.1 | L21: 70.8 | M21: 72.2 | N21: 74.5 | O21: 85.2 | P21: 77.8 | Q21: 74.8 | R21: 77.5 | S21: 83.8 | T21: 77.9 | AA21: =SUMIF($G$11:$V$11,AA$11,$G21:$V21) -> 283.6 | AB21: =SUMIF($G$11:$V$11,AB$11,$G21:$V21) -> 315.3
D22: Post-Collections revenue | I22: 82.9 | J22: 87.8 | K22: 119.4 | L22: 109.6 | M22: 113.4 | N22: 118.1 | O22: 124.4 | P22: 102.6 | Q22: 102.8 | R22: 115 | S22: 130.1 | T22: 114.5 | AA22: =SUMIF($G$11:$V$11,AA$11,$G22:$V22) -> 460.5 | AB22: =SUMIF($G$11:$V$11,AB$11,$G22:$V22) -> 444.8
D23: Other revenue | I23: 8.6 | J23: 7.9 | K23: 8.9 | L23: 10 | M23: 8.3 | N23: 9.7 | O23: 8.6 | P23: 7.2 | Q23: 6.7 | R23: 4.6 | S23: 4.4 | T23: 3.4 | AA23: =SUMIF($G$11:$V$11,AA$11,$G23:$V23) -> 36.9 | AB23: =SUMIF($G$11:$V$11,AB$11,$G23:$V23) -> 27.1
D24: Eliminations | I24: -26.5 | J24: -15.3 | K24: -33.1 | L24: -34.8 | M24: -31.4 | N24: -34.9 | O24: -35.3 | P24: -31.9 | Q24: -31.2 | R24: -31.9 | S24: -37.9 | T24: -34.3 | AA24: =SUMIF($G$11:$V$11,AA$11,$G24:$V24) -> -134.2 | AB24: =SUMIF($G$11:$V$11,AB$11,$G24:$V24) -> -130.3
D25: Total Revenues | G25: 70.474 | H25: 125.6 | I25: =SUM(I21:I24) -> 114.3 | J25: =SUM(J21:J24) -> 135.2 | K25: =SUM(K21:K24) -> 161.3 | L25: =SUM(L21:L24) -> 155.6 | M25: =SUM(M21:M24) -> 162.5 | N25: =SUM(N21:N24) -> 167.4 | O25: =SUM(O21:O24) -> 182.9 | P25: =SUM(P21:P24) -> 155.7 | ... T25: =SUM(T21:T24) -> 161.5 | U25: 157.698 | V25: =AC25-SUM(S25:U25) -> 176.267 | W25: 144.874 | X25: 138.06 | Z25: =SUMIF($G$11:$S$11,Z$11,$G25:$T25) -> 445.574 | AA25: =SUMIF($G$11:$S$11,AA$11,$G25:$T25) -> 646.8 | AB25: =SUMIF($G$11:$S$11,AB$11,$G25:$T25) -> 656.9 | AC25: 675.865 | AD25: =SUM(U25:X25) -> 616.899
D26: Post-Collections % of Total | I26: =I22/SUM(I21:I22) -> 0.62708018 | J26: =J22/SUM(J21:J22) -> 0.61570827 | K26: =K22/SUM(K21:K22) -> 0.64366577 | L26: =L22/SUM(L21:L22) -> 0.6075388 | M26: =M22/SUM(M21:M22) -> 0.61099138 | N26: =N22/SUM(N21:N22) -> 0.61318795 | O26: =O22/SUM(O21:O22) -> 0.59351145 | P26: =P22/SUM(P21:P22) -> 0.56873614 | ... T26: =T22/SUM(T21:T22) -> 0.59511435 | AG26: =191.3-91.6 -> 99.7
D27: Check: Segment Sum | I27: 114.3 | J27: 135.2 | K27: 161.3 | L27: 155.6 | M27: 162.5 | N27: 167.4 | O27: 182.9 | P27: 155.7 | Q27: 153.1 | R27: 165.2 | S27: 180.4 | T27: 161.5 | W27: 144.874 | X27: 138.06 | AA27: 646.8 | AB27: 656.9 | AC27: 675.865
I28: =I25-I27 -> 0 | J28: =J25-J27 -> 0 | K28: =K25-K27 -> 0 | L28: =L25-L27 -> 0 | M28: =M25-M27 -> 0 | N28: =N25-N27 -> 0 | O28: =O25-O27 -> 0 | P28: =P25-P27 -> 0 | ... T28: =T25-T27 -> 0 | W28: =W25-W27 -> 0 | X28: =X25-X27 -> 0 | AA28: =AA25-AA27 -> 0 | AB28: =AB25-AB27 -> 0 | AC28: =SUM(R28:V28) -> 0
D30: Tipping & Transportation Costs | G30: -27.671 | H30: -48.853 | I30: -46.599 | J30: -61.344 | K30: -71.517 | L30: -62.521 | M30: -70.753 | N30: -76.695 | O30: -74.914 | P30: -63.685 | Q30: -62.419 | R30: -71.246 | S30: -77.513 | T30: -67.586 | U30: -70.76 | V30: -84.672 | W30: -50.818 | X30: -50.318 | Z30: =SUMIF($G$11:$X$11,Z$11,$G30:$X30) -> -184.467 | AA30: =SUMIF($G$11:$X$11,AA$11,$G30:$X30) -> -281.486 | AB30: =SUMIF($G$11:$X$11,AB$11,$G30:$X30) -> -272.264 | AC30: =SUMIF($G$11:$X$11,AC$11,$G30:$X30) -> -300.531 | AD30: =SUM(U30:X30) -> -256.568
D31: Property expenses | G31: -1.389 | H31: -2.774 | I31: -2.513 | J31: -3.433 | K31: -3.461 | L31: -3.71 | M31: -4.089 | N31: -4.224 | O31: -3.644 | P31: -3.628 | Q31: -4.208 | R31: -4.871 | S31: -4.045 | T31: -3.781 | U31: -4.529 | V31: -5.233 | W31: -4.502 | X31: -4.239 | Z31: =SUMIF($G$11:$X$11,Z$11,$G31:$X31) -> -10.109 | AA31: =SUMIF($G$11:$X$11,AA$11,$G31:$X31) -> -15.484 | AB31: =SUMIF($G$11:$X$11,AB$11,$G31:$X31) -> -16.351 | AC31: =SUMIF($G$11:$X$11,AC$11,$G31:$X31) -> -17.588 | AD31: =SUM(U31:X31) -> -18.503
D32: Lender Deck COGS Adjustment | G32: 0 | H32: 0 | I32: 0.733 | J32: 0 | K32: 1.697 | L32: 2.348 | M32: 0.519 | N32: 7.906 | O32: -0.624 | P32: -0.603 | Q32: 0.562 | R32: 2.18 | S32: 0.9 | T32: 1.5 | U32: 0 | V32: -1.1 | W32: 1.6 | X32: 1.2 | Z32: =SUMIF($G$11:$X$11,Z$11,$G32:$X32) -> 0.733 | AA32: =SUMIF($G$11:$X$11,AA$11,$G32:$X32) -> 12.47 | AB32: =SUMIF($G$11:$X$11,AB$11,$G32:$X32) -> 1.515 | AC32: =SUMIF($G$11:$X$11,AC$11,$G32:$X32) -> 1.3 | AD32: =SUM(U32:X32) -> 1.7
D33: Cost of goods sold | G33: =SUM(G30:G32) -> -29.06 | H33: =SUM(H30:H32) -> -51.627 | I33: =SUM(I30:I32) -> -48.379 | J33: =SUM(J30:J32) -> -64.777 | K33: =SUM(K30:K32) -> -73.281 | L33: =SUM(L30:L32) -> -63.883 | M33: =SUM(M30:M32) -> -74.323 | N33: =SUM(N30:N32) -> -73.013 | ... U33: =SUM(U30:U32) -> -75.289 | V33: =AC33-SUM(S33:U33) -> -91.005 | W33: =SUM(W30:W32) -> -53.72 | X33: =SUM(X30:X32) -> -53.357 | Z33: =SUM(Z30:Z32) -> -193.843 | AA33: =SUM(AA30:AA32) -> -284.5 | AB33: =SUM(AB30:AB32) -> -287.1 | AC33: =SUM(AC30:AC32) -> -316.819 | AD33: =SUM(U33:X33) -> -273.371
D35: Gross Profit | G35: =SUM(G33,G25) -> 41.414 | H35: =SUM(H33,H25) -> 73.973 | I35: =SUM(I33,I25) -> 65.921 | J35: =SUM(J33,J25) -> 70.423 | K35: =SUM(K33,K25) -> 88.019 | L35: =SUM(L33,L25) -> 91.717 | M35: =SUM(M33,M25) -> 88.177 | N35: =SUM(N33,N25) -> 94.387 | ... U35: =SUM(U33,U25) -> 82.409 | V35: =AC35-SUM(S35:U35) -> 85.262 | W35: =SUM(W33,W25) -> 91.154 | X35: =SUM(X33,X25) -> 84.703 | Z35: =SUM(Z33,Z25) -> 251.731 | AA35: =SUM(AA33,AA25) -> 362.3 | AB35: =SUM(AB33,AB25) -> 369.8 | AC35: =SUM(AC33,AC25) -> 359.046 | AD35: =SUM(U35:X35) -> 343.528
D36: Check: Lender Deck | G36: 63.907 | H36: =H35 -> 73.973 | I36: 65.921 | J36: =J35 -> 70.423 | K36: 88.019 | L36: 91.717 | M36: 88.177 | N36: 94.387 | O36: 103.718 | P36: 87.784 | Q36: 87.035 | R36: 91.263 | S36: =191.3-91.6 -> 99.7 | T36: 91.6 | U36: =U35 -> 82.409 | V36: 93.1 | W36: =175.9-84.7 -> 91.2 | X36: 84.7 | Z36: =SUMIF($G$11:$S$11,Z$11,$G36:$S36) -> 274.224 | AA36: =SUMIF($G$11:$S$11,AA$11,$G36:$S36) -> 362.3 | AB36: =SUMIF($G$11:$S$11,AB$11,$G36:$S36) -> 369.8 | AC36: =SUM(S36:V36) -> 366.809 | AD36: =SUM(U36:X36) -> 351.409
G37: =G35-G36 -> -22.493 | I37: =I35-I36 -> 0 | K37: =K35-K36 -> 0 | L37: =L35-L36 -> 0 | M37: =M35-M36 -> 0 | N37: =N35-N36 -> 0 | O37: =O35-O36 -> 0 | P37: =P35-P36 -> 0 | Q37: =Q35-Q36 -> 0 | R37: =R35-R36 -> 0 | ... T37: =T35-T36 -> 0.033 | W37: =W35-W36 -> -0.046 | X37: =X35-X36 -> 0.003 | Z37: =Z35-Z36 -> -22.493 | AA37: =AA35-AA36 -> 0 | AB37: =AB35-AB36 -> 0 | AC37: =SUM(R37:V37) -> 0.075
D38: Gross Profit Margin | G38: =G35 / G25 -> 0.58764935 | H38: =H35 / H25 -> 0.58895701 | I38: =I35 / I25 -> 0.57673666 | J38: =J35 / J25 -> 0.52088018 | K38: =K35 / K25 -> 0.54568506 | L38: =L35 / L25 -> 0.58944087 | M38: =M35 / M25 -> 0.54262769 | N38: =N35 / N25 -> 0.5638411 | ... X38: =X35 / X25 -> 0.61352311 | Z38: =Z35 / Z25 -> 0.56495891 | AA38: =AA35 / AA25 -> 0.56014224 | AB38: =AB35 / AB25 -> 0.56294718 | AC38: =AC35 / AC25 -> 0.53123923
D40: Trucks and machinery costs | G40: -4.217 | H40: -10.364 | I40: -8.318 | J40: -8.736 | K40: -10.721 | L40: -11.56 | M40: -12.005 | N40: -11.298 | O40: -11.595 | P40: -11.306 | Q40: -11.433 | R40: -11.841 | S40: -13.411 | T40: -11.538 | U40: -11.76 | V40: -12.206 | W40: -12.601 | X40: -12.166 | Z40: =SUMIF($G$11:$X$11,Z$11,$G40:$X40) -> -31.635 | AA40: =SUMIF($G$11:$X$11,AA$11,$G40:$X40) -> -45.584 | AB40: =SUMIF($G$11:$X$11,AB$11,$G40:$X40) -> -46.175 | AC40: =SUMIF($G$11:$X$11,AC$11,$G40:$X40) -> -48.915 | AD40: =SUM(U40:X40) -> -48.733
D41: Administrative expenses | G41: -0.908 | H41: -1.153 | I41: -1.121 | J41: -3.179 | K41: -0.843 | L41: 0.601 | M41: -1.937 | N41: -9.295 | O41: -3.046 | P41: -2.452 | Q41: -2.959 | R41: 6.322 | S41: -3.322 | T41: -2.864 | U41: -3.056 | V41: -4.424 | W41: -1.924 | X41: -3.124 | Z41: =SUMIF($G$11:$X$11,Z$11,$G41:$X41) -> -6.361 | AA41: =SUMIF($G$11:$X$11,AA$11,$G41:$X41) -> -11.474 | AB41: =SUMIF($G$11:$X$11,AB$11,$G41:$X41) -> -2.135 | AC41: =SUMIF($G$11:$X$11,AC$11,$G41:$X41) -> -13.666 | AD41: =SUM(U41:X41) -> -12.528
D42: Employee benefits expenses | G42: -19.499 | H42: -36.769 | I42: -36.53 | J42: -39.573 | K42: -41.608 | L42: -42.826 | M42: -42.352 | N42: -42.906 | O42: -45.1 | P42: -43.02 | Q42: -42.241 | R42: -46.434 | S42: -46.05 | T42: -45.626 | U42: -42.259 | V42: -43.492 | W42: -43.489 | X42: -40.737 | Z42: =SUMIF($G$11:$X$11,Z$11,$G42:$X42) -> -132.371 | AA42: =SUMIF($G$11:$X$11,AA$11,$G42:$X42) -> -169.692 | AB42: =SUMIF($G$11:$X$11,AB$11,$G42:$X42) -> -176.795 | AC42: =SUMIF($G$11:$X$11,AC$11,$G42:$X42) -> -177.427 | AD42: =SUM(U42:X42) -> -169.977
D43: Interest income | G43: 0.12 | H43: 0.199 | I43: 0.171 | J43: 0.779 | K43: 0.557 | L43: 15.9 | M43: 0.703 | N43: -14.263 | O43: 1.041 | P43: 0.837 | Q43: 0.638 | R43: 0.941 | S43: 0.364 | T43: 0.55 | U43: 0.182 | V43: 0.328 | W43: 0 | X43: 0.129 | Z43: =SUMIF($G$11:$X$11,Z$11,$G43:$X43) -> 1.269 | AA43: =SUMIF($G$11:$X$11,AA$11,$G43:$X43) -> 2.897 | AB43: =SUMIF($G$11:$X$11,AB$11,$G43:$X43) -> 3.457 | AC43: =SUMIF($G$11:$X$11,AC$11,$G43:$X43) -> 1.424 | AD43: =SUM(U43:X43) -> 0.639
D44: Acquisition expenses | G44: -23.4 | H44: -4.922 | I44: -1.205 | J44: -21.451 | K44: -0.162 | L44: 0.081 | M44: 0.08 | N44: 0.001 | O44: 0 | P44: 0 | Q44: 0 | R44: 0 | S44: 0 | T44: 0 | U44: 0 | V44: 0 | W44: 0 | X44: 0 | Z44: =SUMIF($G$11:$X$11,Z$11,$G44:$X44) -> -50.978 | AA44: =SUMIF($G$11:$X$11,AA$11,$G44:$X44) -> -8.6736174e-19 | AB44: =SUMIF($G$11:$X$11,AB$11,$G44:$X44) -> 0 | AC44: =SUMIF($G$11:$X$11,AC$11,$G44:$X44) -> 0 | AD44: =SUM(U44:X44) -> 0
D45: Oth. income/(expenses) | G45: -0.795 | H45: -11.573 | I45: -8.075 | J45: 16.632 | K45: -9.673 | L45: -13.139 | M45: -8.075 | N45: 17.799 | O45: -10.463 | P45: -7.069 | Q45: -4.316 | R45: 8.723 | S45: -9.936 | T45: -5.327 | U45: -0.169 | V45: -10.582 | W45: -6.136 | X45: -6.056 | Z45: =SUMIF($G$11:$X$11,Z$11,$G45:$X45) -> -3.811 | AA45: =SUMIF($G$11:$X$11,AA$11,$G45:$X45) -> -13.088 | AB45: =SUMIF($G$11:$X$11,AB$11,$G45:$X45) -> -13.125 | AC45: =SUMIF($G$11:$X$11,AC$11,$G45:$X45) -> -26.014 | AD45: =SUM(U45:X45) -> -22.943
D46: Lender Deck COGS Adjustment | G46: =-G32 -> 0 | H46: =-H32 -> 0 | I46: =-I32 -> -0.733 | J46: =-J32 -> 0 | K46: =-K32 -> -1.697 | L46: =-L32 -> -2.348 | M46: =-M32 -> -0.519 | N46: =-N32 -> -7.906 | ... X46: =-X32 -> -1.2 | Z46: =SUMIF($G$11:$X$11,Z$11,$G46:$X46) -> -0.733 | AA46: =SUMIF($G$11:$X$11,AA$11,$G46:$X46) -> -12.47 | AB46: =SUMIF($G$11:$X$11,AB$11,$G46:$X46) -> -1.515 | AC46: =SUMIF($G$11:$X$11,AC$11,$G46:$X46) -> -1.3 | AD46: =SUM(U46:X46) -> -1.7
D47: EBITDA | G47: =SUM(G40:G46,G35) -> -7.285 | H47: =SUM(H40:H46,H35) -> 9.391 | I47: =SUM(I40:I46,I35) -> 10.11 | J47: =SUM(J40:J46,J35) -> 14.895 | K47: =SUM(K40:K46,K35) -> 23.872 | L47: =SUM(L40:L46,L35) -> 38.426 | M47: =SUM(M40:M46,M35) -> 24.072 | N47: =SUM(N40:N46,N35) -> 26.519 | ... X47: =SUM(X40:X46,X35) -> 21.549 | Z47: =SUM(Z40:Z46,Z35) -> 27.111 | AA47: =SUM(AA40:AA46,AA35) -> 112.889 | AB47: =SUM(AB40:AB46,AB35) -> 133.512 | AC47: =SUM(AC40:AC46,AC35) -> 93.148 | AD47: =SUM(U47:X47) -> 88.286
D48: EBITDA Margin | G48: =G47 / G25 -> -0.10337146 | H48: =H47 / H25 -> 0.074769108 | I48: =I47 / I25 -> 0.088451444 | J48: =J47 / J25 -> 0.11017012 | K48: =K47 / K25 -> 0.14799752 | L48: =L47 / L25 -> 0.24695373 | M48: =M47 / M25 -> 0.14813538 | N48: =N47 / N25 -> 0.15841697 | ... X48: =X47 / X25 -> 0.15608431 | Z48: =Z47 / Z25 -> 0.060845112 | AA48: =AA47 / AA25 -> 0.17453463 | AB48: =AB47 / AB$25 -> 0.20324555 | AC48: =AC47 / AC25 -> 0.13782042
D50: Impairment Loss on Intangibles | G50: 0 | H50: 0 | I50: 0 | J50: -155 | K50: 0 | L50: 0 | M50: 0 | N50: -385 | O50: 0 | P50: 0 | Q50: 0 | R50: -160 | S50: 0 | T50: 0 | U50: 0 | V50: 0 | X50: 0 | Z50: =SUMIF($G$11:$X$11,Z$11,$G50:$X50) -> -155 | AA50: =SUMIF($G$11:$X$11,AA$11,$G50:$X50) -> -385 | AB50: =SUMIF($G$11:$X$11,AB$11,$G50:$X50) -> -160 | AC50: =SUMIF($G$11:$X$11,AC$11,$G50:$X50) -> 0 | AD50: =SUM(U50:X50) -> 0
D51: Net finance costs | G51: -9.214 | H51: -12.924 | I51: -13.99 | J51: -64.132 | K51: -30.063 | L51: -42.145 | M51: -38.428 | N51: -41.045 | O51: -43.832 | P51: -45.464 | Q51: -46.343 | R51: -47.332 | S51: -48.358 | T51: 9.771 | U51: -25.391 | V51: -22.76 | W51: -21.516 | X51: -20.359 | Z51: =SUMIF($G$11:$X$11,Z$11,$G51:$X51) -> -100.26 | AA51: =SUMIF($G$11:$X$11,AA$11,$G51:$X51) -> -151.681 | AB51: =SUMIF($G$11:$X$11,AB$11,$G51:$X51) -> -182.971 | AC51: =SUMIF($G$11:$X$11,AC$11,$G51:$X51) -> -86.738 | AD51: =SUM(U51:X51) -> -90.026
...

Sheet O1
D3: ='Capital Structure'!D3 -> Bingo Industries | K3: DRAFT
D4: Income Statement Output | K4: CONFIDENTIAL
D5: Data as of 2Q'26
D6: ($ millions)
F7: Year Ended | J7: Quarter Ended
F8: 2023 | G8: =F8+1 -> 2024 | H8: =G8+1 -> 2025 | I8: LTM | J8: =Historicals!T15 -> 2Q25 | K8: =Historicals!X15 -> 2Q26
F9: =Historicals!$AA$16 -> 45107 | G9: =Historicals!$AB$16 -> 45473 | H9: =Historicals!$AC$16 -> 45838 | I9: =Historicals!$AD$16 -> 46022 | J9: =Historicals!$T$16 -> 45657 | K9: =Historicals!$X$16 -> 46022
D11: Revenues
D12: Collections revenue | F12: =INDEX(Historicals!$Z$21:$AD$92,MATCH($D12,Historicals!$D$21:$D$92,0),MATCH(F$8,Historicals!$Z$11:$AD$11,0)) -> 283.6 | G12: =INDEX(Historicals!$Z$21:$AD$92,MATCH($D12,Historicals!$D$21:$D$92,0),MATCH(G$8,Historicals!$Z$11:$AD$11,0)) -> 315.3 | J12: =INDEX(Historicals!$F$21:$X$92,MATCH($D16,Historicals!$D$21:$D$92,0),MATCH(J$8,Historicals!$F$15:$X$15,0)) -> 161.5
D13: Post-Collections revenue | F13: =INDEX(Historicals!$Z$21:$AD$92,MATCH($D13,Historicals!$D$21:$D$92,0),MATCH(F$8,Historicals!$Z$11:$AD$11,0)) -> 460.5 | G13: =INDEX(Historicals!$Z$21:$AD$92,MATCH($D13,Historicals!$D$21:$D$92,0),MATCH(G$8,Historicals!$Z$11:$AD$11,0)) -> 444.8 | J13: =INDEX(Historicals!$F$21:$X$92,MATCH($D13,Historicals!$D$21:$D$92,0),MATCH(J$8,Historicals!$F$15:$X$15,0)) -> 114.5
D14: Other revenue | F14: =INDEX(Historicals!$Z$21:$AD$92,MATCH($D14,Historicals!$D$21:$D$92,0),MATCH(F$8,Historicals!$Z$11:$AD$11,0)) -> 36.9 | G14: =INDEX(Historicals!$Z$21:$AD$92,MATCH($D14,Historicals!$D$21:$D$92,0),MATCH(G$8,Historicals!$Z$11:$AD$11,0)) -> 27.1 | J14: =INDEX(Historicals!$F$21:$X$92,MATCH($D14,Historicals!$D$21:$D$92,0),MATCH(J$8,Historicals!$F$15:$X$15,0)) -> 3.4
D15: Eliminations | F15: =INDEX(Historicals!$Z$21:$AD$92,MATCH($D15,Historicals!$D$21:$D$92,0),MATCH(F$8,Historicals!$Z$11:$AD$11,0)) -> -134.2 | G15: =INDEX(Historicals!$Z$21:$AD$92,MATCH($D15,Historicals!$D$21:$D$92,0),MATCH(G$8,Historicals!$Z$11:$AD$11,0)) -> -130.3 | J15: =INDEX(Historicals!$F$21:$X$92,MATCH($D15,Historicals!$D$21:$D$92,0),MATCH(J$8,Historicals!$F$15:$X$15,0)) -> -34.3
D16: Total Revenues | F16: =INDEX(Historicals!$Z$21:$AD$92,MATCH($D16,Historicals!$D$21:$D$92,0),MATCH(F$8,Historicals!$Z$11:$AD$11,0)) -> 646.8 | G16: =INDEX(Historicals!$Z$21:$AD$92,MATCH($D16,Historicals!$D$21:$D$92,0),MATCH(G$8,Historicals!$Z$11:$AD$11,0)) -> 656.9 | H16: =INDEX(Historicals!$Z$21:$AD$92,MATCH($D16,Historicals!$D$21:$D$92,0),MATCH(H$8,Historicals!$Z$11:$AD$11,0)) -> 675.865 | I16: =INDEX(Historicals!$Z$21:$AD$92,MATCH($D16,Historicals!$D$21:$D$92,0),MATCH(I$8,Historicals!$Z$11:$AD$11,0)) -> 616.899 | J16: =INDEX(Historicals!$F$21:$X$92,MATCH($D16,Historicals!$D$21:$D$92,0),MATCH(J$8,Historicals!$F$15:$X$15,0)) -> 161.5 | K16: =INDEX(Historicals!$F$21:$X$92,MATCH($D16,Historicals!$D$21:$D$92,0),MATCH(K$8,Historicals!$F$15:$X$15,0)) -> 138.06
D17: Cost of goods sold | F17: =INDEX(Historicals!$Z$21:$AD$92,MATCH($D17,Historicals!$D$21:$D$92,0),MATCH(F$8,Historicals!$Z$11:$AD$11,0)) -> -284.5 | G17: =INDEX(Historicals!$Z$21:$AD$92,MATCH($D17,Historicals!$D$21:$D$92,0),MATCH(G$8,Historicals!$Z$11:$AD$11,0)) -> -287.1 | H17: =INDEX(Historicals!$Z$21:$AD$92,MATCH($D17,Historicals!$D$21:$D$92,0),MATCH(H$8,Historicals!$Z$11:$AD$11,0)) -> -316.819 | I17: =INDEX(Historicals!$Z$21:$AD$92,MATCH($D17,Historicals!$D$21:$D$92,0),MATCH(I$8,Historicals!$Z$11:$AD$11,0)) -> -273.371 | J17: =INDEX(Historicals!$F$21:$X$92,MATCH($D17,Historicals!$D$21:$D$92,0),MATCH(J$8,Historicals!$F$15:$X$15,0)) -> -69.867 | K17: =INDEX(Historicals!$F$21:$X$92,MATCH($D17,Historicals!$D$21:$D$92,0),MATCH(K$8,Historicals!$F$15:$X$15,0)) -> -53.357
D18: Gross profit | F18: =INDEX(Historicals!$Z$21:$AD$92,MATCH($D18,Historicals!$D$21:$D$92,0),MATCH(F$8,Historicals!$Z$11:$AD$11,0)) -> 362.3 | G18: =INDEX(Historicals!$Z$21:$AD$92,MATCH($D18,Historicals!$D$21:$D$92,0),MATCH(G$8,Historicals!$Z$11:$AD$11,0)) -> 369.8 | H18: =INDEX(Historicals!$Z$21:$AD$92,MATCH($D18,Historicals!$D$21:$D$92,0),MATCH(H$8,Historicals!$Z$11:$AD$11,0)) -> 359.046 | I18: =INDEX(Historicals!$Z$21:$AD$92,MATCH($D18,Historicals!$D$21:$D$92,0),MATCH(I$8,Historicals!$Z$11:$AD$11,0)) -> 343.528 | J18: =INDEX(Historicals!$F$21:$X$92,MATCH($D18,Historicals!$D$21:$D$92,0),MATCH(J$8,Historicals!$F$15:$X$15,0)) -> 91.633 | K18: =INDEX(Historicals!$F$21:$X$92,MATCH($D18,Historicals!$D$21:$D$92,0),MATCH(K$8,Historicals!$F$15:$X$15,0)) -> 84.703
D19: Check: | F19: =ROUND(SUM(F16:F17,-F18),1) -> 0 | G19: =ROUND(SUM(G16:G17,-G18),1) -> 0 | H19: =ROUND(SUM(H16:H17,-H18),1) -> 0 | I19: =ROUND(SUM(I16:I17,-I18),1) -> 0 | J19: =ROUND(SUM(J16:J17,-J18),1) -> 0 | K19: =ROUND(SUM(K16:K17,-K18),1) -> 0
D21: Interest income | F21: =INDEX(Historicals!$Z$21:$AD$92,MATCH($D21,Historicals!$D$21:$D$92,0),MATCH(F$8,Historicals!$Z$11:$AD$11,0)) -> 2.897 | G21: =INDEX(Historicals!$Z$21:$AD$92,MATCH($D21,Historicals!$D$21:$D$92,0),MATCH(G$8,Historicals!$Z$11:$AD$11,0)) -> 3.457 | H21: =INDEX(Historicals!$Z$21:$AD$92,MATCH($D21,Historicals!$D$21:$D$92,0),MATCH(H$8,Historicals!$Z$11:$AD$11,0)) -> 1.424 | I21: =INDEX(Historicals!$Z$21:$AD$92,MATCH($D21,Historicals!$D$21:$D$92,0),MATCH(I$8,Historicals!$Z$11:$AD$11,0)) -> 0.639 | J21: =INDEX(Historicals!$F$21:$X$92,MATCH($D21,Historicals!$D$21:$D$92,0),MATCH(J$8,Historicals!$F$15:$X$15,0)) -> 0.55 | K21: =INDEX(Historicals!$F$21:$X$92,MATCH($D21,Historicals!$D$21:$D$92,0),MATCH(K$8,Historicals!$F$15:$X$15,0)) -> 0.129
D22: Employee benefits expenses | F22: =INDEX(Historicals!$Z$21:$AD$92,MATCH($D22,Historicals!$D$21:$D$92,0),MATCH(F$8,Historicals!$Z$11:$AD$11,0)) -> -169.692 | G22: =INDEX(Historicals!$Z$21:$AD$92,MATCH($D22,Historicals!$D$21:$D$92,0),MATCH(G$8,Historicals!$Z$11:$AD$11,0)) -> -176.795 | H22: =INDEX(Historicals!$Z$21:$AD$92,MATCH($D22,Historicals!$D$21:$D$92,0),MATCH(H$8,Historicals!$Z$11:$AD$11,0)) -> -177.427 | I22: =INDEX(Historicals!$Z$21:$AD$92,MATCH($D22,Historicals!$D$21:$D$92,0),MATCH(I$8,Historicals!$Z$11:$AD$11,0)) -> -169.977 | J22: =INDEX(Historicals!$F$21:$X$92,MATCH($D22,Historicals!$D$21:$D$92,0),MATCH(J$8,Historicals!$F$15:$X$15,0)) -> -45.626 | K22: =INDEX(Historicals!$F$21:$X$92,MATCH($D22,Historicals!$D$21:$D$92,0),MATCH(K$8,Historicals!$F$15:$X$15,0)) -> -40.737
D23: Trucks and machinery costs | F23: =INDEX(Historicals!$Z$21:$AD$92,MATCH($D23,Historicals!$D$21:$D$92,0),MATCH(F$8,Historicals!$Z$11:$AD$11,0)) -> -45.584 | G23: =INDEX(Historicals!$Z$21:$AD$92,MATCH($D23,Historicals!$D$21:$D$92,0),MATCH(G$8,Historicals!$Z$11:$AD$11,0)) -> -46.175 | H23: =INDEX(Historicals!$Z$21:$AD$92,MATCH($D23,Historicals!$D$21:$D$92,0),MATCH(H$8,Historicals!$Z$11:$AD$11,0)) -> -48.915 | I23: =INDEX(Historicals!$Z$21:$AD$92,MATCH($D23,Historicals!$D$21:$D$92,0),MATCH(I$8,Historicals!$Z$11:$AD$11,0)) -> -48.733 | J23: =INDEX(Historicals!$F$21:$X$92,MATCH($D23,Historicals!$D$21:$D$92,0),MATCH(J$8,Historicals!$F$15:$X$15,0)) -> -11.538 | K23: =INDEX(Historicals!$F$21:$X$92,MATCH($D23,Historicals!$D$21:$D$92,0),MATCH(K$8,Historicals!$F$15:$X$15,0)) -> -12.166
D24: Administrative expenses | F24: =INDEX(Historicals!$Z$21:$AD$92,MATCH($D24,Historicals!$D$21:$D$92,0),MATCH(F$8,Historicals!$Z$11:$AD$11,0)) -> -11.474 | G24: =INDEX(Historicals!$Z$21:$AD$92,MATCH($D24,Historicals!$D$21:$D$92,0),MATCH(G$8,Historicals!$Z$11:$AD$11,0)) -> -2.135 | H24: =INDEX(Historicals!$Z$21:$AD$92,MATCH($D24,Historicals!$D$21:$D$92,0),MATCH(H$8,Historicals!$Z$11:$AD$11,0)) -> -13.666 | I24: =INDEX(Historicals!$Z$21:$AD$92,MATCH($D24,Historicals!$D$21:$D$92,0),MATCH(I$8,Historicals!$Z$11:$AD$11,0)) -> -12.528 | J24: =INDEX(Historicals!$F$21:$X$92,MATCH($D24,Historicals!$D$21:$D$92,0),MATCH(J$8,Historicals!$F$15:$X$15,0)) -> -2.864 | K24: =INDEX(Historicals!$F$21:$X$92,MATCH($D24,Historicals!$D$21:$D$92,0),MATCH(K$8,Historicals!$F$15:$X$15,0)) -> -3.124
D25: Acquisition expenses | F25: =INDEX(Historicals!$Z$21:$AD$92,MATCH($D25,Historicals!$D$21:$D$92,0),MATCH(F$8,Historicals!$Z$11:$AD$11,0)) -> -8.6736174e-19 | G25: =INDEX(Historicals!$Z$21:$AD$92,MATCH($D25,Historicals!$D$21:$D$92,0),MATCH(G$8,Historicals!$Z$11:$AD$11,0)) -> 0 | H25: =INDEX(Historicals!$Z$21:$AD$92,MATCH($D25,Historicals!$D$21:$D$92,0),MATCH(H$8,Historicals!$Z$11:$AD$11,0)) -> 0 | I25: =INDEX(Historicals!$Z$21:$AD$92,MATCH($D25,Historicals!$D$21:$D$92,0),MATCH(I$8,Historicals!$Z$11:$AD$11,0)) -> 0 | J25: =INDEX(Historicals!$F$21:$X$92,MATCH($D25,Historicals!$D$21:$D$92,0),MATCH(J$8,Historicals!$F$15:$X$15,0)) -> 0 | K25: =INDEX(Historicals!$F$21:$X$92,MATCH($D25,Historicals!$D$21:$D$92,0),MATCH(K$8,Historicals!$F$15:$X$15,0)) -> 0
D26: Oth. income/(expenses) | F26: =INDEX(Historicals!$Z$21:$AD$84,MATCH($D26,Historicals!$D$21:$D$84,0),MATCH(F$8,Historicals!$Z$11:$AD$11,0)) -INDEX(Historicals!$Z$21:$AD$84,MATCH("Lender Deck COGS Adjustment",Historicals!$D$21:$D$84,0),MATCH(F$8,Historicals!$Z$11:$AD$11,0)) -> -25.558 | G26: =INDEX(Historicals!$Z$21:$AD$84,MATCH($D26,Historicals!$D$21:$D$84,0),MATCH(G$8,Historicals!$Z$11:$AD$11,0)) -INDEX(Historicals!$Z$21:$AD$84,MATCH("Lender Deck COGS Adjustment",Historicals!$D$21:$D$84,0),MATCH(G$8,Historicals!$Z$11:$AD$11,0)) -> -14.64 | H26: =INDEX(Historicals!$Z$21:$AD$84,MATCH($D26,Historicals!$D$21:$D$84,0),MATCH(H$8,Historicals!$Z$11:$AD$11,0)) -INDEX(Historicals!$Z$21:$AD$84,MATCH("Lender Deck COGS Adjustment",Historicals!$D$21:$D$84,0),MATCH(H$8,Historicals!$Z$11:$AD$11,0)) -> -27.314 | I26: =INDEX(Historicals!$Z$21:$AD$84,MATCH($D26,Historicals!$D$21:$D$84,0),MATCH(I$8,Historicals!$Z$11:$AD$11,0)) -INDEX(Historicals!$Z$21:$AD$84,MATCH("Lender Deck COGS Adjustment",Historicals!$D$21:$D$84,0),MATCH(I$8,Historicals!$Z$11:$AD$11,0)) -> -24.643 | J26: =INDEX(Historicals!$F$21:$X$84,MATCH($D26,Historicals!$D$21:$D$84,0),MATCH(J$8,Historicals!$F$15:$X$15,0)) -INDEX(Historicals!$F$21:$X$84,MATCH("Lender Deck COGS Adjustment",Historicals!$D$21:$D$84,0),MATCH(J$8,Historicals!$F$15:$X$15,0)) -> -6.827 | K26: =INDEX(Historicals!$F$21:$X$84,MATCH($D26,Historicals!$D$21:$D$84,0),MATCH(K$8,Historicals!$F$15:$X$15,0)) -INDEX(Historicals!$F$21:$X$84,MATCH("Lender Deck COGS Adjustment",Historicals!$D$21:$D$84,0),MATCH(K$8,Historicals!$F$15:$X$15,0)) -> -7.256
D27: EBITDA | F27: =INDEX(Historicals!$Z$21:$AD$92,MATCH($D27,Historicals!$D$21:$D$92,0),MATCH(F$8,Historicals!$Z$11:$AD$11,0)) -> 112.889 | G27: =INDEX(Historicals!$Z$21:$AD$92,MATCH($D27,Historicals!$D$21:$D$92,0),MATCH(G$8,Historicals!$Z$11:$AD$11,0)) -> 133.512 | H27: =INDEX(Historicals!$Z$21:$AD$92,MATCH($D27,Historicals!$D$21:$D$92,0),MATCH(H$8,Historicals!$Z$11:$AD$11,0)) -> 93.148 | I27: =INDEX(Historicals!$Z$21:$AD$92,MATCH($D27,Historicals!$D$21:$D$92,0),MATCH(I$8,Historicals!$Z$11:$AD$11,0)) -> 88.286 | J27: =INDEX(Historicals!$F$21:$X$92,MATCH($D27,Historicals!$D$21:$D$92,0),MATCH(J$8,Historicals!$F$15:$X$15,0)) -> 25.328 | K27: =INDEX(Historicals!$F$21:$X$92,MATCH($D27,Historicals!$D$21:$D$92,0),MATCH(K$8,Historicals!$F$15:$X$15,0)) -> 21.549
D28: Check: | F28: =ROUND(SUM(F21:F26,F18,-F27),0) -> 0 | G28: =ROUND(SUM(G21:G26,G18,-G27),0) -> 0 | H28: =ROUND(SUM(H21:H26,H18,-H27),0) -> 0 | I28: =ROUND(SUM(I21:I26,I18,-I27),0) -> 0 | J28: =ROUND(SUM(J21:J26,J18,-J27),0) -> 0 | K28: =ROUND(SUM(K21:K26,K18,-K27),0) -> 0
D30: Acquisition Costs | F30: =INDEX(Historicals!$Z$21:$AD$92,MATCH($D30,Historicals!$D$21:$D$92,0),MATCH(F$8,Historicals!$Z$11:$AD$11,0)) -> -0.9 | G30: =INDEX(Historicals!$Z$21:$AD$92,MATCH($D30,Historicals!$D$21:$D$92,0),MATCH(G$8,Historicals!$Z$11:$AD$11,0)) -> -0.3 | H30: =INDEX(Historicals!$Z$21:$AD$92,MATCH($D30,Historicals!$D$21:$D$92,0),MATCH(H$8,Historicals!$Z$11:$AD$11,0)) -> -0.6 | J30: =INDEX(Historicals!$F$21:$X$92,MATCH($D30,Historicals!$D$21:$D$92,0),MATCH(J$8,Historicals!$F$15:$X$15,0)) -> -0.9
D31: Litigation costs | F31: =INDEX(Historicals!$Z$21:$AD$92,MATCH($D31,Historicals!$D$21:$D$92,0),MATCH(F$8,Historicals!$Z$11:$AD$11,0)) -> 8.2 | G31: =INDEX(Historicals!$Z$21:$AD$92,MATCH($D31,Historicals!$D$21:$D$92,0),MATCH(G$8,Historicals!$Z$11:$AD$11,0)) -> -22.1 | H31: =INDEX(Historicals!$Z$21:$AD$92,MATCH($D31,Historicals!$D$21:$D$92,0),MATCH(H$8,Historicals!$Z$11:$AD$11,0)) -> 0 | J31: =INDEX(Historicals!$F$21:$X$92,MATCH($D31,Historicals!$D$21:$D$92,0),MATCH(J$8,Historicals!$F$15:$X$15,0)) -> 0
D32: Other Costs | F32: =INDEX(Historicals!$Z$21:$AD$92,MATCH($D32,Historicals!$D$21:$D$92,0),MATCH(F$8,Historicals!$Z$11:$AD$11,0)) -> 11.2 | G32: =INDEX(Historicals!$Z$21:$AD$92,MATCH($D32,Historicals!$D$21:$D$92,0),MATCH(G$8,Historicals!$Z$11:$AD$11,0)) -> 7.8 | H32: =INDEX(Historicals!$Z$21:$AD$92,MATCH($D32,Historicals!$D$21:$D$92,0),MATCH(H$8,Historicals!$Z$11:$AD$11,0)) -> 18.5 | J32: =INDEX(Historicals!$F$21:$X$92,MATCH($D32,Historicals!$D$21:$D$92,0),MATCH(J$8,Historicals!$F$15:$X$15,0)) -> 5.4
D33: Adjusted EBITDA | F33: =INDEX(Historicals!$Z$21:$AD$92,MATCH($D33,Historicals!$D$21:$D$92,0),MATCH(F$8,Historicals!$Z$11:$AD$11,0)) -> 131.389 | G33: =INDEX(Historicals!$Z$21:$AD$92,MATCH($D33,Historicals!$D$21:$D$92,0),MATCH(G$8,Historicals!$Z$11:$AD$11,0)) -> 118.912 | H33: =INDEX(Historicals!$Z$21:$AD$92,MATCH($D33,Historicals!$D$21:$D$92,0),MATCH(H$8,Historicals!$Z$11:$AD$11,0)) -> 111.048 | I33: =INDEX(Historicals!$Z$21:$AD$92,MATCH($D33,Historicals!$D$21:$D$92,0),MATCH(I$8,Historicals!$Z$11:$AD$11,0)) -> 102.837 | J33: =INDEX(Historicals!$F$21:$X$92,MATCH($D33,Historicals!$D$21:$D$92,0),MATCH(J$8,Historicals!$F$15:$X$15,0)) -> 29.828 | K33: =INDEX(Historicals!$F$21:$X$92,MATCH($D33,Historicals!$D$21:$D$92,0),MATCH(K$8,Historicals!$F$15:$X$15,0)) -> 23.4
D34: Check: | F34: =ROUND(SUM(F30:F32,F27,-F33),0) -> 0 | G34: =ROUND(SUM(G30:G32,G27,-G33),0) -> 0 | H34: =ROUND(SUM(H30:H32,H27,-H33),0) -> 0 | J34: =ROUND(SUM(J30:J32,J27,-J33),0) -> 0
D36: Free Cash Flow Build
D37: Reported EBITDA | F37: =INDEX(Historicals!$Z$284:$AD$292,MATCH($D37,Historicals!$D$284:$D$292,0),MATCH(F$8,Historicals!$Z$11:$AD$11,0)) -> 112.889 | G37: =INDEX(Historicals!$Z$284:$AD$292,MATCH($D37,Historicals!$D$284:$D$292,0),MATCH(G$8,Historicals!$Z$11:$AD$11,0)) -> 133.512 | H37: =INDEX(Historicals!$Z$284:$AD$292,MATCH($D37,Historicals!$D$284:$D$292,0),MATCH(H$8,Historicals!$Z$11:$AD$11,0)) -> 93.148 | I37: =INDEX(Historicals!$Z$284:$AD$292,MATCH($D37,Historicals!$D$284:$D$292,0),MATCH(I$8,Historicals!$Z$11:$AD$11,0)) -> 88.286 | J37: =INDEX(Historicals!$F$284:$X$292,MATCH($D37,Historicals!$D$284:$D$292,0),MATCH(J$8,Historicals!$F$15:$X$15,0)) -> 25.328 | K37: =INDEX(Historicals!$F$284:$X$292,MATCH($D37,Historicals!$D$284:$D$292,0),MATCH(K$8,Historicals!$F$15:$X$15,0)) -> 21.549
D38: Est. Change in NWC | F38: =INDEX(Historicals!$Z$284:$AD$292,MATCH($D38,Historicals!$D$284:$D$292,0),MATCH(F$8,Historicals!$Z$11:$AD$11,0)) -> 6.2528 | G38: =INDEX(Historicals!$Z$284:$AD$292,MATCH($D38,Historicals!$D$284:$D$292,0),MATCH(G$8,Historicals!$Z$11:$AD$11,0)) -> 11.2678 | H38: =INDEX(Historicals!$Z$284:$AD$292,MATCH($D38,Historicals!$D$284:$D$292,0),MATCH(H$8,Historicals!$Z$11:$AD$11,0)) -> 12.5904 | I38: =INDEX(Historicals!$Z$284:$AD$292,MATCH($D38,Historicals!$D$284:$D$292,0),MATCH(I$8,Historicals!$Z$11:$AD$11,0)) -> 45.5605 | J38: =INDEX(Historicals!$F$284:$X$292,MATCH($D38,Historicals!$D$284:$D$292,0),MATCH(J$8,Historicals!$F$15:$X$15,0)) -> -12.76405 | K38: =INDEX(Historicals!$F$284:$X$292,MATCH($D38,Historicals!$D$284:$D$292,0),MATCH(K$8,Historicals!$F$15:$X$15,0)) -> -1.324
D39: Est. Capex in NWC | F39: =INDEX(Historicals!$Z$284:$AD$292,MATCH($D39,Historicals!$D$284:$D$292,0),MATCH(F$8,Historicals!$Z$11:$AD$11,0)) -> -35.4548 | G39: =INDEX(Historicals!$Z$284:$AD$292,MATCH($D39,Historicals!$D$284:$D$292,0),MATCH(G$8,Historicals!$Z$11:$AD$11,0)) -> -35.4548 | H39: =INDEX(Historicals!$Z$284:$AD$292,MATCH($D39,Historicals!$D$284:$D$292,0),MATCH(H$8,Historicals!$Z$11:$AD$11,0)) -> -17.7274 | I39: =INDEX(Historicals!$Z$284:$AD$292,MATCH($D39,Historicals!$D$284:$D$292,0),MATCH(I$8,Historicals!$Z$11:$AD$11,0)) -> -2.8421709e-14 | J39: =INDEX(Historicals!$F$284:$X$292,MATCH($D39,Historicals!$D$284:$D$292,0),MATCH(J$8,Historicals!$F$15:$X$15,0)) -> -8.8637 | K39: =INDEX(Historicals!$F$284:$X$292,MATCH($D39,Historicals!$D$284:$D$292,0),MATCH(K$8,Historicals!$F$15:$X$15,0)) -> 0
D40: Reported Capital Expenditures | F40: =INDEX(Historicals!$Z$284:$AD$292,MATCH($D40,Historicals!$D$284:$D$292,0),MATCH(F$8,Historicals!$Z$11:$AD$11,0)) -> -85.428 | G40: =INDEX(Historicals!$Z$284:$AD$292,MATCH($D40,Historicals!$D$284:$D$292,0),MATCH(G$8,Historicals!$Z$11:$AD$11,0)) -> -73.773 | H40: =INDEX(Historicals!$Z$284:$AD$292,MATCH($D40,Historicals!$D$284:$D$292,0),MATCH(H$8,Historicals!$Z$11:$AD$11,0)) -> -42.043 | I40: =INDEX(Historicals!$Z$284:$AD$292,MATCH($D40,Historicals!$D$284:$D$292,0),MATCH(I$8,Historicals!$Z$11:$AD$11,0)) -> -23.31 | J40: =INDEX(Historicals!$F$284:$X$292,MATCH($D40,Historicals!$D$284:$D$292,0),MATCH(J$8,Historicals!$F$15:$X$15,0)) -> -10.519 | K40: =INDEX(Historicals!$F$284:$X$292,MATCH($D40,Historicals!$D$284:$D$292,0),MATCH(K$8,Historicals!$F$15:$X$15,0)) -> -3.588
D41: One-Time Items | F41: =INDEX(Historicals!$Z$284:$AD$292,MATCH($D41,Historicals!$D$284:$D$292,0),MATCH(F$8,Historicals!$Z$11:$AD$11,0)) -> 11.343 | G41: =INDEX(Historicals!$Z$284:$AD$292,MATCH($D41,Historicals!$D$284:$D$292,0),MATCH(G$8,Historicals!$Z$11:$AD$11,0)) -> -11.607 | H41: =INDEX(Historicals!$Z$284:$AD$292,MATCH($D41,Historicals!$D$284:$D$292,0),MATCH(H$8,Historicals!$Z$11:$AD$11,0)) -> -25.344 | I41: =INDEX(Historicals!$Z$284:$AD$292,MATCH($D41,Historicals!$D$284:$D$292,0),MATCH(I$8,Historicals!$Z$11:$AD$11,0)) -> -48.4255 | J41: =INDEX(Historicals!$F$284:$X$292,MATCH($D41,Historicals!$D$284:$D$292,0),MATCH(J$8,Historicals!$F$15:$X$15,0)) -> -0.42225 | K41: =INDEX(Historicals!$F$284:$X$292,MATCH($D41,Historicals!$D$284:$D$292,0),MATCH(K$8,Historicals!$F$15:$X$15,0)) -> -4.157
D42: Unlevered Free Cash Flow | F42: =INDEX(Historicals!$Z$284:$AD$292,MATCH($D42,Historicals!$D$284:$D$292,0),MATCH(F$8,Historicals!$Z$11:$AD$11,0)) -> 9.602 | G42: =INDEX(Historicals!$Z$284:$AD$292,MATCH($D42,Historicals!$D$284:$D$292,0),MATCH(G$8,Historicals!$Z$11:$AD$11,0)) -> 23.945 | H42: =INDEX(Historicals!$Z$284:$AD$292,MATCH($D42,Historicals!$D$284:$D$292,0),MATCH(H$8,Historicals!$Z$11:$AD$11,0)) -> 20.624 | I42: =INDEX(Historicals!$Z$284:$AD$292,MATCH($D42,Historicals!$D$284:$D$292,0),MATCH(I$8,Historicals!$Z$11:$AD$11,0)) -> 62.111 | J42: =INDEX(Historicals!$F$284:$X$292,MATCH($D42,Historicals!$D$284:$D$292,0),MATCH(J$8,Historicals!$F$15:$X$15,0)) -> -7.241 | K42: =INDEX(Historicals!$F$284:$X$292,MATCH($D42,Historicals!$D$284:$D$292,0),MATCH(K$8,Historicals!$F$15:$X$15,0)) -> 12.48
D43: Check: | F43: =ROUND(SUM(F37:F41,-F42),0) -> 0 | G43: =ROUND(SUM(G37:G41,-G42),0) -> 0 | H43: =ROUND(SUM(H37:H41,-H42),0) -> 0 | I43: =ROUND(SUM(I37:I41,-I42),0) -> 0 | J43: =ROUND(SUM(J37:J41,-J42),0) -> 0 | K43: =ROUND(SUM(K37:K41,-K42),0) -> 0
D45: Less: Interest Expense (incl. leases) | F45: =INDEX(Historicals!$Z$284:$AD$292,MATCH($D45,Historicals!$D$284:$D$292,0),MATCH(F$8,Historicals!$Z$11:$AD$11,0)) -> -61.787 | G45: =INDEX(Historicals!$Z$284:$AD$292,MATCH($D45,Historicals!$D$284:$D$292,0),MATCH(G$8,Historicals!$Z$11:$AD$11,0)) -> -66.85 | H45: =INDEX(Historicals!$Z$284:$AD$292,MATCH($D45,Historicals!$D$284:$D$292,0),MATCH(H$8,Historicals!$Z$11:$AD$11,0)) -> -61.049 | I45: =INDEX(Historicals!$Z$284:$AD$292,MATCH($D45,Historicals!$D$284:$D$292,0),MATCH(I$8,Historicals!$Z$11:$AD$11,0)) -> -56.246 | J45: =INDEX(Historicals!$F$284:$X$292,MATCH($D45,Historicals!$D$284:$D$292,0),MATCH(J$8,Historicals!$F$15:$X$15,0)) -> -16.868 | K45: =INDEX(Historicals!$F$284:$X$292,MATCH($D45,Historicals!$D$284:$D$292,0),MATCH(K$8,Historicals!$F$15:$X$15,0)) -> -14.815
D46: Less: Mandatory Debt Repayments | F46: =INDEX(Historicals!$Z$284:$AD$292,MATCH($D46,Historicals!$D$284:$D$292,0),MATCH(F$8,Historicals!$Z$11:$AD$11,0)) -> -9.2 | G46: =INDEX(Historicals!$Z$284:$AD$292,MATCH($D46,Historicals!$D$284:$D$292,0),MATCH(G$8,Historicals!$Z$11:$AD$11,0)) -> -9.2 | H46: =INDEX(Historicals!$Z$284:$AD$292,MATCH($D46,Historicals!$D$284:$D$292,0),MATCH(H$8,Historicals!$Z$11:$AD$11,0)) -> -9.2 | I46: =INDEX(Historicals!$Z$284:$AD$292,MATCH($D46,Historicals!$D$284:$D$292,0),MATCH(I$8,Historicals!$Z$11:$AD$11,0)) -> -9.2 | J46: =INDEX(Historicals!$F$284:$X$292,MATCH($D46,Historicals!$D$284:$D$292,0),MATCH(J$8,Historicals!$F$15:$X$15,0)) -> -2.3 | K46: =INDEX(Historicals!$F$284:$X$292,MATCH($D46,Historicals!$D$284:$D$292,0),MATCH(K$8,Historicals!$F$15:$X$15,0)) -> -2.3
D47: Levered Free Cash Flow | F47: =INDEX(Historicals!$Z$284:$AD$292,MATCH($D47,Historicals!$D$284:$D$292,0),MATCH(F$8,Historicals!$Z$11:$AD$11,0)) -> -61.385 | G47: =INDEX(Historicals!$Z$284:$AD$292,MATCH($D47,Historicals!$D$284:$D$292,0),MATCH(G$8,Historicals!$Z$11:$AD$11,0)) -> -52.105 | H47: =INDEX(Historicals!$Z$284:$AD$292,MATCH($D47,Historicals!$D$284:$D$292,0),MATCH(H$8,Historicals!$Z$11:$AD$11,0)) -> -49.625 | I47: =INDEX(Historicals!$Z$284:$AD$292,MATCH($D47,Historicals!$D$284:$D$292,0),MATCH(I$8,Historicals!$Z$11:$AD$11,0)) -> -3.335 | J47: =INDEX(Historicals!$F$284:$X$292,MATCH($D47,Historicals!$D$284:$D$292,0),MATCH(J$8,Historicals!$F$15:$X$15,0)) -> -26.409 | K47: =INDEX(Historicals!$F$284:$X$292,MATCH($D47,Historicals!$D$284:$D$292,0),MATCH(K$8,Historicals!$F$15:$X$15,0)) -> -4.635
...

Sheet O2
D3: ='Capital Structure'!D3 -> Bingo Industries | K3: DRAFT
D4: Statement of Cash Flows Output | K4: CONFIDENTIAL
D5: Data as of 2Q'26
D6: ($ millions)
F7: Year Ended | J7: Quarter Ended
F8: 2023 | G8: =F8+1 -> 2024 | H8: =G8+1 -> 2025 | I8: LTM | J8: ='O1'!J8 -> 2Q25 | K8: ='O1'!K8 -> 2Q26
F9: =Historicals!$AA$16 -> 45107 | G9: =Historicals!$AB$16 -> 45473 | H9: =Historicals!$AC$16 -> 45838 | I9: =Historicals!$AD$16 -> 46022 | J9: =Historicals!$T$16 -> 45657 | K9: =Historicals!$X$16 -> 46022
D11: Net Income (Loss) | F11: =Historicals!AA60 -> -462.201 | G11: =Historicals!AB60 -> -216.059 | H11: =Historicals!AC60 -> -93.257 | I11: =Historicals!AD60 -> -97.403 | J11: =Historicals!T60 -> 8.029 | K11: =Historicals!X60 -> -24.116
D13: Cash Flows From Operations
D14: Plus: Depreciation and amortization | F14: =-Historicals!AA52 -> 105.568 | G14: =-Historicals!AB52 -> 108.669 | H14: =-Historicals!AC52 -> 105.902 | I14: =-Historicals!AD52 -> 105.051 | J14: =-Historicals!T52 -> 26.945 | K14: =-Historicals!X52 -> 28.377
D15: Plus: Financing Costs | F15: =-Historicals!AA51 -> 151.681 | G15: =-Historicals!AB51 -> 182.971 | H15: =-Historicals!AC51 -> 86.738 | I15: =-Historicals!AD51 -> 90.026 | J15: =-Historicals!T51 -> -9.771 | K15: =-Historicals!X51 -> 20.359
D16: Plus: Impairment Expense | F16: =-Historicals!AA50 -> 385 | G16: =-Historicals!AB50 -> 160 | H16: =-Historicals!AC50 -> 0 | I16: =-Historicals!AD50 -> 0 | J16: =-Historicals!T50 -> 0 | K16: =-Historicals!X50 -> 0
D17: Less: Non-Cash Tax Benefits | F17: =-Historicals!AA55 -> -67.756 | G17: =-Historicals!AB55 -> -111.165 | H17: =-Historicals!AC55 -> -21.126 | I17: =-Historicals!AD55 -> -22.499 | J17: =-Historicals!T55 -> -6.29 | K17: =-Historicals!X55 -> -9.281
D18: Less: Gain on Fair Value Hedges, net of tax | F18: =SUM(Historicals!AA58:AA59) -> -0.597 | G18: =SUM(Historicals!AB58:AB59) -> -9.096 | H18: =SUM(Historicals!AC58:AC59) -> -14.891 | I18: =SUM(Historicals!AD58:AD59) -> -13.111 | J18: =SUM(Historicals!T58:T59) -> -6.415 | K18: =SUM(Historicals!X58:X59) -> -6.21
D19: Other Cash items | F19: =F26-SUM(F11,F14:F18,F21:F25) -> -22.9178 | G19: =G26-SUM(G11,G14:G18,G21:G25) -> -28.8698 | H19: =H26-SUM(H11,H14:H18,H21:H25) -> -13.2894 | I19: =I26-SUM(I11,I14:I18,I21:I25) -> -28.5945 | J19: =J26-SUM(J11,J14:J18,J21:J25) -> 3.68305 | K19: =K26-SUM(K11,K14:K18,K21:K25) -> 7.555
D20: Decrease (increase) in:
D21: Adj. Trade and other receivables | F21: =Historicals!AA235 -> -21.129 | G21: =Historicals!AB235 -> -8.65 | H21: =Historicals!AC235 -> 6.943 | I21: =Historicals!AD235 -> 39.7255 | J21: =Historicals!T235 -> -6.77275 | K21: =Historicals!X235 -> -6.391
D22: Inventories | F22: =Historicals!Z259-Historicals!AA259 -> -0.298 | G22: =Historicals!AA259-Historicals!AB259 -> 0.299 | H22: =Historicals!AB259-Historicals!AC259 -> 2.112 | I22: =Historicals!T259-Historicals!AD259 -> 1.133 | J22: =Historicals!U259-Historicals!T259 -> 0.706 | K22: =Historicals!V259-Historicals!X259 -> 1.321
D23: Adj. Other Assets (ex. Derivative Assets) | F23: =Historicals!AA247 -> 2.708 | G23: =Historicals!AB247 -> -1.687 | H23: =Historicals!AC247 -> -20.633 | I23: =Historicals!AD247 -> 5.002 | J23: =Historicals!T247 -> 0.401 | K23: =Historicals!X247 -> 10.585
D24: Increase (decrease) in:
D25: Adj. Trade and other payables | F25: =Historicals!AA255 -> 24.9718 | G25: =Historicals!AB255 -> 21.3058 | H25: =Historicals!AC255 -> 24.1684 | I25: =Historicals!AD255 -> 6.091 | J25: =Historicals!T255 -> -7.2373 | K25: =Historicals!X255 -> -6.131
D26: Net cash flows provided by (used in) operating activities | F26: =Historicals!AA162 -> 95.03 | G26: =Historicals!AB162 -> 97.718 | H26: =Historicals!AC162 -> 62.667 | I26: =Historicals!AD162 -> 85.421 | J26: =Historicals!T162 -> 3.278 | K26: =Historicals!X162 -> 16.068
D27: Check: | F27: =ROUND(SUM(F11:F25,-F26),1) -> 0 | G27: =ROUND(SUM(G11:G25,-G26),1) -> 0 | H27: =ROUND(SUM(H11:H25,-H26),1) -> 0 | I27: =ROUND(SUM(I11:I25,-I26),1) -> 0 | J27: =ROUND(SUM(J11:J25,-J26),1) -> 0 | K27: =ROUND(SUM(K11:K25,-K26),1) -> 0
D29: Cash Flows From Investing
D30: Purchase of property, plant and equipment | F30: =INDEX(Historicals!$Z$159:$AD$195,MATCH($D30,Historicals!$D$159:$D$195,0),MATCH(F$8,Historicals!$Z$11:$AD$11,0)) -> -85.428 | G30: =INDEX(Historicals!$Z$159:$AD$195,MATCH($D30,Historicals!$D$159:$D$195,0),MATCH(G$8,Historicals!$Z$11:$AD$11,0)) -> -73.773 | H30: =INDEX(Historicals!$Z$159:$AD$195,MATCH($D30,Historicals!$D$159:$D$195,0),MATCH(H$8,Historicals!$Z$11:$AD$11,0)) -> -42.043 | I30: =INDEX(Historicals!$Z$159:$AD$195,MATCH($D30,Historicals!$D$159:$D$195,0),MATCH(I$8,Historicals!$Z$11:$AD$11,0)) -> -23.31 | J30: =INDEX(Historicals!$F$159:$X$195,MATCH($D30,Historicals!$D$159:$D$195,0),MATCH(J$8,Historicals!$F$15:$X$15,0)) -> -10.519 | K30: =INDEX(Historicals!$F$159:$X$195,MATCH($D30,Historicals!$D$159:$D$195,0),MATCH(K$8,Historicals!$F$15:$X$15,0)) -> -3.588
D31: Purchase of business | F31: =INDEX(Historicals!$Z$159:$AD$195,MATCH($D31,Historicals!$D$159:$D$195,0),MATCH(F$8,Historicals!$Z$11:$AD$11,0)) -> -21.482 | G31: =INDEX(Historicals!$Z$159:$AD$195,MATCH($D31,Historicals!$D$159:$D$195,0),MATCH(G$8,Historicals!$Z$11:$AD$11,0)) -> -3.607 | H31: =INDEX(Historicals!$Z$159:$AD$195,MATCH($D31,Historicals!$D$159:$D$195,0),MATCH(H$8,Historicals!$Z$11:$AD$11,0)) -> 0 | I31: =INDEX(Historicals!$Z$159:$AD$195,MATCH($D31,Historicals!$D$159:$D$195,0),MATCH(I$8,Historicals!$Z$11:$AD$11,0)) -> 0 | J31: =INDEX(Historicals!$F$159:$X$195,MATCH($D31,Historicals!$D$159:$D$195,0),MATCH(J$8,Historicals!$F$15:$X$15,0)) -> 0 | K31: =INDEX(Historicals!$F$159:$X$195,MATCH($D31,Historicals!$D$159:$D$195,0),MATCH(K$8,Historicals!$F$15:$X$15,0)) -> 0
D32: Purchase of intangible assets | F32: =INDEX(Historicals!$Z$159:$AD$195,MATCH($D32,Historicals!$D$159:$D$195,0),MATCH(F$8,Historicals!$Z$11:$AD$11,0)) -> -7.961 | G32: =INDEX(Historicals!$Z$159:$AD$195,MATCH($D32,Historicals!$D$159:$D$195,0),MATCH(G$8,Historicals!$Z$11:$AD$11,0)) -> -5.876 | H32: =INDEX(Historicals!$Z$159:$AD$195,MATCH($D32,Historicals!$D$159:$D$195,0),MATCH(H$8,Historicals!$Z$11:$AD$11,0)) -> -3.371 | I32: =INDEX(Historicals!$Z$159:$AD$195,MATCH($D32,Historicals!$D$159:$D$195,0),MATCH(I$8,Historicals!$Z$11:$AD$11,0)) -> -2.45 | J32: =INDEX(Historicals!$F$159:$X$195,MATCH($D32,Historicals!$D$159:$D$195,0),MATCH(J$8,Historicals!$F$15:$X$15,0)) -> -0.308 | K32: =INDEX(Historicals!$F$159:$X$195,MATCH($D32,Historicals!$D$159:$D$195,0),MATCH(K$8,Historicals!$F$15:$X$15,0)) -> -0.052
D33: Payments for Land Option | F33: =INDEX(Historicals!$Z$159:$AD$195,MATCH($D33,Historicals!$D$159:$D$195,0),MATCH(F$8,Historicals!$Z$11:$AD$11,0)) -> 0 | G33: =INDEX(Historicals!$Z$159:$AD$195,MATCH($D33,Historicals!$D$159:$D$195,0),MATCH(G$8,Historicals!$Z$11:$AD$11,0)) -> 0 | H33: =INDEX(Historicals!$Z$159:$AD$195,MATCH($D33,Historicals!$D$159:$D$195,0),MATCH(H$8,Historicals!$Z$11:$AD$11,0)) -> -103.39 | I33: =INDEX(Historicals!$Z$159:$AD$195,MATCH($D33,Historicals!$D$159:$D$195,0),MATCH(I$8,Historicals!$Z$11:$AD$11,0)) -> -103.39 | J33: =INDEX(Historicals!$F$159:$X$195,MATCH($D33,Historicals!$D$159:$D$195,0),MATCH(J$8,Historicals!$F$15:$X$15,0)) -> 0 | K33: =INDEX(Historicals!$F$159:$X$195,MATCH($D33,Historicals!$D$159:$D$195,0),MATCH(K$8,Historicals!$F$15:$X$15,0)) -> 0
D34: Proceeds from Disposal of Assets Held For Sale | F34: =INDEX(Historicals!$Z$159:$AD$195,MATCH($D34,Historicals!$D$159:$D$195,0),MATCH(F$8,Historicals!$Z$11:$AD$11,0)) -> 0 | G34: =INDEX(Historicals!$Z$159:$AD$195,MATCH($D34,Historicals!$D$159:$D$195,0),MATCH(G$8,Historicals!$Z$11:$AD$11,0)) -> 0 | H34: =INDEX(Historicals!$Z$159:$AD$195,MATCH($D34,Historicals!$D$159:$D$195,0),MATCH(H$8,Historicals!$Z$11:$AD$11,0)) -> 64.049 | I34: =INDEX(Historicals!$Z$159:$AD$195,MATCH($D34,Historicals!$D$159:$D$195,0),MATCH(I$8,Historicals!$Z$11:$AD$11,0)) -> 64.049 | J34: =INDEX(Historicals!$F$159:$X$195,MATCH($D34,Historicals!$D$159:$D$195,0),MATCH(J$8,Historicals!$F$15:$X$15,0)) -> 0 | K34: =INDEX(Historicals!$F$159:$X$195,MATCH($D34,Historicals!$D$159:$D$195,0),MATCH(K$8,Historicals!$F$15:$X$15,0)) -> 0
D35: Proceeds from sale of non-current assets | F35: =INDEX(Historicals!$Z$159:$AD$195,MATCH($D35,Historicals!$D$159:$D$195,0),MATCH(F$8,Historicals!$Z$11:$AD$11,0)) -> 40.724 | G35: =INDEX(Historicals!$Z$159:$AD$195,MATCH($D35,Historicals!$D$159:$D$195,0),MATCH(G$8,Historicals!$Z$11:$AD$11,0)) -> 1.415 | H35: =INDEX(Historicals!$Z$159:$AD$195,MATCH($D35,Historicals!$D$159:$D$195,0),MATCH(H$8,Historicals!$Z$11:$AD$11,0)) -> 2.549 | I35: =INDEX(Historicals!$Z$159:$AD$195,MATCH($D35,Historicals!$D$159:$D$195,0),MATCH(I$8,Historicals!$Z$11:$AD$11,0)) -> -9.95 | J35: =INDEX(Historicals!$F$159:$X$195,MATCH($D35,Historicals!$D$159:$D$195,0),MATCH(J$8,Historicals!$F$15:$X$15,0)) -> 3.119 | K35: =INDEX(Historicals!$F$159:$X$195,MATCH($D35,Historicals!$D$159:$D$195,0),MATCH(K$8,Historicals!$F$15:$X$15,0)) -> 0
D36: Deposites at call for bank guarantees | F36: =INDEX(Historicals!$Z$159:$AD$195,MATCH($D36,Historicals!$D$159:$D$195,0),MATCH(F$8,Historicals!$Z$11:$AD$11,0)) -> 0 | G36: =INDEX(Historicals!$Z$159:$AD$195,MATCH($D36,Historicals!$D$159:$D$195,0),MATCH(G$8,Historicals!$Z$11:$AD$11,0)) -> 0 | H36: =INDEX(Historicals!$Z$159:$AD$195,MATCH($D36,Historicals!$D$159:$D$195,0),MATCH(H$8,Historicals!$Z$11:$AD$11,0)) -> -0.914 | I36: =INDEX(Historicals!$Z$159:$AD$195,MATCH($D36,Historicals!$D$159:$D$195,0),MATCH(I$8,Historicals!$Z$11:$AD$11,0)) -> -0.914 | J36: =INDEX(Historicals!$F$159:$X$195,MATCH($D36,Historicals!$D$159:$D$195,0),MATCH(J$8,Historicals!$F$15:$X$15,0)) -> 0 | K36: =INDEX(Historicals!$F$159:$X$195,MATCH($D36,Historicals!$D$159:$D$195,0),MATCH(K$8,Historicals!$F$15:$X$15,0)) -> 0
D37: Interest received | F37: =INDEX(Historicals!$Z$159:$AD$195,MATCH($D37,Historicals!$D$159:$D$195,0),MATCH(F$8,Historicals!$Z$11:$AD$11,0)) -> 3.02 | G37: =INDEX(Historicals!$Z$159:$AD$195,MATCH($D37,Historicals!$D$159:$D$195,0),MATCH(G$8,Historicals!$Z$11:$AD$11,0)) -> 3.457 | H37: =INDEX(Historicals!$Z$159:$AD$195,MATCH($D37,Historicals!$D$159:$D$195,0),MATCH(H$8,Historicals!$Z$11:$AD$11,0)) -> 1.424 | I37: =INDEX(Historicals!$Z$159:$AD$195,MATCH($D37,Historicals!$D$159:$D$195,0),MATCH(I$8,Historicals!$Z$11:$AD$11,0)) -> 0.967 | J37: =INDEX(Historicals!$F$159:$X$195,MATCH($D37,Historicals!$D$159:$D$195,0),MATCH(J$8,Historicals!$F$15:$X$15,0)) -> 0.55 | K37: =INDEX(Historicals!$F$159:$X$195,MATCH($D37,Historicals!$D$159:$D$195,0),MATCH(K$8,Historicals!$F$15:$X$15,0)) -> 0.129
D38: Net cash flows provided by (used in) investing activities | F38: =INDEX(Historicals!$Z$159:$AD$195,MATCH($D38,Historicals!$D$159:$D$195,0),MATCH(F$8,Historicals!$Z$11:$AD$11,0)) -> -71.127 | G38: =INDEX(Historicals!$Z$159:$AD$195,MATCH($D38,Historicals!$D$159:$D$195,0),MATCH(G$8,Historicals!$Z$11:$AD$11,0)) -> -78.384 | H38: =INDEX(Historicals!$Z$159:$AD$195,MATCH($D38,Historicals!$D$159:$D$195,0),MATCH(H$8,Historicals!$Z$11:$AD$11,0)) -> -81.696 | I38: =INDEX(Historicals!$Z$159:$AD$195,MATCH($D38,Historicals!$D$159:$D$195,0),MATCH(I$8,Historicals!$Z$11:$AD$11,0)) -> -74.998 | J38: =INDEX(Historicals!$F$159:$X$195,MATCH($D38,Historicals!$D$159:$D$195,0),MATCH(J$8,Historicals!$F$15:$X$15,0)) -> -7.158 | K38: =INDEX(Historicals!$F$159:$X$195,MATCH($D38,Historicals!$D$159:$D$195,0),MATCH(K$8,Historicals!$F$15:$X$15,0)) -> -3.511
D39: Check: | F39: =ROUND(SUM(F30:F37,-F38),1) -> 0 | G39: =ROUND(SUM(G30:G37,-G38),1) -> 0 | H39: =ROUND(SUM(H30:H37,-H38),1) -> 0 | I39: =ROUND(SUM(I30:I37,-I38),1) -> 0 | J39: =ROUND(SUM(J30:J37,-J38),1) -> 0 | K39: =ROUND(SUM(K30:K37,-K38),1) -> 0
D41: Cash Flows From Financing
D42: Proceeds from share issue | F42: =INDEX(Historicals!$Z$159:$AD$195,MATCH($D42,Historicals!$D$159:$D$195,0),MATCH(F$8,Historicals!$Z$11:$AD$11,0)) -> 0 | G42: =INDEX(Historicals!$Z$159:$AD$195,MATCH($D42,Historicals!$D$159:$D$195,0),MATCH(G$8,Historicals!$Z$11:$AD$11,0)) -> 0 | H42: =INDEX(Historicals!$Z$159:$AD$195,MATCH($D42,Historicals!$D$159:$D$195,0),MATCH(H$8,Historicals!$Z$11:$AD$11,0)) -> 0 | I42: =INDEX(Historicals!$Z$159:$AD$195,MATCH($D42,Historicals!$D$159:$D$195,0),MATCH(I$8,Historicals!$Z$11:$AD$11,0)) -> 0 | J42: =INDEX(Historicals!$F$159:$X$195,MATCH($D42,Historicals!$D$159:$D$195,0),MATCH(J$8,Historicals!$F$15:$X$15,0)) -> 0 | K42: =INDEX(Historicals!$F$159:$X$195,MATCH($D42,Historicals!$D$159:$D$195,0),MATCH(K$8,Historicals!$F$15:$X$15,0)) -> 0
D43: (Repayment of) / proceeds from related party loan | F43: =INDEX(Historicals!$Z$159:$AD$195,MATCH($D43,Historicals!$D$159:$D$195,0),MATCH(F$8,Historicals!$Z$11:$AD$11,0)) -> -8.868 | G43: =INDEX(Historicals!$Z$159:$AD$195,MATCH($D43,Historicals!$D$159:$D$195,0),MATCH(G$8,Historicals!$Z$11:$AD$11,0)) -> -1.724 | H43: =INDEX(Historicals!$Z$159:$AD$195,MATCH($D43,Historicals!$D$159:$D$195,0),MATCH(H$8,Historicals!$Z$11:$AD$11,0)) -> 40 | I43: =INDEX(Historicals!$Z$159:$AD$195,MATCH($D43,Historicals!$D$159:$D$195,0),MATCH(I$8,Historicals!$Z$11:$AD$11,0)) -> 45.501 | J43: =INDEX(Historicals!$F$159:$X$195,MATCH($D43,Historicals!$D$159:$D$195,0),MATCH(J$8,Historicals!$F$15:$X$15,0)) -> 0.101 | K43: =INDEX(Historicals!$F$159:$X$195,MATCH($D43,Historicals!$D$159:$D$195,0),MATCH(K$8,Historicals!$F$15:$X$15,0)) -> -0.18
D44: (Repayment of) / proceeds from borrowing | F44: =INDEX(Historicals!$Z$159:$AD$195,MATCH($D44,Historicals!$D$159:$D$195,0),MATCH(F$8,Historicals!$Z$11:$AD$11,0)) -> -11.943 | G44: =INDEX(Historicals!$Z$159:$AD$195,MATCH($D44,Historicals!$D$159:$D$195,0),MATCH(G$8,Historicals!$Z$11:$AD$11,0)) -> -11.077 | H44: =INDEX(Historicals!$Z$159:$AD$195,MATCH($D44,Historicals!$D$159:$D$195,0),MATCH(H$8,Historicals!$Z$11:$AD$11,0)) -> 28.076 | I44: =INDEX(Historicals!$Z$159:$AD$195,MATCH($D44,Historicals!$D$159:$D$195,0),MATCH(I$8,Historicals!$Z$11:$AD$11,0)) -> 4.004 | J44: =INDEX(Historicals!$F$159:$X$195,MATCH($D44,Historicals!$D$159:$D$195,0),MATCH(J$8,Historicals!$F$15:$X$15,0)) -> 27.39 | K44: =INDEX(Historicals!$F$159:$X$195,MATCH($D44,Historicals!$D$159:$D$195,0),MATCH(K$8,Historicals!$F$15:$X$15,0)) -> -2.648
D45: Principal payment for lease liabilities | F45: =INDEX(Historicals!$Z$159:$AD$195,MATCH($D45,Historicals!$D$159:$D$195,0),MATCH(F$8,Historicals!$Z$11:$AD$11,0)) -> -8.436 | G45: =INDEX(Historicals!$Z$159:$AD$195,MATCH($D45,Historicals!$D$159:$D$195,0),MATCH(G$8,Historicals!$Z$11:$AD$11,0)) -> -8.691 | H45: =INDEX(Historicals!$Z$159:$AD$195,MATCH($D45,Historicals!$D$159:$D$195,0),MATCH(H$8,Historicals!$Z$11:$AD$11,0)) -> -14.929 | I45: =INDEX(Historicals!$Z$159:$AD$195,MATCH($D45,Historicals!$D$159:$D$195,0),MATCH(I$8,Historicals!$Z$11:$AD$11,0)) -> -18.237 | J45: =INDEX(Historicals!$F$159:$X$195,MATCH($D45,Historicals!$D$159:$D$195,0),MATCH(J$8,Historicals!$F$15:$X$15,0)) -> -2.487 | K45: =INDEX(Historicals!$F$159:$X$195,MATCH($D45,Historicals!$D$159:$D$195,0),MATCH(K$8,Historicals!$F$15:$X$15,0)) -> -3.631
D46: Debt raising cost | F46: =INDEX(Historicals!$Z$159:$AD$195,MATCH($D46,Historicals!$D$159:$D$195,0),MATCH(F$8,Historicals!$Z$11:$AD$11,0)) -> 0 | G46: =INDEX(Historicals!$Z$159:$AD$195,MATCH($D46,Historicals!$D$159:$D$195,0),MATCH(G$8,Historicals!$Z$11:$AD$11,0)) -> 0 | H46: =INDEX(Historicals!$Z$159:$AD$195,MATCH($D46,Historicals!$D$159:$D$195,0),MATCH(H$8,Historicals!$Z$11:$AD$11,0)) -> 0 | I46: =INDEX(Historicals!$Z$159:$AD$195,MATCH($D46,Historicals!$D$159:$D$195,0),MATCH(I$8,Historicals!$Z$11:$AD$11,0)) -> 0 | J46: =INDEX(Historicals!$F$159:$X$195,MATCH($D46,Historicals!$D$159:$D$195,0),MATCH(J$8,Historicals!$F$15:$X$15,0)) -> 0 | K46: =INDEX(Historicals!$F$159:$X$195,MATCH($D46,Historicals!$D$159:$D$195,0),MATCH(K$8,Historicals!$F$15:$X$15,0)) -> 0
...

Sheet O3
D3: ='Capital Structure'!D3 -> Bingo Industries | G3: DRAFT | K3: =D3 -> Bingo Industries | L3: DRAFT
D4: Charts - Situation Overview | G4: CONFIDENTIAL | K4: Charts - Company Overview | L4: CONFIDENTIAL
D5: Data as of 2Q'26 | K5: Data as of 2Q'26
D6: ($ millions) | K6: ($ millions)
B8: x | D8: Total Revenue & Gross Margin | (A$ Millions) | K8: Revenue (A$ Millions)
B17: x | D17: Adjusted EBITDA Breakdown | (A$ Millions) | K17: Reported EBITDA (A$ Millions)
B26: x | D26: Cumulative Levered Free Cash Flow | (A$ Millions)
K28: Levered Free Cash Flow (A$ Millions)
B34: x | D34: Liquidity Profile | (A$ Millions)
B42: x | D42: Revolving Facility Balance | (A$ Millions)
B50: x | D50: Covenant Adj. EBITDA Headroom | (A$ Millions)
B57: x | D57: Segment Revenues | (A$ Millions)
B67: x | D67: Throughput & Recovery
B76: x | D76: Productivity & Uptime

Sheet Pricing
D3: Bingo Industries | H3: DRAFT
D4: Pricing | H4: CONFIDENTIAL
D5: Data as of March 2, 2026
D6: (A$ millions)
D8: Pulled from Debtwire
