Workbook
Name \0: #REF!
Name \0: #REF!
Name \0: #REF!
Name \a: #REF!
Name \a: #REF!
Name \B: #REF!
Name \B: #REF!
Name \c: #N/A
Name \D: #REF!
Name \DD: #REF!
Name \E: #REF!
Name \f: #N/A
Name \G: #REF!
Name \H: #REF!
Name \I: #REF!
Name \J: #REF!
Name \K: #REF!
Name \l: #N/A
Name \m: #N/A
Name \N: #REF!
Name \O: #REF!
Name \P: #REF!
Name \q: #N/A
Name \r: #N/A
Name \S: #REF!
Name \t: #N/A
Name \U: #REF!
Name \V: #REF!
Name \w: #N/A
Name \X: #REF!
Name \Z: #REF!
Name _________________________vvv1: {"bbtday",#N/A,FALSE,"ban0930";"banksday",#N/A,FALSE,"ban0930";"compday",#N/A,FALSE,"ban0930"}
Name _________________________vvv1: {"bbtday",#N/A,FALSE,"ban0930";"banksday",#N/A,FALSE,"ban0930";"compday",#N/A,FALSE,"ban0930"}
Name _________________________vvv1: {"bbtday",#N/A,FALSE,"ban0930";"banksday",#N/A,FALSE,"ban0930";"compday",#N/A,FALSE,"ban0930"}
Name _________________________x1: {"compweek",#N/A,FALSE,"ban0930";"bankweek",#N/A,FALSE,"ban0930"}
Name _________________________x1: {"compweek",#N/A,FALSE,"ban0930";"bankweek",#N/A,FALSE,"ban0930"}
Name _________________________x1: {"compweek",#N/A,FALSE,"ban0930";"bankweek",#N/A,FALSE,"ban0930"}
Name _________________________y1: {"bbtday",#N/A,FALSE,"ban0930";"banksday",#N/A,FALSE,"ban0930";"compday",#N/A,FALSE,"ban0930"}
Name _________________________y1: {"bbtday",#N/A,FALSE,"ban0930";"banksday",#N/A,FALSE,"ban0930";"compday",#N/A,FALSE,"ban0930"}
Name _________________________y1: {"bbtday",#N/A,FALSE,"ban0930";"banksday",#N/A,FALSE,"ban0930";"compday",#N/A,FALSE,"ban0930"}
Name ________________________vvv1: {"bbtday",#N/A,FALSE,"ban0930";"banksday",#N/A,FALSE,"ban0930";"compday",#N/A,FALSE,"ban0930"}
Name ________________________vvv1: {"bbtday",#N/A,FALSE,"ban0930";"banksday",#N/A,FALSE,"ban0930";"compday",#N/A,FALSE,"ban0930"}
Name ________________________vvv1: {"bbtday",#N/A,FALSE,"ban0930";"banksday",#N/A,FALSE,"ban0930";"compday",#N/A,FALSE,"ban0930"}
Name ________________________x1: {"compweek",#N/A,FALSE,"ban0930";"bankweek",#N/A,FALSE,"ban0930"}
Name ________________________x1: {"compweek",#N/A,FALSE,"ban0930";"bankweek",#N/A,FALSE,"ban0930"}
Name ________________________x1: {"compweek",#N/A,FALSE,"ban0930";"bankweek",#N/A,FALSE,"ban0930"}
Name ________________________y1: {"bbtday",#N/A,FALSE,"ban0930";"banksday",#N/A,FALSE,"ban0930";"compday",#N/A,FALSE,"ban0930"}
Name ________________________y1: {"bbtday",#N/A,FALSE,"ban0930";"banksday",#N/A,FALSE,"ban0930";"compday",#N/A,FALSE,"ban0930"}
Name ________________________y1: {"bbtday",#N/A,FALSE,"ban0930";"banksday",#N/A,FALSE,"ban0930";"compday",#N/A,FALSE,"ban0930"}
Name _______________________vvv1: {"bbtday",#N/A,FALSE,"ban0930";"banksday",#N/A,FALSE,"ban0930";"compday",#N/A,FALSE,"ban0930"}
Name _______________________vvv1: {"bbtday",#N/A,FALSE,"ban0930";"banksday",#N/A,FALSE,"ban0930";"compday",#N/A,FALSE,"ban0930"}
Name _______________________vvv1: {"bbtday",#N/A,FALSE,"ban0930";"banksday",#N/A,FALSE,"ban0930";"compday",#N/A,FALSE,"ban0930"}
Name _______________________x1: {"compweek",#N/A,FALSE,"ban0930";"bankweek",#N/A,FALSE,"ban0930"}
Name _______________________x1: {"compweek",#N/A,FALSE,"ban0930";"bankweek",#N/A,FALSE,"ban0930"}
Name _______________________x1: {"compweek",#N/A,FALSE,"ban0930";"bankweek",#N/A,FALSE,"ban0930"}
Name _______________________y1: {"bbtday",#N/A,FALSE,"ban0930";"banksday",#N/A,FALSE,"ban0930";"compday",#N/A,FALSE,"ban0930"}
Name _______________________y1: {"bbtday",#N/A,FALSE,"ban0930";"banksday",#N/A,FALSE,"ban0930";"compday",#N/A,FALSE,"ban0930"}
Name _______________________y1: {"bbtday",#N/A,FALSE,"ban0930";"banksday",#N/A,FALSE,"ban0930";"compday",#N/A,FALSE,"ban0930"}
Name _____________________vvv1: {"bbtday",#N/A,FALSE,"ban0930";"banksday",#N/A,FALSE,"ban0930";"compday",#N/A,FALSE,"ban0930"}
Name _____________________vvv1: {"bbtday",#N/A,FALSE,"ban0930";"banksday",#N/A,FALSE,"ban0930";"compday",#N/A,FALSE,"ban0930"}

Sheet __snloffice
A1: 允䅁䅁䅍䅁慁䅁䅁兓剂䙁䄸兔䉂䙁䅉睓䙂䙁䅑睑䉂䙁䅁䅁䉁䅁䅁䅆䅁䕁䄴兗呂䕁䅕杏䑂䕁䄸睔䱂䅁䅁䅁䅁䅁䅷䅁ぁ䑁䅙䅍㑁䑁䅙䅁䍁䅁䅁䅁䅁䅁㴽

Sheet Historical Financials
D3: Traeger Pellet Grills | G3: Print Screen | I3: 0 | AJ3: DRAFT
D4: Spread Financials | AJ4: CONFIDENTIAL
D5: Data as of 4Q'25
D7: ($ millions) | F7: 2021 | G7: 2021 | H7: 2021 | I7: 2021 | J7: 2022 | K7: 2022 | L7: 2022 | M7: 2022 | N7: 2023 | O7: 2023 | P7: 2023 | Q7: 2023 | R7: 2024 | S7: 2024 | T7: 2024 | U7: 2024 | V7: 2025 | W7: 2025 | X7: 2025 | Y7: 2025 | AI7: Quarter Ended | BG7: Retail | BH7: 203.217 | BI7: 162.137 | BJ7: 502.884 | BK7: 132.61 | BL7: 135.198 | BM7: =BJ7-SUM(BH7:BI7)+SUM(BK7:BL7) -> 405.338 | BN7: 451.759 | BO7: 121.26 | BP7: =BO7/BO8 -> 1
D8: Line Item | F8: 1Q'21 | G8: 2Q'21 | H8: 3Q'21 | I8: 4Q'21 | J8: 1Q'22 | K8: 2Q'22 | L8: 3Q'22 | M8: 4Q'22 | N8: 1Q'23 | O8: 2Q'23 | P8: 3Q'23 | Q8: 4Q'23 | R8: 1Q'24 | S8: 2Q'24 | T8: 3Q'24 | U8: 4Q'24 | V8: 1Q'25 | W8: 2Q'25 | X8: 3Q'25 | Y8: 4Q'25 | AA8: 2019 | AB8: 2020 | AC8: 2021 | AD8: 2022 | AE8: 2023 | AF8: 2024 | AG8: 2025 | AH8: LTM 3Q'25 | AI8: 4Q'24 | AJ8: 4Q'25 | BH8: =SUM(BH7:BH7) -> 203.217 | BI8: =SUM(BI7:BI7) -> 162.137 | BJ8: =SUM(#REF!) -> #REF! | BK8: =SUM(BK7:BK7) -> 132.61 | BL8: =SUM(BL7:BL7) -> 135.198 | BM8: =SUM(BM7:BM7) -> 405.338 | BN8: =SUM(BN7:BN7) -> 451.759 | BO8: =SUM(BO7:BO7) -> 121.26
F9: 44286 | G9: 44377 | H9: 44469 | I9: 44561 | J9: 44651 | K9: 44742 | L9: 44834 | M9: 44926 | N9: 45016 | O9: 45107 | P9: 45199 | Q9: 45291 | R9: 45382 | S9: 45473 | T9: 45565 | U9: 45657 | V9: 45747 | W9: 45838 | X9: 45930 | Y9: 46022
B11: x | C11: Income Statement
C13: Revenue
D14: Grills | F14: 178.655 | G14: 156.101 | H14: 108.799 | I14: =AC14-SUM(F14:H14) -> 100.645 | J14: 150.431 | K14: 117.68 | L14: 38.994 | M14: 48.333 | N14: 89.738 | O14: 93.133 | P14: 56.573 | Q14: =AE14-SUM(N14:P14) -> 59.902 | R14: 76.819 | S14: 94.971 | T14: 74.931 | U14: =AF14-SUM(R14:T14) -> 77.981 | V14: 86.685 | W14: 74.184 | X14: 76.569 | Y14: =AG14-SUM(V14:X14) -> 60.572 | AB14: 391.047 | AC14: 544.2 | AD14: 355.441 | AE14: 299.346 | AF14: 324.702 | AG14: 298.01 | AH14: =SUM(U14:X14) -> 315.419 | AI14: =U14 -> 77.981 | AJ14: =Y14 -> 60.572 | AM14: =AH14/SUM(Q14:T14)-1 -> 0.028686693 | AN14: =SUM(Q14:T14) -> 306.623
D15: Consumables | F15: 40.813 | G15: 41.178 | H15: 28.029 | I15: =AC15-SUM(F15:H15) -> 26.196 | J15: 39.651 | K15: 42.097 | L15: 25.151 | M15: 24.4 | N15: 30.045 | O15: 34.9 | P15: 25.385 | Q15: =AE15-SUM(N15:P15) -> 24.571 | R15: 32.259 | S15: 33.831 | T15: 22.531 | U15: =AF15-SUM(R15:T15) -> 30.678 | V15: 30.288 | W15: 36.357 | X15: 25.296 | Y15: =AG15-SUM(V15:X15) -> 35.569 | AB15: 120.247 | AC15: 136.216 | AD15: 131.342 | AE15: 114.901 | AF15: 119.299 | AG15: 127.51 | AH15: =SUM(U15:X15) -> 122.619 | AI15: =U15 -> 30.678 | AJ15: =Y15 -> 35.569 | AM15: =AH15/$AH$17 -> 0.21039636
D16: Accessories | F16: 16.105 | G16: 15.743 | H16: 25.19 | I16: =AC16-SUM(F16:H16) -> 48.091 | J16: 33.628 | K16: 40.493 | L16: 29.644 | M16: 65.4 | N16: 33.378 | O16: 43.479 | P16: 35.772 | Q16: =AE16-SUM(N16:P16) -> 79.006 | R16: 35.836 | S16: 39.669 | T16: 24.588 | U16: =AF16-SUM(R16:T16) -> 59.978 | V16: 26.31 | W16: 34.943 | X16: 23.531 | Y16: =AG16-SUM(V16:X16) -> 49.216 | AB16: 34.478 | AC16: 105.129 | AD16: 169.118 | AE16: 191.635 | AF16: 160.071 | AG16: 134 | AH16: =SUM(U16:X16) -> 144.762 | AI16: =U16 -> 59.978 | AJ16: =Y16 -> 49.216 | AM16: =AH16/$AH$17 -> 0.24839053
C17: Total Revenue | F17: =SUM(F14:F16) -> 235.573 | G17: =SUM(G14:G16) -> 213.022 | H17: =SUM(H14:H16) -> 162.018 | I17: =SUM(I14:I16) -> 174.932 | J17: =SUM(J14:J16) -> 223.71 | K17: =SUM(K14:K16) -> 200.27 | L17: =SUM(L14:L16) -> 93.789 | M17: =SUM(M14:M16) -> 138.133 | ... T17: =SUM(T14:T16) -> 122.05 | U17: =AF17-SUM(R17:T17) -> 168.637 | V17: =SUM(V14:V16) -> 143.283 | W17: =SUM(W14:W16) -> 145.484 | X17: =SUM(X14:X16) -> 125.396 | Y17: =SUM(Y14:Y16) -> 145.357 | AA17: 363.319 | AB17: =SUM(AB14:AB16) -> 545.772 | AC17: =SUM(AC14:AC16) -> 785.545 | AD17: =SUM(AD14:AD16) -> 655.901 | AE17: =SUM(AE14:AE16) -> 605.882 | AF17: =SUM(AF14:AF16) -> 604.072 | AG17: =SUM(AG14:AG16) -> 559.52 | AH17: =SUM(U17:X17) -> 582.8 | AI17: =SUM(AI14:AI16) -> 168.637 | AJ17: =SUM(AJ14:AJ16) -> 145.357 | AM17: =AJ17/AI17-1 -> -0.138048
C18: Cost of Revenue | F18: 134.942 | G18: 129.715 | H18: 107.696 | I18: =AC18-SUM(F18:H18) -> 109.481 | J18: 140.145 | K18: 126.764 | L18: 67.81 | M18: 90.524 | N18: 97.738 | O18: 108.181 | P18: 73.064 | Q18: 103.342 | R18: 82.351 | S18: 96.143 | T18: 70.362 | U18: =AF18-SUM(R18:T18) -> 99.747 | V18: 83.824 | W18: 88.483 | X18: 76.85 | Y18: =AG18-SUM(V18:X18) -> 91.017 | AA18: 207.539 | AB18: 310.408 | AC18: 481.834 | AD18: 427.129 | AE18: =382.325 -> 382.325 | AF18: 348.603 | AG18: 340.174 | AH18: =SUM(U18:X18) -> 348.904 | AI18: =U18 -> 99.747 | AJ18: =Y18 -> 91.017
C19: Gross Profit | F19: =F17-F18 -> 100.631 | G19: =G17-G18 -> 83.307 | H19: =H17-H18 -> 54.322 | I19: =I17-I18 -> 65.451 | J19: =J17-J18 -> 83.565 | K19: =K17-K18 -> 73.506 | L19: =L17-L18 -> 25.979 | M19: =M17-M18 -> 47.609 | ... T19: =T17-T18 -> 51.688 | U19: =AF19-SUM(R19:T19) -> 68.89 | V19: =V17-V18 -> 59.459 | W19: =W17-W18 -> 57.001 | X19: =X17-X18 -> 48.546 | Y19: =Y17-Y18 -> 54.34 | AA19: =AA17-AA18 -> 155.78 | AB19: =AB17-AB18 -> 235.364 | AC19: =AC17-AC18 -> 303.711 | AD19: =AD17-AD18 -> 228.772 | AE19: =AE17-AE18 -> 223.557 | AF19: =AF17-AF18 -> 255.469 | AG19: =AG17-AG18 -> 219.346 | AH19: =SUM(U19:X19) -> 233.896 | AI19: =AI17-AI18 -> 68.89 | AJ19: =AJ17-AJ18 -> 54.34 | AM19: =AJ19/AI19-1 -> -0.21120627
D20: Gross Margin | F20: =F19/F17 -> 0.42717544 | G20: =G19/G17 -> 0.39107228 | H20: =H19/H17 -> 0.33528373 | I20: =I19/I17 -> 0.3741511 | J20: =J19/J17 -> 0.37354164 | K20: =K19/K17 -> 0.3670345 | L20: =L19/L17 -> 0.2769941 | M20: =M19/M17 -> 0.34466058 | ... Y20: =Y19/Y17 -> 0.37383821 | AA20: =AA19/AA17 -> 0.42876921 | AB20: =AB19/AB17 -> 0.43124968 | AC20: =AC19/AC17 -> 0.38662457 | AD20: =AD19/AD17 -> 0.34879044 | AE20: =AE19/AE17 -> 0.36897779 | AF20: =AF19/AF17 -> 0.42291151 | AG20: =AG19/AG17 -> 0.39202531 | AH20: =AH19/AH17 -> 0.4013315 | ... AJ20: =AJ19/AJ17 -> 0.37383821
D21: TTM Revenue | J21: =SUM(G17:J17) -> 773.682 | K21: =SUM(H17:K17) -> 760.93 | L21: =SUM(I17:L17) -> 692.701 | M21: =SUM(J17:M17) -> 655.902 | N21: =SUM(K17:N17) -> 585.353 | O21: =SUM(L17:O17) -> 556.595 | P21: =SUM(M17:P17) -> 580.536 | Q21: =SUM(N17:Q17) -> 605.882 | ... Y21: =SUM(V17:Y17) -> 559.52
C23: Operating Expense
D24: Sales and Marketing | F24: 30.851 | G24: 47.269 | H24: 48.519 | I24: =AC24-SUM(F24:H24) -> 38.541 | J24: 33.094 | K24: 43.811 | L24: 25.496 | M24: 28.287 | N24: 22.075 | O24: 27.915 | P24: =25.913 -> 25.913 | Q24: 32.824 | R24: 21.679 | S24: 28.224 | T24: 26.162 | U24: =AF24-SUM(R24:T24) -> 33.591 | V24: 22.21 | W24: 24.779 | X24: 20 | Y24: =AG24-SUM(V24:X24) -> 23.228 | AA24: 66.921 | AB24: 93.69 | AC24: 165.18 | AD24: 130.688 | AE24: =108.727 -> 108.727 | AF24: 109.656 | AG24: 90.217 | AH24: =SUM(U24:X24) -> 100.58 | AI24: =U24 -> 33.591 | AJ24: =Y24 -> 23.228
D25: General and Admin | F25: 13.556 | G25: 24.802 | H25: 75.824 | I25: =AC25-SUM(F25:H25) -> 44.373 | J25: 42.869 | K25: 28.886 | L25: 70.882 | M25: 24.187 | N25: 26.679 | O25: 52.371 | P25: 24.823 | Q25: 25.927 | R25: 32.138 | S25: 30.491 | T25: 24.135 | U25: =AF25-SUM(R25:T25) -> 26.719 | V25: 25.019 | W25: 26.032 | X25: 22.164 | Y25: =AG25-SUM(V25:X25) -> 21.816 | AA25: 45.304 | AB25: 50.243 | AC25: 158.555 | AD25: 166.824 | AE25: =129.8 -> 129.8 | AF25: 113.483 | AG25: 95.031 | AH25: =SUM(U25:X25) -> 99.934 | AI25: =U25 -> 26.719 | AJ25: =Y25 -> 21.816
D26: Amortization of Intangibles | F26: 8.301 | G26: 8.301 | H26: 8.889 | I26: =AC26-SUM(F26:H26) -> 8.888 | J26: 8.889 | K26: 8.888 | L26: 8.889 | M26: 8.888 | N26: 8.889 | O26: 8.888 | P26: 8.889 | Q26: 8.888 | R26: 8.819 | S26: 8.818 | T26: 8.819 | U26: =AF26-SUM(R26:T26) -> 8.818 | V26: 8.818 | W26: 8.816 | X26: 8.813 | Y26: =AG26-SUM(V26:X26) -> 8.813 | AA26: 33.1 | AB26: 32.533 | AC26: 34.379 | AD26: 35.554 | AE26: =35.554 -> 35.554 | AF26: 35.274 | AG26: 35.26 | AH26: =SUM(U26:X26) -> 35.265 | AI26: =U26 -> 8.818 | AJ26: =Y26 -> 8.813
D27: Change in fair value of contingent consideration | F27: 0 | G27: 0 | H27: 2.9 | I27: =AC27-SUM(F27:H27) -> 0.9 | J27: 1.7 | K27: 0.255 | L27: 1.82 | M27: 6.227 | N27: 1.043 | O27: 1.765 | P27: =-2.3 -> -2.3 | Q27: 4.19 | R27: 0 | S27: 0 | T27: 0 | U27: =AF27-SUM(R27:T27) -> 0 | V27: 0 | W27: 0 | X27: 0 | Y27: =AG27-SUM(V27:X27) -> 0 | AA27: 0 | AB27: 0 | AC27: 3.8 | AD27: 10.002 | AE27: =4.698 -> 4.698 | AF27: 0 | AG27: 0 | AH27: =SUM(U27:X27) -> 0 | AI27: =U27 -> 0 | AJ27: =Y27 -> 0
D28: Goodwill impairment | F28: 0 | G28: 0 | H28: 0 | I28: =AC28-SUM(F28:H28) -> 0 | J28: 0 | K28: 111.485 | L28: 110.837 | M28: 0 | N28: 0 | O28: 0 | P28: =0.225 -> 0.225 | Q28: 0 | R28: 0 | S28: 0 | T28: 0 | U28: =AF28-SUM(R28:T28) -> 0 | V28: 0 | W28: 0 | X28: 74.725 | Y28: =AG28-SUM(V28:X28) -> 0 | AA28: 0 | AB28: 0 | AC28: 0 | AD28: 222.322 | AE28: 0 | AF28: 0 | AG28: 74.725 | AH28: =SUM(U28:X28) -> 74.725 | AI28: =U28 -> 0 | AJ28: =Y28 -> 0
D29: Restructuring Charges | F29: 0 | G29: 0 | H29: 0 | I29: =AC29-SUM(F29:H29) -> 0 | J29: 0 | K29: 0 | L29: 8.036 | M29: 1.288 | N29: 0 | O29: 0 | P29: 0 | Q29: 0 | R29: 0 | S29: 0 | U29: =AF29-SUM(R29:T29) -> 0 | W29: 3.468 | X29: 6.204 | Y29: =AG29-SUM(V29:X29) -> 12.168 | AA29: 0 | AB29: 0 | AC29: 0 | AD29: 9.324 | AE29: =0.225 -> 0.225 | AF29: 0 | AG29: 21.84 | AH29: =SUM(U29:X29) -> 9.672 | AI29: =U29 -> 0 | AJ29: =Y29 -> 12.168
C30: Operating Income | F30: =F19-SUM(F24:F29) -> 47.923 | G30: =G19-SUM(G24:G29) -> 2.935 | H30: =H19-SUM(H24:H29) -> -81.81 | I30: =I19-SUM(I24:I29) -> -27.251 | J30: =J19-SUM(J24:J29) -> -2.987 | K30: =K19-SUM(K24:K29) -> -119.819 | L30: =L19-SUM(L24:L29) -> -199.981 | M30: =M19-SUM(M24:M29) -> -21.268 | ... T30: =T19-SUM(T24:T29) -> -7.428 | U30: =AF30-SUM(R30:T30) -> -0.238 | V30: =V19-SUM(V24:V29) -> 3.412 | W30: =W19-SUM(W24:W29) -> -6.094 | X30: =X19-SUM(X24:X29) -> -83.36 | Y30: =Y19-SUM(Y24:Y29) -> -11.685 | AA30: =AA19-SUM(AA24:AA29) -> 10.455 | AB30: =AB19-SUM(AB24:AB29) -> 58.898 | AC30: =AC19-SUM(AC24:AC29) -> -58.203 | AD30: =AD19-SUM(AD24:AD29) -> -345.942 | AE30: =AE19-SUM(AE24:AE29) -> -55.447 | AF30: =AF19-SUM(AF24:AF29) -> -2.944 | AG30: =AG19-SUM(AG24:AG29) -> -97.727 | AH30: =SUM(U30:X30) -> -86.28 | AI30: =AI19-SUM(AI24:AI29) -> -0.238 | AJ30: =AJ19-SUM(AJ24:AJ29) -> -11.685
D31: Interest Expense, Net | F31: -7.812 | G31: -7.877 | H31: -5.704 | I31: =AC31-SUM(F31:H31) -> -5.253 | J31: -5.837 | K31: -7.064 | L31: -7.337 | M31: -7.647 | N31: -10.454 | O31: -7.81 | P31: =-7.517 -> -7.517 | Q31: =-7.867 -> -7.867 | R31: =-8.096 -> -8.096 | S31: -8.678 | T31: -8.534 | U31: =AF31-SUM(R31:T31) -> -8.192 | V31: -7.893 | W31: -8.091 | X31: -7.815 | Y31: =AG31-SUM(V31:X31) -> -7.551 | AA31: -39.462 | AB31: -34.073 | AC31: -26.646 | AD31: -27.885 | AE31: =-31.275 -> -31.275 | AF31: -33.5 | AG31: -31.35 | AH31: =SUM(U31:X31) -> -31.991 | AI31: =U31 -> -8.192 | AJ31: =Y31 -> -7.551
D32: Loss on extinguishment of debt | F32: -0.458 | G32: -1.957 | H32: -3.228 | I32: =AC32-SUM(F32:H32) -> 0.458 | J32: 0.544 | K32: 0 | L32: 0 | M32: 0 | N32: 0 | O32: 0 | P32: 0 | Q32: 0 | R32: 0 | S32: 0 | T32: 0 | U32: =AF32-SUM(R32:T32) -> 0 | V32: 0 | W32: 0 | X32: 0 | Y32: =AG32-SUM(V32:X32) -> 0 | AA32: 0 | AB32: 0 | AC32: -5.185 | AD32: 0 | AE32: 0 | AF32: 0 | AG32: 0 | AH32: =SUM(U32:X32) -> 0 | AI32: =U32 -> 0 | AJ32: =Y32 -> 0
D33: Other Income (expense) | F33: 0 | G33: 1.996 | H33: -0.426 | I33: =AC33-SUM(F33:H33) -> 1.132 | J33: 0 | K33: -5.35 | L33: -3.545 | M33: 1.224 | N33: 21.899 | O33: 5.45 | P33: =1.992 -> 1.992 | Q33: =-3.715 -> -3.715 | R33: 3.676 | S33: 1.281 | T33: -3.964 | U33: =AF33-SUM(R33:T33) -> -0.513 | V33: 2.103 | W33: 6.411 | X33: 1.049 | Y33: =AG33-SUM(V33:X33) -> 0.192 | AA33: -0.462 | AB33: 7.526 | AC33: 2.702 | AD33: -7.127 | AE33: =4.305 -> 4.305 | AF33: 0.48 | AG33: 9.755 | AH33: =SUM(U33:X33) -> 9.05 | AI33: =U33 -> -0.513 | AJ33: =Y33 -> 0.192
C34: Income (Loss) Before Tax | F34: =+F30+SUM(F31:F33) -> 39.653 | G34: =+G30+SUM(G31:G33) -> -4.903 | H34: =+H30+SUM(H31:H33) -> -91.168 | I34: =+I30+SUM(I31:I33) -> -30.914 | J34: =+J30+SUM(J31:J33) -> -8.28 | K34: =+K30+SUM(K31:K33) -> -132.233 | L34: =+L30+SUM(L31:L33) -> -210.863 | M34: =+M30+SUM(M31:M33) -> -27.691 | ... T34: =+T30+SUM(T31:T33) -> -19.926 | U34: =AF34-SUM(R34:T34) -> -8.943 | V34: =+V30+SUM(V31:V33) -> -2.378 | W34: =+W30+SUM(W31:W33) -> -7.774 | X34: =+X30+SUM(X31:X33) -> -90.126 | Y34: =+Y30+SUM(Y31:Y33) -> -19.044 | AA34: =+AA30+SUM(AA31:AA33) -> -29.469 | AB34: =+AB30+SUM(AB31:AB33) -> 32.351 | AC34: =+AC30+SUM(AC31:AC33) -> -87.332 | AD34: =+AD30+SUM(AD31:AD33) -> -380.954 | AE34: =+AE30+SUM(AE31:AE33) -> -82.417 | AF34: =+AF30+SUM(AF31:AF33) -> -35.964 | AG34: =+AG30+SUM(AG31:AG33) -> -119.322 | AH34: =SUM(U34:X34) -> -109.221 | AI34: =+AI30+SUM(AI31:AI33) -> -8.943 | AJ34: =+AJ30+SUM(AJ31:AJ33) -> -19.044
D35: Provision (benefit) for Income Tax | F35: 0.724 | G35: 0.004 | H35: -1.983 | I35: =AC35-SUM(F35:H35) -> 2.744 | J35: 0.152 | K35: 0.046 | L35: -0.225 | M35: 1.213 | N35: 0.164 | O35: 0.198 | P35: =0.852 -> 0.852 | Q35: =0.771 -> 0.771 | R35: 0.19 | S35: -0.024 | T35: -0.137 | U35: =AF35-SUM(R35:T35) -> -1.985 | V35: -1.6 | W35: -0.391 | X35: -0.307 | Y35: =AG35-SUM(V35:X35) -> -1.843 | AA35: 0.124 | AB35: 0.749 | AC35: 1.489 | AD35: 1.186 | AE35: =1.985 -> 1.985 | AF35: -1.956 | AG35: -4.141 | AH35: =SUM(U35:X35) -> -4.283 | AI35: =U35 -> -1.985 | AJ35: =Y35 -> -1.843
C36: Net Income (Loss) | F36: =+F34-F35 -> 38.929 | G36: =+G34-G35 -> -4.907 | H36: =+H34-H35 -> -89.185 | I36: =+I34-I35 -> -33.658 | J36: =+J34-J35 -> -8.432 | K36: =+K34-K35 -> -132.279 | L36: =+L34-L35 -> -210.638 | M36: =+M34-M35 -> -28.904 | ... T36: =+T34-T35 -> -19.789 | U36: =AF36-SUM(R36:T36) -> -6.958 | V36: =+V34-V35 -> -0.778 | W36: =+W34-W35 -> -7.383 | X36: =+X34-X35 -> -89.819 | Y36: =+Y34-Y35 -> -17.201 | AA36: =+AA34-AA35 -> -29.593 | AB36: =+AB34-AB35 -> 31.602 | AC36: =+AC34-AC35 -> -88.821 | AD36: =+AD34-AD35 -> -382.14 | AE36: =+AE34-AE35 -> -84.402 | AF36: =+AF34-AF35 -> -34.008 | AG36: =+AG34-AG35 -> -115.181 | AH36: =SUM(U36:X36) -> -104.938 | AI36: =+AI34-AI35 -> -6.958 | AJ36: =+AJ34-AJ35 -> -17.201
C37: As Reported | F37: 38.929 | G37: -4.907 | H37: -89.185 | I37: =AC37-SUM(F37:H37) -> -33.658 | J37: -8.432 | K37: -132.279 | L37: -210.639 | M37: -28.904 | N37: 8.018 | O37: -30.166 | P37: =-19.261 -> -19.261 | Q37: =-24.045 -> -24.045 | R37: =-4.683 -> -4.683 | S37: -2.578 | T37: -19.789 | U37: -6.958 | V37: -0.778 | W37: -7.384 | X37: -89.819 | Y37: -17.2 | AA37: -29.593 | AB37: 31.602 | AC37: -88.821 | AD37: -382.14 | AE37: =-84.402 -> -84.402 | AF37: -34.008 | AG37: -115.181 | AH37: =SUM(U37:X37) -> -104.939
C38: Check | F38: =F36-F37 -> 0 | G38: =G36-G37 -> -1.0658141e-14 | H38: =H36-H37 -> 0 | I38: =I36-I37 -> 1.6342483e-13 | J38: =J36-J37 -> 3.5527137e-14 | K38: =K36-K37 -> 0 | L38: =L36-L37 -> 0.001 | M38: =M36-M37 -> 0 | ... Y38: =Y36-Y37 -> -0.001 | AB38: =AB36-AB37 -> 2.8421709e-14 | AC38: =AC36-AC37 -> 0 | AD38: =AD36-AD37 -> 0 | AE38: =AE36-AE37 -> 0 | AF38: =AF36-AF37 -> 0 | AG38: =AG36-AG37 -> 0 | AH38: =SUM(U38:X38) -> 0.001
D40: Provision for income taxes | F40: 0.724 | G40: 0.004 | H40: -1.983 | I40: =AC40-SUM(F40:H40) -> 2.744 | J40: 0.152 | K40: 0.046 | L40: -0.225 | M40: 1.213 | N40: 0.164 | O40: 0.198 | P40: =0.852 -> 0.852 | Q40: =0.771 -> 0.771 | R40: 0.19 | S40: -0.024 | T40: -0.137 | U40: -1.985 | V40: -1.6 | W40: -0.391 | X40: -0.307 | Y40: =Y35 -> -1.843 | AB40: 0.749 | AC40: 1.489 | AD40: 1.186 | AE40: =1.985 -> 1.985 | AF40: -1.956 | AG40: =AG35 -> -4.141 | AH40: =SUM(U40:X40) -> -4.283 | AI40: =U40 -> -1.985 | AJ40: =Y40 -> -1.843
D41: Interest expense | F41: 7.812 | G41: 7.877 | H41: 3.977 | I41: =AC41-SUM(F41:H41) -> 6.98 | J41: 5.837 | K41: 7.064 | L41: 7.337 | M41: 7.647 | N41: 10.454 | O41: 7.81 | P41: =7.517 -> 7.517 | Q41: =7.867 -> 7.867 | R41: =8.096 -> 8.096 | S41: 8.678 | T41: 8.534 | U41: 8.192 | V41: 7.893 | W41: 8.091 | X41: 7.815 | Y41: =AG41-SUM(V41:X41) -> 7.551 | AB41: 34.073 | AC41: 26.646 | AD41: 27.885 | AE41: 31.275 | AF41: 33.5 | AG41: 31.35 | AH41: =SUM(U41:X41) -> 31.991 | AI41: =U41 -> 8.192 | AJ41: =Y41 -> 7.551
D42: Depreciation and amortization | F42: 10.699 | G42: 10.74 | H42: 5.704 | I42: =AC42-SUM(F42:H42) -> 20.356 | J42: 13.177 | K42: 14.242 | L42: 14.382 | M42: 14.816 | N42: 14.255 | O42: 14.587 | P42: =14.433 -> 14.433 | Q42: =14.503 -> 14.503 | R42: 14.247 | S42: 13.944 | T42: 13.885 | U42: 14.251 | V42: 14.242 | W42: 13.308 | X42: 13.302 | Y42: =AG42-SUM(V42:X42) -> 13.285 | AB42: 40.968 | AC42: 47.499 | AD42: 56.617 | AE42: =57.778 -> 57.778 | AF42: 56.327 | AG42: 54.137 | AH42: =SUM(U42:X42) -> 55.103 | AI42: =U42 -> 14.251 | AJ42: =Y42 -> 13.285
D43: Other (income) expense | F43: 3.348 | G43: 2.72 | H43: 13.076 | I43: =AC43-SUM(F43:H43) -> -8.626 | J43: 0.674 | K43: 3.401 | L43: 0.021 | M43: -1.629 | N43: -20.307 | O43: -6.529 | P43: =-2.978 -> -2.978 | Q43: =3.276 -> 3.276 | R43: =-3.637 -> -3.637 | S43: -1.863 | T43: 3.875 | U43: 0.011 | V43: -2.411 | W43: -1.747 | X43: -0.467 | Y43: =AG43-SUM(V43:X43) -> -0.468 | AB43: -5.947 | AC43: 10.518 | AD43: 2.466 | AE43: =-5.216 -> -5.216 | AF43: -1.614 | AG43: -5.093 | AH43: =SUM(U43:X43) -> -4.614 | AI43: =U43 -> 0.011 | AJ43: =Y43 -> -0.468
D44: Goodwill impairment | F44: 0 | G44: 0 | H44: 59.21 | I44: =AC44-SUM(F44:H44) -> -59.21 | J44: 0 | K44: 111.485 | L44: 109.757 | M44: 0 | N44: 0 | O44: 0 | P44: 0 | Q44: 0 | R44: 0 | S44: 0 | T44: 0 | U44: 0 | W44: 0 | X44: 74.725 | Y44: =AG44-SUM(V44:X44) -> 0 | AB44: 0 | AC44: 0 | AD44: 222.322 | AE44: 0 | AF44: 0 | AG44: 74.725 | AH44: =SUM(U44:X44) -> 74.725 | AI44: =U44 -> 0 | AJ44: =Y44 -> 0
D45: Restructuring costs | F45: 0 | G45: 0 | H45: 0 | I45: 0 | J45: 0 | K45: 0 | L45: 9.644 | M45: 1.898 | N45: 0 | O45: 0 | P45: =0.225 -> 0.225 | Q45: 0 | R45: 0 | S45: 0 | T45: 0 | U45: 0 | W45: 3.468 | X45: 6.204 | Y45: =AG45-SUM(V45:X45) -> 15.27 | AB45: 0 | AC45: 0 | AD45: 11.542 | AE45: =0.225 -> 0.225 | AF45: 27.901 | AG45: 24.942 | AH45: =SUM(U45:X45) -> 9.672 | AI45: =U45 -> 0 | AJ45: =Y45 -> 15.27
D46: Equity-based compensation | F46: 0.956 | G46: 1.545 | H46: 1.313 | I46: =AC46-SUM(F46:H46) -> 77.298 | J46: 15.483 | K46: 11.951 | L46: 53.254 | M46: 7.01 | N46: 7.943 | O46: 33.036 | P46: =6.201 -> 6.201 | Q46: 6.023 | R46: 10.098 | S46: 7.065 | T46: 5.901 | U46: 4.837 | V46: 5.176 | W46: 3.969 | X46: 3.331 | Y46: =AG46-SUM(V46:X46) -> 2.778 | AB46: 12.81 | AC46: 81.112 | AD46: 87.697 | AE46: =53.203 -> 53.203 | AF46: 1.794 | AG46: 15.254 | AH46: =SUM(U46:X46) -> 17.313 | AI46: =U46 -> 4.837 | AJ46: =Y46 -> 2.778
D47: Non-routine legal expenses | F47: 1.242 | G47: 1.512 | H47: 2.883 | I47: =AC47-SUM(F47:H47) -> 0.706 | J47: 1.919 | K47: 1.051 | L47: 0.788 | M47: -0.745 | N47: 0.233 | O47: 0.248 | P47: 0 | Q47: =0.397 -> 0.397 | R47: 0.103 | S47: 1.6 | T47: 0.079 | U47: 0.013 | V47: 0.008 | W47: 0.01 | X47: 0.005 | Y47: =AG47-SUM(V47:X47) -> 0.002 | AB47: 1.82 | AC47: 6.343 | AD47: 3.012 | AE47: =0.878 -> 0.878 | AF47: 0 | AG47: 0.025 | AH47: =SUM(U47:X47) -> 0.036 | AI47: =U47 -> 0.013 | AJ47: =Y47 -> 0.002
...

Sheet Capital Structure
D3: Traeger Pellet Grills | S3: DRAFT
D4: Capital Structure | S4: CONFIDENTIAL
D5: Data as of 4Q'25
D6: ($ millions)
D8: Stock Ticker: | F8: NYSE:COOK
D9: Date: | F9: 46086
G11: Principal | H11: Interest | J11: Effective | L11: Credit | M11: Trading | N11: Cash | O11: Cum. | P11: Market | R11: 1 Month SOFR as of 3/5/2026
D12: Description | G12: Amount | H12: Rate | I12: YTM | J12: Rate | K12: Maturity | L12: Rating | M12: Price(1) | N12: Interest | O12: Leverage | P12: Amount | R12: 0.0367223
D14: Revolving Credit Facility ($112.5mm)(2) | G14: 0 | H14: 350 | I14: NA | J14: =$R$12+(H14/10000) -> 0.0717223 | K14: 46202 | L14: NA | M14: NA | N14: =J14*G14 -> 0 | P14: =IF(ISNUMBER(M14),M14*G14/100,G14) -> 0 | R14: 1L TL Hedged Cash Interest
D15: Receivables Financing Agreement | G15: 0 | H15: 200 | I15: NA | J15: =$R$12+(H15/10000) -> 0.0567223 | K15: 46605 | L15: B- | M15: NA | N15: =J15*G15 -> 0 | P15: =IF(ISNUMBER(M15),M15*G15/100,G15) -> 0 | R15: Interest Rate Swap Notional: | S15: 379.2
D16: Delayed Draw Term Loan | G16: 25 | H16: 350 | J16: =$R$12+(H16/10000) -> 0.0717223 | K16: 46933 | L16: B- | M16: 94.43 | N16: =J16*G16 -> 1.7930575 | O16: =SUM($G$14:G16)/$G$22 -> 0.35730109 | P16: =IF(ISNUMBER(M16),M16*G16/100,G16) -> 23.6075 | R16: Interest Rate | S16: 0.0533
D17: 1L Term Loan due 2028(3) | G17: 403.325 | H17: 350 | I17: 0.0991 | J17: =$R$12+(H17/10000) -> 0.0717223 | K17: 46933 | L17: B- | M17: 84.38 | N17: =J17*G17 -> 28.927397 | P17: =IF(ISNUMBER(M17),M17*G17/100,G17) -> 340.32563 | R17: Cash Interest - Hedged | S17: =+S15*S16 -> 20.21136
D18: Total Debt | G18: =SUM(G14,G15,G17) -> 403.325 | N18: =SUM(N14,N15,N17) -> 28.927397 | O18: =G18/$G$22 -> 5.7643385 | P18: =SUM(P14,P15,P17) -> 340.32563 | R18: Remaining TL Balance | S18: =+G17-S15 -> 24.125
D19: Less: Cash and Equivalents | G19: =-G32 -> -19.624 | O19: =G19/G22 -> -0.28046706 | R19: Cash Interest - Unhedged | S19: =+S18*J17 -> 1.7303005
D20: Net Debt | G20: =SUM(G18:G19) -> 383.701 | O20: =+G20/G22 -> 5.4838714 | R20: Total Cash Interest | S20: =+S19+S17 -> 21.94166
D22: Memo: FY'25 Adj. EBITDA | G22: ='O1'!M40 -> 69.969
D23: Market Cap | G23: =_xll.ciqfunctions.udf.CIQ(F8, "IQ_MARKETCAP", F9) -> 105.62807
D26: Liquidity
D27: RCF Capacity | G27: 112.5
D28: Less: Outstanding | G28: =-G14 -> 0
D29: Receivables Financing Agreement Capacity | G29: 30
D30: Less: Outstanding | G30: =-G15 -> 0
D31: Credit Facility Availability | G31: =SUM(G27:G30) -> 142.5
D32: Plus: Cash and Equivalents | G32: 19.624
D33: Less: Min Liquidity Requirement(4) | G33: -42.5
D34: Total Liquidity | G34: =SUM(G31:G33) -> 119.624

Sheet _CIQHiddenCacheSheet
A1: 2 | B1: BAABTAVMT0NBTAFI/////wFQAQAAACNDSVEuTllTRTpDT09LLklRX01BUktFVENBUC4zLzUvMjAyNgEAAABTELtjAgAAAAoxMDUuNjI4MDczAQYAAAAFAAAAATEBAAAACy0xOTAzMzA0OTcwAwAAAAMxNjACAAAABjEwMDA1NAQAAAABMAcAAAAIMy81LzIwMjZKPFwYvn3eCLqEdhi+fd4I

Sheet Liquidity Model
D3: Traeger Pellet Grills | AD3: DRAFT
D4: Liquidity Model | AD4: CONFIDENTIAL
D5: Data as of 1Q25
D6: ($ millions)
E8: Case | F8: 2
E10: Circ | F10: 1 | S10: New Price = 1 + ( % COGS x % Tariff x % Pass-Through)
S11: Tariff Paid % of Revenue = ( % COGS x % Tariff )
E12: Print Screen | F12: 2 | S12: COGS % of Revenue = ( 1 - Assumed Gross Margin % )
E14: PF Switch | F14: 1
E16: Tariff / Margin Assumptions
E18: Traeger Grilling & Accessories Gross Margin | M18: 0.385
E19: Retailer Gross Margin | M19: 0.2
E21: Section 232 Steel Tariff | M21: 0.5
E22: IEEPA Tariff | M22: 0
E23: Section 301 China Tariff | M23: 0.25
E24: Vietnam Tariff | M24: 0
E26: Tariff Pass-Through
E27: Live Case | S27: =CHOOSE($F$8,S28,S29,S30) -> 0.75 | T27: =CHOOSE($F$8,T28,T29,T30) -> 0.75 | U27: =CHOOSE($F$8,U28,U29,U30) -> 0.75 | V27: =CHOOSE($F$8,V28,V29,V30) -> 0.75
D28: 1 | E28: Downside | S28: 0.5 | T28: 0.5 | U28: 0.5 | V28: 0.5
D29: 2 | E29: Base | S29: 0.75 | T29: 0.75 | U29: 0.75 | V29: 0.75
D30: 3 | E30: Upside | S30: 1 | T30: 1 | U30: 1 | V30: 1
E33: Tariffs on Grills
E34: Live Case | S34: =CHOOSE($F$8,S35,S36,S37) -> 0.5 | T34: =CHOOSE($F$8,T35,T36,T37) -> 0.5 | U34: =CHOOSE($F$8,U35,U36,U37) -> 0.5 | V34: =CHOOSE($F$8,V35,V36,V37) -> 0.5
D35: 1 | E35: Downside | K35: 301 Exemption Renewed | S35: =SUM($M$21:$M$22) -> 0.5 | T35: =SUM($M$21:$M$22) -> 0.5 | U35: =SUM($M$21:$M$22) -> 0.5 | V35: =SUM($M$21:$M$22) -> 0.5
D36: 2 | E36: Base | K36: 301 Exemption Renewed | S36: =SUM($M$21:$M$22) -> 0.5 | T36: =SUM($M$21:$M$22) -> 0.5 | U36: =SUM($M$21:$M$22) -> 0.5 | V36: =SUM($M$21:$M$22) -> 0.5
D37: 3 | E37: Upside | K37: 301 Exemption Renewed | S37: =SUM($M$21:$M$22) -> 0.5 | T37: =SUM($M$21:$M$22) -> 0.5 | U37: =SUM($M$21:$M$22) -> 0.5 | V37: =SUM($M$21:$M$22) -> 0.5
E39: Illustrative Gross Margin Build (NO TARIFF)
E40: Revenue - Grills | S40: 100 | T40: 100 | U40: 100 | V40: 100
E41: Less: Cost of Goods Sold - Grills | S41: =-S40*(1-$M$18) -> -61.5 | T41: =-T40*(1-$M$18) -> -61.5 | U41: =-U40*(1-$M$18) -> -61.5 | V41: =-V40*(1-$M$18) -> -61.5
E42: Gross Profit - Grills | S42: =S40+S41 -> 38.5 | T42: =T40+T41 -> 38.5 | U42: =U40+U41 -> 38.5 | V42: =V40+V41 -> 38.5
E43: Gross Profit (%) | S43: =S42/S40 -> 0.385 | T43: =T42/T40 -> 0.385 | U43: =U42/U40 -> 0.385 | V43: =V42/V40 -> 0.385
E45: Illustrative Gross Margin Build (TARIFF)
E46: Revenue - Grills | S46: 100 | T46: 100 | U46: 100 | V46: 100
E47: Plus: Additional Revenue from Price Increases | S47: =-S50*S27 -> 23.0625 | T47: =-T50*T27 -> 23.0625 | U47: =-U50*U27 -> 23.0625 | V47: =-V50*V27 -> 23.0625
E48: Total Revenues (Post Price Increase) | S48: =SUM(S46:S47) -> 123.0625 | T48: =SUM(T46:T47) -> 123.0625 | U48: =SUM(U46:U47) -> 123.0625 | V48: =SUM(V46:V47) -> 123.0625
E49: Less: Cost of Goods Sold - Grills | S49: =-S46*(1-$M$18) -> -61.5 | T49: =-T46*(1-$M$18) -> -61.5 | U49: =-U46*(1-$M$18) -> -61.5 | V49: =-V46*(1-$M$18) -> -61.5
E50: Less: Tariff Due - Grills | S50: =S49*S34 -> -30.75 | T50: =T49*T34 -> -30.75 | U50: =U49*U34 -> -30.75 | V50: =V49*V34 -> -30.75
E51: Gross Profit - Grills (Post Price Increase) | S51: =SUM(S48:S50) -> 30.8125 | T51: =SUM(T48:T50) -> 30.8125 | U51: =SUM(U48:U50) -> 30.8125 | V51: =SUM(V48:V50) -> 30.8125
E52: Gross Profit (%) | S52: =S51/S48 -> 0.2503809 | T52: =T51/T48 -> 0.2503809 | U52: =U51/U48 -> 0.2503809 | V52: =V51/V48 -> 0.2503809
E55: Negative Tariff Impact on Grills GM | S55: =S52-S43 -> -0.1346191 | T55: =T52-T43 -> -0.1346191 | U55: =U52-U43 -> -0.1346191 | V55: =V52-V43 -> -0.1346191
...

Sheet O1
D3: Traeger Pellet Grills | P3: DRAFT
D4: Historical Financials | P4: CONFIDENTIAL
D5: Data as of 2Q'25
H8: Year Ended | O8: ='Historical Financials'!AI7 -> Quarter Ended
H10: 2020 | I10: 2021 | J10: ='Historical Financials'!AD8 -> 2022 | K10: 2023 | L10: ='Historical Financials'!AF8 -> 2024 | M10: ='Historical Financials'!AG8 -> 2025 | N10: LTM 3Q25 | O10: ='Historical Financials'!AI8 -> 4Q'24 | P10: ='Historical Financials'!AJ8 -> 4Q'25
D12: Revenue
E13: Grills | H13: ='Historical Financials'!AB14 -> 391.047 | I13: ='Historical Financials'!AC14 -> 544.2 | J13: ='Historical Financials'!AD14 -> 355.441 | K13: ='Historical Financials'!AE14 -> 299.346 | L13: ='Historical Financials'!AF14 -> 324.702 | M13: ='Historical Financials'!AG14 -> 298.01 | N13: ='Historical Financials'!AH14 -> 315.419 | O13: ='Historical Financials'!AI14 -> 77.981 | P13: ='Historical Financials'!AJ14 -> 60.572 | R13: =M13/L13-1 -> -0.082204606
E14: Consumables | H14: ='Historical Financials'!AB15 -> 120.247 | I14: ='Historical Financials'!AC15 -> 136.216 | J14: ='Historical Financials'!AD15 -> 131.342 | K14: ='Historical Financials'!AE15 -> 114.901 | L14: ='Historical Financials'!AF15 -> 119.299 | M14: ='Historical Financials'!AG15 -> 127.51 | N14: ='Historical Financials'!AH15 -> 122.619 | O14: ='Historical Financials'!AI15 -> 30.678 | P14: ='Historical Financials'!AJ15 -> 35.569
E15: Accessories | H15: ='Historical Financials'!AB16 -> 34.478 | I15: ='Historical Financials'!AC16 -> 105.129 | J15: ='Historical Financials'!AD16 -> 169.118 | K15: ='Historical Financials'!AE16 -> 191.635 | L15: ='Historical Financials'!AF16 -> 160.071 | M15: ='Historical Financials'!AG16 -> 134 | N15: ='Historical Financials'!AH16 -> 144.762 | O15: ='Historical Financials'!AI16 -> 59.978 | P15: ='Historical Financials'!AJ16 -> 49.216
D16: Total Revenue | H16: ='Historical Financials'!AB17 -> 545.772 | I16: ='Historical Financials'!AC17 -> 785.545 | J16: ='Historical Financials'!AD17 -> 655.901 | K16: ='Historical Financials'!AE17 -> 605.882 | L16: ='Historical Financials'!AF17 -> 604.072 | M16: ='Historical Financials'!AG17 -> 559.52 | N16: ='Historical Financials'!AH17 -> 582.8 | O16: ='Historical Financials'!AI17 -> 168.637 | P16: ='Historical Financials'!AJ17 -> 145.357
E17: Cost of Revenue | H17: ='Historical Financials'!AB18 -> 310.408 | I17: ='Historical Financials'!AC18 -> 481.834 | J17: ='Historical Financials'!AD18 -> 427.129 | K17: ='Historical Financials'!AE18 -> 382.325 | L17: ='Historical Financials'!AF18 -> 348.603 | M17: ='Historical Financials'!AG18 -> 340.174 | N17: ='Historical Financials'!AH18 -> 348.904 | O17: ='Historical Financials'!AI18 -> 99.747 | P17: ='Historical Financials'!AJ18 -> 91.017
D18: Gross Profit | H18: ='Historical Financials'!AB19 -> 235.364 | I18: ='Historical Financials'!AC19 -> 303.711 | J18: ='Historical Financials'!AD19 -> 228.772 | K18: ='Historical Financials'!AE19 -> 223.557 | L18: ='Historical Financials'!AF19 -> 255.469 | M18: ='Historical Financials'!AG19 -> 219.346 | N18: ='Historical Financials'!AH19 -> 233.896 | O18: ='Historical Financials'!AI19 -> 68.89 | P18: ='Historical Financials'!AJ19 -> 54.34
E19: Gross Margin | H19: ='Historical Financials'!AB20 -> 0.43124968 | I19: ='Historical Financials'!AC20 -> 0.38662457 | J19: ='Historical Financials'!AD20 -> 0.34879044 | K19: ='Historical Financials'!AE20 -> 0.36897779 | L19: ='Historical Financials'!AF20 -> 0.42291151 | M19: ='Historical Financials'!AG20 -> 0.39202531 | N19: ='Historical Financials'!AH20 -> 0.4013315 | O19: ='Historical Financials'!AI20 -> 0.40851059 | P19: ='Historical Financials'!AJ20 -> 0.37383821 | AF19: Retail | AG19: 468.452 | AH19: =AG19/SUM($AG$19:$AG$20) -> 0.83723906
D20: Operating Expenses | AF20: DTC | AG20: 91.068 | AH20: =AG20/SUM($AG$19:$AG$20) -> 0.16276094
E21: Sales and Marketing | H21: ='Historical Financials'!AB24 -> 93.69 | I21: ='Historical Financials'!AC24 -> 165.18 | J21: ='Historical Financials'!AD24 -> 130.688 | K21: ='Historical Financials'!AE24 -> 108.727 | L21: ='Historical Financials'!AF24 -> 109.656 | M21: ='Historical Financials'!AG24 -> 90.217 | N21: ='Historical Financials'!AH24 -> 100.58 | O21: ='Historical Financials'!AI24 -> 33.591 | P21: ='Historical Financials'!AJ24 -> 23.228
E22: General and Admin | H22: ='Historical Financials'!AB25 -> 50.243 | I22: ='Historical Financials'!AC25 -> 158.555 | J22: ='Historical Financials'!AD25 -> 166.824 | K22: ='Historical Financials'!AE25 -> 129.8 | L22: ='Historical Financials'!AF25 -> 113.483 | M22: ='Historical Financials'!AG25 -> 95.031 | N22: ='Historical Financials'!AH25 -> 99.934 | O22: ='Historical Financials'!AI25 -> 26.719 | P22: ='Historical Financials'!AJ25 -> 21.816
E23: Amortization of Intangibles | H23: ='Historical Financials'!AB26 -> 32.533 | I23: ='Historical Financials'!AC26 -> 34.379 | J23: ='Historical Financials'!AD26 -> 35.554 | K23: ='Historical Financials'!AE26 -> 35.554 | L23: ='Historical Financials'!AF26 -> 35.274 | M23: ='Historical Financials'!AG26 -> 35.26 | N23: ='Historical Financials'!AH26 -> 35.265 | O23: ='Historical Financials'!AI26 -> 8.818 | P23: ='Historical Financials'!AJ26 -> 8.813 | AK23: Grills | AL23: =M13 -> 298.01
E24: Change in fair value of contingent consideration | H24: ='Historical Financials'!AB27 -> 0 | I24: ='Historical Financials'!AC27 -> 3.8 | J24: ='Historical Financials'!AD27 -> 10.002 | K24: ='Historical Financials'!AE27 -> 4.698 | L24: ='Historical Financials'!AF27 -> 0 | M24: ='Historical Financials'!AG27 -> 0 | N24: ='Historical Financials'!AH27 -> 0 | O24: ='Historical Financials'!AI27 -> 0 | P24: ='Historical Financials'!AJ27 -> 0 | AK24: Consumables | AL24: =M14 -> 127.51
E25: Goodwill impairment | H25: ='Historical Financials'!AB28 -> 0 | I25: ='Historical Financials'!AC28 -> 0 | J25: ='Historical Financials'!AD28 -> 222.322 | K25: ='Historical Financials'!AE28 -> 0 | L25: ='Historical Financials'!AF28 -> 0 | M25: ='Historical Financials'!AG28 -> 74.725 | N25: ='Historical Financials'!AH28 -> 74.725 | O25: ='Historical Financials'!AI28 -> 0 | P25: ='Historical Financials'!AJ28 -> 0 | AK25: Accessories | AL25: =M15 -> 134
E26: Restructuring Charges | H26: ='Historical Financials'!AB29 -> 0 | I26: ='Historical Financials'!AC29 -> 0 | J26: ='Historical Financials'!AD29 -> 9.324 | K26: ='Historical Financials'!AE29 -> 0.225 | L26: ='Historical Financials'!AF29 -> 0 | M26: ='Historical Financials'!AG29 -> 21.84 | N26: ='Historical Financials'!AH29 -> 9.672 | O26: ='Historical Financials'!AI29 -> 0 | P26: ='Historical Financials'!AJ29 -> 12.168 | AK26: Other | AL26: =SUM(AL24:AL25) -> 261.51
D27: Operating Income | H27: ='Historical Financials'!AB30 -> 58.898 | I27: ='Historical Financials'!AC30 -> -58.203 | J27: ='Historical Financials'!AD30 -> -345.942 | K27: ='Historical Financials'!AE30 -> -55.447 | L27: ='Historical Financials'!AF30 -> -2.944 | M27: ='Historical Financials'!AG30 -> -97.727 | N27: ='Historical Financials'!AH30 -> -86.28 | O27: ='Historical Financials'!AI30 -> -0.238 | P27: ='Historical Financials'!AJ30 -> -11.685
E28: Interest Expense, Net | H28: ='Historical Financials'!AB31 -> -34.073 | I28: ='Historical Financials'!AC31 -> -26.646 | J28: ='Historical Financials'!AD31 -> -27.885 | K28: ='Historical Financials'!AE31 -> -31.275 | L28: ='Historical Financials'!AF31 -> -33.5 | M28: ='Historical Financials'!AG31 -> -31.35 | N28: ='Historical Financials'!AH31 -> -31.991 | O28: ='Historical Financials'!AI31 -> -8.192 | P28: ='Historical Financials'!AJ31 -> -7.551
E29: Loss on extinguishment of debt | H29: ='Historical Financials'!AB32 -> 0 | I29: ='Historical Financials'!AC32 -> -5.185 | J29: ='Historical Financials'!AD32 -> 0 | K29: ='Historical Financials'!AE32 -> 0 | L29: ='Historical Financials'!AF32 -> 0 | M29: ='Historical Financials'!AG32 -> 0 | N29: ='Historical Financials'!AH32 -> 0 | O29: ='Historical Financials'!AI32 -> 0 | P29: ='Historical Financials'!AJ32 -> 0
E30: Other Income (expense) | H30: ='Historical Financials'!AB33 -> 7.526 | I30: ='Historical Financials'!AC33 -> 2.702 | J30: ='Historical Financials'!AD33 -> -7.127 | K30: ='Historical Financials'!AE33 -> 4.305 | L30: ='Historical Financials'!AF33 -> 0.48 | M30: ='Historical Financials'!AG33 -> 9.755 | N30: ='Historical Financials'!AH33 -> 9.05 | O30: ='Historical Financials'!AI33 -> -0.513 | P30: ='Historical Financials'!AJ33 -> 0.192
D31: Income (Loss) Before Tax | H31: ='Historical Financials'!AB34 -> 32.351 | I31: ='Historical Financials'!AC34 -> -87.332 | J31: ='Historical Financials'!AD34 -> -380.954 | K31: ='Historical Financials'!AE34 -> -82.417 | L31: ='Historical Financials'!AF34 -> -35.964 | M31: ='Historical Financials'!AG34 -> -119.322 | N31: ='Historical Financials'!AH34 -> -109.221 | O31: ='Historical Financials'!AI34 -> -8.943 | P31: ='Historical Financials'!AJ34 -> -19.044
E32: Provision (benefit) for Income Tax | H32: ='Historical Financials'!AB35 -> 0.749 | I32: ='Historical Financials'!AC35 -> 1.489 | J32: ='Historical Financials'!AD35 -> 1.186 | K32: ='Historical Financials'!AE35 -> 1.985 | L32: ='Historical Financials'!AF35 -> -1.956 | M32: ='Historical Financials'!AG35 -> -4.141 | N32: ='Historical Financials'!AH35 -> -4.283 | O32: ='Historical Financials'!AI35 -> -1.985 | P32: ='Historical Financials'!AJ35 -> -1.843
E33: Interest expense | H33: ='Historical Financials'!AB41 -> 34.073 | I33: ='Historical Financials'!AC41 -> 26.646 | J33: ='Historical Financials'!AD41 -> 27.885 | K33: ='Historical Financials'!AE41 -> 31.275 | L33: ='Historical Financials'!AF41 -> 33.5 | M33: ='Historical Financials'!AG41 -> 31.35 | N33: ='Historical Financials'!AH41 -> 31.991 | O33: ='Historical Financials'!AI41 -> 8.192 | P33: ='Historical Financials'!AJ41 -> 7.551
E34: Depreciation and amortization | H34: ='Historical Financials'!AB42 -> 40.968 | I34: ='Historical Financials'!AC42 -> 47.499 | J34: ='Historical Financials'!AD42 -> 56.617 | K34: ='Historical Financials'!AE42 -> 57.778 | L34: ='Historical Financials'!AF42 -> 56.327 | M34: ='Historical Financials'!AG42 -> 54.137 | N34: ='Historical Financials'!AH42 -> 55.103 | O34: ='Historical Financials'!AI42 -> 14.251 | P34: ='Historical Financials'!AJ42 -> 13.285
E35: Other (income) expense | H35: ='Historical Financials'!AB43 -> -5.947 | I35: ='Historical Financials'!AC43 -> 10.518 | J35: ='Historical Financials'!AD43 -> 2.466 | K35: ='Historical Financials'!AE43 -> -5.216 | L35: ='Historical Financials'!AF43 -> -1.614 | M35: ='Historical Financials'!AG43 -> -5.093 | N35: ='Historical Financials'!AH43 -> -4.614 | O35: ='Historical Financials'!AI43 -> 0.011 | P35: ='Historical Financials'!AJ43 -> -0.468
E36: Goodwill impairment | H36: ='Historical Financials'!AB44 -> 0 | I36: ='Historical Financials'!AC44 -> 0 | J36: ='Historical Financials'!AD44 -> 222.322 | K36: ='Historical Financials'!AE44 -> 0 | L36: ='Historical Financials'!AF44 -> 0 | M36: ='Historical Financials'!AG44 -> 74.725 | N36: ='Historical Financials'!AH44 -> 74.725 | O36: ='Historical Financials'!AI44 -> 0 | P36: ='Historical Financials'!AJ44 -> 0
E37: Restructuring costs | H37: ='Historical Financials'!AB45 -> 0 | I37: ='Historical Financials'!AC45 -> 0 | J37: ='Historical Financials'!AD45 -> 11.542 | K37: ='Historical Financials'!AE45 -> 0.225 | L37: ='Historical Financials'!AF45 -> 27.901 | M37: ='Historical Financials'!AG45 -> 24.942 | N37: ='Historical Financials'!AH45 -> 9.672 | O37: ='Historical Financials'!AI45 -> 0 | P37: ='Historical Financials'!AJ45 -> 15.27
E38: Equity-based compensation | H38: ='Historical Financials'!AB46 -> 12.81 | I38: ='Historical Financials'!AC46 -> 81.112 | J38: ='Historical Financials'!AD46 -> 87.697 | K38: ='Historical Financials'!AE46 -> 53.203 | L38: ='Historical Financials'!AF46 -> 1.794 | M38: ='Historical Financials'!AG46 -> 15.254 | N38: ='Historical Financials'!AH46 -> 17.313 | O38: ='Historical Financials'!AI46 -> 4.837 | P38: ='Historical Financials'!AJ46 -> 2.778
E39: Other adjustment items | H39: ='Historical Financials'!AB47 -> 1.82 | I39: ='Historical Financials'!AC54 -> 30.564 | J39: ='Historical Financials'!AD54 -> 13.952 | K39: ='Historical Financials'!AE54 -> 6.245 | L39: ='Historical Financials'!AF54 -> 0 | M39: ='Historical Financials'!AG54 -> -6.049 | N39: ='Historical Financials'!AH54 -> -6.036 | O39: ='Historical Financials'!AI54 -> 0.013 | P39: ='Historical Financials'!AJ54 -> 0
D40: Adjusted EBITDA | H40: ='Historical Financials'!AB55 -> 116.075 | I40: ='Historical Financials'!AC55 -> 109.007 | J40: ='Historical Financials'!AD55 -> 41.527 | K40: ='Historical Financials'!AE55 -> 61.093 | L40: ='Historical Financials'!AF55 -> 81.944 | M40: ='Historical Financials'!AG55 -> 69.969 | N40: ='Historical Financials'!AH55 -> 68.956 | O40: ='Historical Financials'!AI55 -> 18.361 | P40: ='Historical Financials'!AJ55 -> 19.372
E41: Margin | H41: ='Historical Financials'!AB56 -> 0.21268039 | I41: ='Historical Financials'!AC56 -> 0.13876608 | J41: ='Historical Financials'!AD56 -> 0.063312909 | K41: ='Historical Financials'!AE56 -> 0.10083317 | L41: ='Historical Financials'!AF56 -> 0.1356527 | M41: ='Historical Financials'!AG56 -> 0.12505183 | N41: ='Historical Financials'!AH56 -> 0.11831846 | O41: ='Historical Financials'!AI56 -> 0.10887883 | P41: ='Historical Financials'!AJ56 -> 0.13327188
E42: Less: Change in NWC | H42: ='Historical Financials'!AB69 -> -35.092 | I42: ='Historical Financials'!AC69 -> -82.343 | J42: ='Historical Financials'!AD69 -> 6.204 | K42: ='Historical Financials'!AE69 -> 37.167 | L42: ='Historical Financials'!AF69 -> -17.031 | M42: ='Historical Financials'!AG69 -> -9.023 | N42: ='Historical Financials'!AH69 -> -33.363 | O42: ='Historical Financials'!AI69 -> -4.999 | P42: ='Historical Financials'!AJ69 -> 19.341
E43: Less: Capex | H43: ='Historical Financials'!AB70 -> -14.127 | I43: ='Historical Financials'!AC70 -> -22.479 | J43: ='Historical Financials'!AD70 -> -18.398 | K43: ='Historical Financials'!AE70 -> -19.946 | L43: ='Historical Financials'!AF70 -> -11.996 | M43: ='Historical Financials'!AG70 -> -6.934 | N43: ='Historical Financials'!AH70 -> -7.576 | O43: ='Historical Financials'!AI70 -> -1.962 | P43: ='Historical Financials'!AJ70 -> -1.32
E44: Less: Provision for income tax | H44: =-H32 -> -0.749 | I44: =-I32 -> -1.489 | J44: =-J32 -> -1.186 | K44: =-K32 -> -1.985 | L44: =-L32 -> 1.956 | M44: =-M32 -> 4.141 | N44: =-N32 -> 4.283 | O44: =-O32 -> 1.985 | P44: =-P32 -> 1.843
D45: ='O2'!D31 -> FCF | H45: =H40+SUM(H42:H44) -> 66.107 | I45: =I40+SUM(I42:I44) -> 2.696 | J45: =J40+SUM(J42:J44) -> 28.147 | K45: =K40+SUM(K42:K44) -> 76.329 | L45: =L40+SUM(L42:L44) -> 54.873 | M45: =M40+SUM(M42:M44) -> 58.153 | N45: =N40+SUM(N42:N44) -> 32.3 | O45: =O40+SUM(O42:O44) -> 13.385 | P45: =P40+SUM(P42:P44) -> 39.236
E46: ='Historical Financials'!D72 -> Less: Interest Expense | H46: ='Historical Financials'!AB72 -> -34.073 | I46: ='Historical Financials'!AC72 -> -26.646 | J46: ='Historical Financials'!AD72 -> -27.885 | K46: ='Historical Financials'!AE72 -> -31.275 | L46: ='Historical Financials'!AF72 -> -33.5 | M46: ='Historical Financials'!AG72 -> -31.35 | N46: ='Historical Financials'!AH72 -> -31.991 | O46: ='Historical Financials'!AI72 -> -8.192 | P46: ='Historical Financials'!AJ72 -> -7.551
...

Sheet O2
D3: Traeger Pellet Grills | P3: DRAFT
D4: Historical Financials | P4: CONFIDENTIAL
D5: Data as of 2Q'25
H8: Year Ended | O8: ='Historical Financials'!AI7 -> Quarter Ended
H10: 2020 | I10: 2021 | J10: ='Historical Financials'!AD8 -> 2022 | K10: 2023 | L10: ='Historical Financials'!AF8 -> 2024 | M10: ='Historical Financials'!AG8 -> 2025 | N10: LTM 3Q25 | O10: ='Historical Financials'!AI8 -> 4Q'24 | P10: ='Historical Financials'!AJ8 -> 4Q'25
D12: Revenue
D13: Grills | H13: ='Historical Financials'!AB14 -> 391.047 | I13: ='Historical Financials'!AC14 -> 544.2 | J13: ='Historical Financials'!AD14 -> 355.441 | K13: ='Historical Financials'!AE14 -> 299.346 | L13: ='Historical Financials'!AF14 -> 324.702 | M13: ='Historical Financials'!AG14 -> 298.01 | N13: ='O1'!N13 -> 315.419 | O13: ='Historical Financials'!AI14 -> 77.981 | P13: ='Historical Financials'!AJ14 -> 60.572
D14: Consumables | H14: ='Historical Financials'!AB15 -> 120.247 | I14: ='Historical Financials'!AC15 -> 136.216 | J14: ='Historical Financials'!AD15 -> 131.342 | K14: ='Historical Financials'!AE15 -> 114.901 | L14: ='Historical Financials'!AF15 -> 119.299 | M14: ='Historical Financials'!AG15 -> 127.51 | N14: ='O1'!N14 -> 122.619 | O14: ='Historical Financials'!AI15 -> 30.678 | P14: ='Historical Financials'!AJ15 -> 35.569
D15: Accessories | H15: ='Historical Financials'!AB16 -> 34.478 | I15: ='Historical Financials'!AC16 -> 105.129 | J15: ='Historical Financials'!AD16 -> 169.118 | K15: ='Historical Financials'!AE16 -> 191.635 | L15: ='Historical Financials'!AF16 -> 160.071 | M15: ='Historical Financials'!AG16 -> 134 | N15: ='O1'!N15 -> 144.762 | O15: ='Historical Financials'!AI16 -> 59.978 | P15: ='Historical Financials'!AJ16 -> 49.216
D16: Total Revenue | H16: ='Historical Financials'!AB17 -> 545.772 | I16: ='Historical Financials'!AC17 -> 785.545 | J16: ='Historical Financials'!AD17 -> 655.901 | K16: ='Historical Financials'!AE17 -> 605.882 | L16: ='Historical Financials'!AF17 -> 604.072 | M16: ='Historical Financials'!AG17 -> 559.52 | N16: ='Historical Financials'!AH17 -> 582.8 | O16: ='Historical Financials'!AI17 -> 168.637 | P16: ='Historical Financials'!AJ17 -> 145.357
D17: YoY Growth | H17: =H16/'Historical Financials'!AA17-1 -> 0.50218403 | I17: =I16/H16-1 -> 0.43932814 | J17: =J16/I16-1 -> -0.16503701 | K17: =K16/J16-1 -> -0.076259984 | L17: =L16/K16-1 -> -0.0029873804 | M17: =M16/L16-1 -> -0.073752798 | N17: =N16/L16-1 -> -0.035214345 | O17: =O16/'Historical Financials'!M17-1 -> 0.22083065 | P17: =P16/O16-1 -> -0.138048
C18: Adjusted EBITDA | D18: Adjusted EBITDA | H18: ='Historical Financials'!AB55 -> 116.075 | I18: ='Historical Financials'!AC55 -> 109.007 | J18: ='Historical Financials'!AD55 -> 41.527 | K18: ='Historical Financials'!AE55 -> 61.093 | L18: ='Historical Financials'!AF55 -> 81.944 | M18: ='Historical Financials'!AG55 -> 69.969 | N18: ='Historical Financials'!AH55 -> 68.956 | O18: ='Historical Financials'!AI55 -> 18.361 | P18: ='Historical Financials'!AJ55 -> 19.372
D19: Margin | H19: =H18/H16 -> 0.21268039 | I19: =I18/I16 -> 0.13876608 | J19: =J18/J16 -> 0.063312909 | K19: =K18/K16 -> 0.10083317 | L19: =L18/L16 -> 0.1356527 | M19: =M18/M16 -> 0.12505183 | N19: =N18/N16 -> 0.11831846 | O19: =O18/O16 -> 0.10887883 | P19: =P18/P16 -> 0.13327188
C20: Change in NWC | D20: Change in NWC
C21: A/R | D21: ='Historical Financials'!D63 -> Accounts receivable | H21: ='Historical Financials'!AB63 -> -30.17 | I21: ='Historical Financials'!AC63 -> -26.365 | J21: ='Historical Financials'!AD63 -> 51.052 | K21: ='Historical Financials'!AE63 -> -17.735 | L21: ='Historical Financials'!AF63 -> -25.396 | M21: ='Historical Financials'!AG63 -> 3.15 | N21: ='Historical Financials'!AH63 -> -9.896 | O21: ='Historical Financials'!AI63 -> -14.545 | P21: ='Historical Financials'!AJ63 -> -1.499
C22: Inventories | D22: ='Historical Financials'!D64 -> Inventories, net | H22: ='Historical Financials'!AB64 -> -28.979 | I22: ='Historical Financials'!AC64 -> -67.826 | J22: ='Historical Financials'!AD64 -> -11.931 | K22: ='Historical Financials'!AE64 -> 57.295 | L22: ='Historical Financials'!AF64 -> -11.192 | M22: ='Historical Financials'!AG64 -> 8.536 | N22: ='Historical Financials'!AH64 -> -9.568 | O22: ='Historical Financials'!AI64 -> -2.309 | P22: ='Historical Financials'!AJ64 -> 15.795
C23: Prepaid expenses | D23: ='Historical Financials'!D65 -> Prepaid expenses and other current assets | H23: ='Historical Financials'!AB65 -> -4.311 | I23: ='Historical Financials'!AC65 -> -5.787 | J23: ='Historical Financials'!AD65 -> -3.046 | K23: ='Historical Financials'!AE65 -> -4.199 | L23: ='Historical Financials'!AF65 -> -7.573 | M23: ='Historical Financials'!AG65 -> 14.355 | N23: ='Historical Financials'!AH65 -> 5.422 | O23: ='Historical Financials'!AI65 -> -10.169 | P23: ='Historical Financials'!AJ65 -> -1.236
C24: Other assets | D24: ='Historical Financials'!D66 -> Other non-current assets | H24: ='Historical Financials'!AB66 -> 0 | I24: ='Historical Financials'!AC66 -> -0.681 | J24: ='Historical Financials'!AD66 -> 0.078 | K24: ='Historical Financials'!AE66 -> -0.568 | L24: ='Historical Financials'!AF66 -> 0.148 | M24: ='Historical Financials'!AG66 -> 0.114 | N24: ='Historical Financials'!AH66 -> 0.157 | O24: ='Historical Financials'!AI66 -> 0.062 | P24: ='Historical Financials'!AJ66 -> 0.019
C25: A/P | D25: ='Historical Financials'!D67 -> Accounts payable and accrued expenses | H25: ='Historical Financials'!AB67 -> 28.351 | I25: ='Historical Financials'!AC67 -> 19.182 | J25: ='Historical Financials'!AD67 -> -28.211 | K25: ='Historical Financials'!AE67 -> 2.374 | L25: ='Historical Financials'!AF67 -> 26.982 | M25: ='Historical Financials'!AG67 -> -35.178 | N25: ='Historical Financials'!AH67 -> -19.478 | O25: ='Historical Financials'!AI67 -> 21.962 | P25: ='Historical Financials'!AJ67 -> 6.262
C26: Other liabilities | D26: ='Historical Financials'!D68 -> Other non-current liabilities | H26: ='Historical Financials'!AB68 -> 0.017 | I26: ='Historical Financials'!AC68 -> -0.866 | J26: ='Historical Financials'!AD68 -> -1.738 | K26: ='Historical Financials'!AE68 -> 0 | L26: ='Historical Financials'!AF68 -> 0 | M26: ='Historical Financials'!AG68 -> 0 | N26: ='Historical Financials'!AH68 -> 0 | O26: ='Historical Financials'!AI68 -> 0 | P26: ='Historical Financials'!AJ68 -> 0
C27: Total Change in NWC | D27: Total Change in NWC | H27: =SUM(H21:H26) -> -35.092 | I27: =SUM(I21:I26) -> -82.343 | J27: =SUM(J21:J26) -> 6.204 | K27: =SUM(K21:K26) -> 37.167 | L27: =SUM(L21:L26) -> -17.031 | M27: =SUM(M21:M26) -> -9.023 | N27: =SUM(N21:N26) -> -33.363 | O27: =SUM(O21:O26) -> -4.999 | P27: =SUM(P21:P26) -> 19.341
E28: Change in NWC Check | H28: ='Historical Financials'!AB69 -> -35.092 | I28: ='Historical Financials'!AC69 -> -82.343 | J28: ='Historical Financials'!AD69 -> 6.204 | K28: ='Historical Financials'!AE69 -> 37.167 | L28: ='Historical Financials'!AF69 -> -17.031 | M28: ='Historical Financials'!AG69 -> -9.023 | N28: ='Historical Financials'!AH69 -> -33.363 | O28: ='Historical Financials'!AI69 -> -4.999 | P28: ='Historical Financials'!AJ69 -> 19.341
C29: Capex | D29: Less: Capex | H29: ='Historical Financials'!AB70 -> -14.127 | I29: ='Historical Financials'!AC70 -> -22.479 | J29: ='Historical Financials'!AD70 -> -18.398 | K29: ='Historical Financials'!AE70 -> -19.946 | L29: ='Historical Financials'!AF70 -> -11.996 | M29: ='Historical Financials'!AG70 -> -6.934 | N29: ='Historical Financials'!AH70 -> -7.576 | O29: ='Historical Financials'!AI70 -> -1.962 | P29: ='Historical Financials'!AJ70 -> -1.32
C30: Income taxes | D30: Less: Provision for income taxes | H30: =-'O1'!H32 -> -0.749 | I30: =-'O1'!I32 -> -1.489 | J30: =-'O1'!J32 -> -1.186 | K30: =-'O1'!K32 -> -1.985 | L30: =-'O1'!L32 -> 1.956 | M30: =-'O1'!M32 -> 4.141 | N30: =-'O1'!N32 -> 4.283 | O30: =-'O1'!O32 -> 1.985 | P30: =-'O1'!P32 -> 1.843
C31: FCF | D31: FCF | H31: =H18+SUM(H27,H29:H30) -> 66.107 | I31: =I18+SUM(I27,I29:I30) -> 2.696 | J31: =J18+SUM(J27,J29:J30) -> 28.147 | K31: =K18+SUM(K27,K29:K30) -> 76.329 | L31: =L18+SUM(L27,L29:L30) -> 54.873 | M31: =M18+SUM(M27,M29:M30) -> 58.153 | N31: =N18+SUM(N27,N29:N30) -> 32.3 | O31: =O18+SUM(O27,O29:O30) -> 13.385 | P31: =P18+SUM(P27,P29:P30) -> 39.236
E32: Less: Interest expense | H32: ='Historical Financials'!AB72 -> -34.073 | I32: ='Historical Financials'!AC72 -> -26.646 | J32: ='Historical Financials'!AD72 -> -27.885 | K32: ='Historical Financials'!AE72 -> -31.275 | L32: ='Historical Financials'!AH72 -> -31.991 | O32: ='Historical Financials'!AI72 -> -8.192 | P32: ='Historical Financials'!AJ72 -> -7.551
E33: Less: Mandatory amortization | H33: ='Historical Financials'!AB73 -> -5.1 | I33: ='Historical Financials'!AC73 -> -5.1 | J33: ='Historical Financials'!AD73 -> -5.1 | K33: ='Historical Financials'!AE73 -> -5.1 | L33: ='Historical Financials'!AH73 -> -5.1 | O33: ='Historical Financials'!AI73 -> -1.275 | P33: ='Historical Financials'!AJ73 -> -1.275
D34: Levered FCF | H34: =SUM(H31:H33) -> 26.934 | I34: =SUM(I31:I33) -> -29.05 | J34: =SUM(J31:J33) -> -4.838 | K34: =SUM(K31:K33) -> 39.954 | L34: =SUM(L31:L33) -> 17.782 | O34: =SUM(O31:O33) -> 3.918 | P34: =SUM(P31:P33) -> 30.41

Sheet O3
D3: Traeger Pellet Grills | O3: DRAFT
D4: Liquidity Model Output | G4: Case | H4: ='Liquidity Model'!F8 -> 2 | J4: Print Screen | K4: 1 | O4: CONFIDENTIAL
D5: Data as of 1Q'25
F6: Actuals | K6: Forecast
F8: 1Q'25 | G8: 2Q'25 | H8: 3Q'25 | I8: 4Q'25 | J8: FY'25 | K8: 1Q'26 | L8: 2Q'26 | M8: 3Q'26 | N8: 4Q'26 | O8: FY'26
D10: Revenue
D11: Grills | F11: ='Liquidity Model'!O196 -> 86.685 | G11: ='Liquidity Model'!P196 -> 74.184 | H11: ='Liquidity Model'!Q196 -> 76.569 | I11: ='Liquidity Model'!R196 -> 60.572 | J11: =SUM(F11:I11) -> 298.01 | K11: ='Liquidity Model'!S196 -> 76.2828 | L11: ='Liquidity Model'!T196 -> 65.28192 | M11: ='Liquidity Model'!U196 -> 67.38072 | N11: ='Liquidity Model'!V196 -> 53.30336 | O11: =SUM(K11:N11) -> 262.2488
D12: Consumables | F12: ='Liquidity Model'!O197 -> 30.288 | G12: ='Liquidity Model'!P197 -> 36.357 | H12: ='Liquidity Model'!Q197 -> 25.296 | I12: ='Liquidity Model'!R197 -> 35.569 | J12: =SUM(F12:I12) -> 127.51 | K12: ='Liquidity Model'!S197 -> 30.288 | L12: ='Liquidity Model'!T197 -> 36.357 | M12: ='Liquidity Model'!U197 -> 25.296 | N12: ='Liquidity Model'!V197 -> 35.569 | O12: =SUM(K12:N12) -> 127.51
D13: Accessories | F13: ='Liquidity Model'!O198 -> 26.31 | G13: ='Liquidity Model'!P198 -> 34.943 | H13: ='Liquidity Model'!Q198 -> 23.531 | I13: ='Liquidity Model'!R198 -> 49.216 | J13: =SUM(F13:I13) -> 134 | K13: ='Liquidity Model'!S198 -> 16.5753 | L13: ='Liquidity Model'!T198 -> 22.01409 | M13: ='Liquidity Model'!U198 -> 14.82453 | N13: ='Liquidity Model'!V198 -> 31.00608 | O13: =SUM(K13:N13) -> 84.42
D14: Total Revenue | F14: ='Liquidity Model'!O199 -> 143.283 | G14: ='Liquidity Model'!P199 -> 145.484 | H14: ='Liquidity Model'!Q199 -> 125.396 | I14: ='Liquidity Model'!R199 -> 145.357 | J14: =SUM(F14:I14) -> 559.52 | K14: ='Liquidity Model'!S199 -> 123.1461 | L14: ='Liquidity Model'!T199 -> 123.65301 | M14: ='Liquidity Model'!U199 -> 107.50125 | N14: ='Liquidity Model'!V199 -> 119.87844 | O14: =SUM(K14:N14) -> 474.1788
D16: Cost of Revenue | F16: ='Liquidity Model'!O200 -> -83.824 | G16: ='Liquidity Model'!P200 -> -88.483 | H16: ='Liquidity Model'!Q200 -> -76.85 | I16: ='Liquidity Model'!R200 -> -91.017 | J16: =SUM(F16:I16) -> -340.174 | K16: ='Liquidity Model'!S200 -> -75.734852 | L16: ='Liquidity Model'!T200 -> -76.046601 | M16: ='Liquidity Model'!U200 -> -66.113269 | N16: ='Liquidity Model'!V200 -> -73.725241 | O16: =SUM(K16:N16) -> -291.61996
D17: Gross Profit | F17: ='Liquidity Model'!O201 -> 59.459 | G17: ='Liquidity Model'!P201 -> 57.001 | H17: ='Liquidity Model'!Q201 -> 48.546 | I17: ='Liquidity Model'!R201 -> 54.34 | J17: =SUM(F17:I17) -> 219.346 | K17: ='Liquidity Model'!S201 -> 47.411248 | L17: ='Liquidity Model'!T201 -> 47.606409 | M17: ='Liquidity Model'!U201 -> 41.387981 | N17: ='Liquidity Model'!V201 -> 46.153199 | O17: =SUM(K17:N17) -> 182.55884
D18: Gross Margin | F18: ='Liquidity Model'!O229 -> 0.41497596 | G18: ='Liquidity Model'!P229 -> 0.39180253 | H18: ='Liquidity Model'!Q229 -> 0.38714154 | I18: ='Liquidity Model'!R229 -> 0.37383821 | J18: =J17/J14 -> 0.39202531 | K18: ='Liquidity Model'!S229 -> 0.385 | L18: ='Liquidity Model'!T229 -> 0.385 | M18: ='Liquidity Model'!U229 -> 0.385 | N18: ='Liquidity Model'!V229 -> 0.385 | O18: =O17/O14 -> 0.385
D20: Operating Expenses
D21: Sales and Marketing | F21: ='Liquidity Model'!O204 -> -22.21 | G21: ='Liquidity Model'!P204 -> -24.779 | H21: ='Liquidity Model'!Q204 -> -20 | I21: ='Liquidity Model'!R204 -> -23.228 | J21: =SUM(F21:I21) -> -90.217 | K21: ='Liquidity Model'!S204 -> -21.988 | L21: ='Liquidity Model'!T204 -> -24.779 | M21: ='Liquidity Model'!U204 -> -20 | N21: ='Liquidity Model'!V204 -> -23.228 | O21: =SUM(K21:N21) -> -89.995
D22: G&A (excl. D&A) | F22: ='Liquidity Model'!O205 -> -10.777 | G22: ='Liquidity Model'!P205 -> -12.724 | H22: ='Liquidity Model'!Q205 -> -8.862 | I22: ='Liquidity Model'!R205 -> -8.531 | J22: =SUM(F22:I22) -> -40.894 | K22: ='Liquidity Model'!S205 -> -8.620227 | L22: ='Liquidity Model'!T205 -> -8.620227 | M22: ='Liquidity Model'!U205 -> -8.620227 | N22: ='Liquidity Model'!V205 -> -8.620227 | O22: =SUM(K22:N22) -> -34.480908
D23: Other Op. Expenses | F23: ='Liquidity Model'!O206 -> -8.818 | G23: ='Liquidity Model'!P206 -> -12.284 | H23: ='Liquidity Model'!Q206 -> -89.742 | I23: ='Liquidity Model'!R206 -> -20.981 | J23: =SUM(F23:I23) -> -131.825 | K23: ='Liquidity Model'!S206 -> -12.31461 | L23: ='Liquidity Model'!T206 -> -12.365301 | M23: ='Liquidity Model'!U206 -> -10.750125 | N23: ='Liquidity Model'!V206 -> -11.987844 | O23: =SUM(K23:N23) -> -47.41788
D24: Operating Income | F24: ='Liquidity Model'!O207 -> 17.654 | G24: ='Liquidity Model'!P207 -> 7.214 | H24: ='Liquidity Model'!Q207 -> -70.058 | I24: ='Liquidity Model'!R207 -> 1.6 | J24: =SUM(F24:I24) -> -43.59 | K24: ='Liquidity Model'!S207 -> 4.4884115 | L24: ='Liquidity Model'!T207 -> 1.8418808 | M24: ='Liquidity Model'!U207 -> 2.0176292 | N24: ='Liquidity Model'!V207 -> 2.3171284 | O24: =SUM(K24:N24) -> 10.66505
D26: Share-based comp. | F26: ='Liquidity Model'!O208 -> 5.176 | G26: ='Liquidity Model'!P208 -> 3.969 | H26: ='Liquidity Model'!Q208 -> 3.331 | I26: ='Liquidity Model'!R208 -> 2.778 | J26: =SUM(F26:I26) -> 15.254 | K26: ='Liquidity Model'!S208 -> 3.694383 | L26: ='Liquidity Model'!T208 -> 3.7095903 | M26: ='Liquidity Model'!U208 -> 3.2250375 | N26: ='Liquidity Model'!V208 -> 3.5963532 | O26: =SUM(K26:N26) -> 14.225364
D27: Other adjustment items(1) | F27: ='Liquidity Model'!O209 -> -0.308 | G27: ='Liquidity Model'!P209 -> 3.065 | H27: ='Liquidity Model'!Q209 -> 80.529 | I27: ='Liquidity Model'!R209 -> 14.994 | J27: =SUM(F27:I27) -> 98.28 | K27: ='Liquidity Model'!S209 -> 7.5 | L27: ='Liquidity Model'!T209 -> 7.5 | M27: ='Liquidity Model'!U209 -> 7.5 | N27: ='Liquidity Model'!V209 -> 7.5 | O27: =SUM(K27:N27) -> 30
