Workbook

Sheet Cover Page
A1: Return to Cover
C2: Xerox Holdings Corporation (NASDAQ: XRX) – Restructuring Model
C3: All $ in Millions (USD), except Per-Share Values
C6: XEROX HOLDINGS CORPORATION
C7: Credit & Restructuring Analysis
C13: Last Updated | D13: =TODAY() | H13: Data As Of | I13: 2Q'26 (June 30, 2026)
C15: Color Coding | D15: R | E15: G | F15: B | H15: Links (Ctrl + [ to Jump to Sheet)
C16: Formulas | D16: 0 | E16: 0 | F16: 0 | H16: Financial Statements
C17: Hard-Code | D17: 0 | E17: 0 | F17: 255 | H17: ='IS'!A1
C18: Link to Other Sheets | D18: 0 | E18: 128 | F18: 0 | H18: ='IS Out'!A1
C19: Highlight Value (Check) | D19: 255 | E19: 0 | F19: 0 | H19: ='CFS'!A1
H20: ='CFS Out'!A1
C21: Heading 1 | D21: 0 | E21: 32 | F21: 96 | H21: ='BS'!A1
C22: Heading 2 | D22: 128 | E22: 128 | F22: 128 | H22: ='BS Out'!A1
H23: Credit Analysis
C24: Input/Driver | D24: 255 | E24: 242 | F24: 204 | H24: ='NWC'!A1
H25: ='Quarterly NWC'!A1
C26: Sources | H26: ='Capital Structure'!A1
C27: SEC EDGAR – Xerox 10-K & 10-Q Filings | H27: ='Maturity Schedule'!A1
C28: Xerox Investor Relations – Earnings Materials | H28: ='Pricing'!A1
C29: Moody's & S&P Rating Actions | H29: References
C30: TRACE-Based Bond Quotes (Indicative) | H30: ='Sources'!A1
C31: Federal Reserve Bank of New York – SOFR
C32: Note: All Financials Pulled from Xerox 10-Qs & 10-Ks

Sheet Financial Statements >
A1: Financial Statements > | B1: ='Cover Page'!A1

Sheet IS
A1: =D3 | B1: ='Cover Page'!A1
D3: Historical Income Statement
D4: Xerox Holdings Corporation – All values in $ millions (USD), except per-share values. Data as of June 30, 2026 (2Q'26); fiscal year ends December 31.
A5: x | D5: Income Statement | E5: Quarter Ended | AB5: Fiscal Year Ended December 31, | AH5: LTM
E6: 1 | F6: 2 | G6: 3 | H6: 4 | I6: 1 | J6: 2 | K6: 3 | L6: 4 | M6: 1 | N6: 2 | O6: 3 | P6: 4 | Q6: 1 | R6: 2 | S6: 3 | T6: 4 | U6: 1 | V6: 2 | W6: 3 | X6: 4 | Y6: 1 | Z6: 2
E7: 2021 | F7: 2021 | G7: 2021 | H7: 2021 | I7: 2022 | J7: 2022 | K7: 2022 | L7: 2022 | M7: 2023 | N7: 2023 | O7: 2023 | P7: 2023 | Q7: 2024 | R7: 2024 | S7: 2024 | T7: 2024 | U7: 2025 | V7: 2025 | W7: 2025 | X7: 2025 | Y7: 2026 | Z7: 2026 | AB7: 2021 | AC7: 2022 | AD7: 2023 | AE7: 2024 | AF7: 2025
E8: 44286 | F8: 44377 | G8: 44469 | H8: 44561 | I8: 44651 | J8: 44742 | K8: 44834 | L8: 44926 | M8: 45016 | N8: 45107 | O8: 45199 | P8: 45291 | Q8: 45382 | R8: 45473 | S8: 45565 | T8: 45657 | U8: 45747 | V8: 45838 | W8: 45930 | X8: 46022 | Y8: 46112 | Z8: 46203 | AB8: 44561 | AC8: 44926 | AD8: 45291 | AE8: 45657 | AF8: 46022 | AH8: 45838 | AI8: 46203
E9: =E6&"Q'"&RIGHT(E7,2) | F9: =F6&"Q'"&RIGHT(F7,2) | G9: =G6&"Q'"&RIGHT(G7,2) | H9: =H6&"Q'"&RIGHT(H7,2) | I9: =I6&"Q'"&RIGHT(I7,2) | J9: =J6&"Q'"&RIGHT(J7,2) | K9: =K6&"Q'"&RIGHT(K7,2) | L9: =L6&"Q'"&RIGHT(L7,2) | ... Z9: =Z6&"Q'"&RIGHT(Z7,2) | AB9: FY2021 | AC9: FY2022 | AD9: FY2023 | AE9: FY2024 | AF9: FY2025 | AH9: LTM 2Q'25 | AI9: LTM 2Q'26
D11: Sales | E11: 602 | F11: 670 | G11: 657 | H11: =AB11-SUM(E11:G11) | I11: 592 | J11: 667 | K11: 690 | L11: =AC11-SUM(I11:K11) | M11: 659 | N11: 696 | O11: 644 | P11: =AD11-SUM(M11:O11) | Q11: 523 | R11: 611 | S11: 588 | T11: =AE11-SUM(Q11:S11) | U11: 557 | V11: 665 | W11: 993 | X11: =AF11-SUM(U11:W11) | Y11: 920 | Z11: 996 | AB11: 2582 | AC11: 2800 | AD11: 2720 | AE11: 2378 | AF11: 3283 | AH11: =SUM(S11:V11) | AI11: =SUM(W11:Z11)
D12: Services, maintenance, rentals and other | E12: =1053+55 | F12: =1067+56 | G12: =1046+55 | H12: =AB12-SUM(E12:G12) | I12: =1023+53 | J12: =1028+52 | K12: =1010+51 | L12: =AC12-SUM(I12:K12) | M12: =1004+52 | N12: =1009+49 | O12: =962+46 | P12: =AD12-SUM(M12:O12) | Q12: 979 | R12: 967 | S12: 940 | T12: =AE12-SUM(Q12:S12) | U12: 900 | V12: 911 | W12: 968 | X12: =AF12-SUM(U12:W12) | Y12: 926 | Z12: 926 | AB12: =4235+221 | AC12: =4100+207 | AD12: 4166 | AE12: 3843 | AF12: 3739 | AH12: =SUM(S12:V12) | AI12: =SUM(W12:Z12)
D13: Total revenues | E13: =E11+E12 | F13: =F11+F12 | G13: =G11+G12 | H13: =H11+H12 | I13: =I11+I12 | J13: =J11+J12 | K13: =K11+K12 | L13: =L11+L12 | ... Z13: =Z11+Z12 | AB13: =AB11+AB12 | AC13: =AC11+AC12 | AD13: =AD11+AD12 | AE13: =AE11+AE12 | AF13: =AF11+AF12 | AH13: =AH11+AH12 | AI13: =AI11+AI12
D14: Total revenues (reported) | E14: 1710 | F14: 1793 | G14: 1758 | H14: 1777 | I14: 1668 | J14: 1747 | K14: 1751 | L14: 1941 | M14: 1715 | N14: 1754 | O14: 1652 | P14: 1765 | Q14: 1502 | R14: 1578 | S14: 1528 | T14: 1613 | U14: 1457 | V14: 1576 | W14: 1961 | X14: 2028 | Y14: 1846 | Z14: 1922 | AB14: 7038 | AC14: 7107 | AD14: 6886 | AE14: 6221 | AF14: 7022
D15: Check | E15: =E13-E14 | F15: =F13-F14 | G15: =G13-G14 | H15: =H13-H14 | I15: =I13-I14 | J15: =J13-J14 | K15: =K13-K14 | L15: =L13-L14 | ... Z15: =Z13-Z14 | AB15: =AB13-AB14 | AC15: =AC13-AC14 | AD15: =AD13-AD14 | AE15: =AE13-AE14 | AF15: =AF13-AF14
D17: Cost of sales | E17: 420 | F17: 468 | G17: 498 | H17: =AB17-SUM(E17:G17) | I17: 435 | J17: 487 | K17: 508 | L17: =AC17-SUM(I17:K17) | M17: 425 | N17: 452 | O17: 435 | P17: =AD17-SUM(M17:O17) | Q17: 340 | R17: 387 | S17: 390 | T17: =AE17-SUM(Q17:S17) | U17: 382 | V17: 480 | W17: 788 | X17: =AF17-SUM(U17:W17) | Y17: 600 | Z17: 579 | AB17: 1862 | AC17: 2002 | AD17: 1778 | AE17: 1562 | AF17: 2367 | AH17: =SUM(S17:V17) | AI17: =SUM(W17:Z17)
D18: Cost of services, maintenance, rentals and other | E18: =651+28 | F18: =658+28 | G18: =662+29 | H18: =AB18-SUM(E18:G18) | I18: =679+24 | J18: =677+26 | K18: =659+28 | L18: =AC18-SUM(I18:K18) | M18: =665+36 | N18: =671+34 | O18: =651+30 | P18: =AD18-SUM(M18:O18) | Q18: 719 | R18: 671 | S18: 643 | T18: =AE18-SUM(Q18:S18) | U18: 649 | V18: 645 | W18: 728 | X18: =AF18-SUM(U18:W18) | Y18: 697 | Z18: 655 | AB18: =2662+111 | AC18: =2679+108 | AD18: 2794 | AE18: 2699 | AF18: 2754 | AH18: =SUM(S18:V18) | AI18: =SUM(W18:Z18)
D19: Total cost of revenues | E19: =E17+E18 | F19: =F17+F18 | G19: =G17+G18 | H19: =H17+H18 | I19: =I17+I18 | J19: =J17+J18 | K19: =K17+K18 | L19: =L17+L18 | ... Z19: =Z17+Z18 | AB19: =AB17+AB18 | AC19: =AC17+AC18 | AD19: =AD17+AD18 | AE19: =AE17+AE18 | AF19: =AF17+AF18 | AH19: =AH17+AH18 | AI19: =AI17+AI18
D20: Gross profit | E20: =E13-E19 | F20: =F13-F19 | G20: =G13-G19 | H20: =H13-H19 | I20: =I13-I19 | J20: =J13-J19 | K20: =K13-K19 | L20: =L13-L19 | ... Z20: =Z13-Z19 | AB20: =AB13-AB19 | AC20: =AC13-AC19 | AD20: =AD13-AD19 | AE20: =AE13-AE19 | AF20: =AF13-AF19 | AH20: =AH13-AH19 | AI20: =AI13-AI19
D22: Research, development and engineering expenses | E22: 74 | F22: 79 | G22: 82 | H22: =AB22-SUM(E22:G22) | I22: 78 | J22: 84 | K22: 73 | L22: =AC22-SUM(I22:K22) | M22: 64 | N22: 57 | O22: 52 | P22: =AD22-SUM(M22:O22) | Q22: 49 | R22: 50 | S22: 45 | T22: =AE22-SUM(Q22:S22) | U22: 42 | V22: 43 | W22: 74 | X22: =AF22-SUM(U22:W22) | Y22: 64 | Z22: 67 | AB22: 310 | AC22: 304 | AD22: 229 | AE22: 191 | AF22: 230 | AH22: =SUM(S22:V22) | AI22: =SUM(W22:Z22)
D23: Selling, administrative and general expenses | E23: 448 | F23: 434 | G23: 413 | H23: =AB23-SUM(E23:G23) | I23: 455 | J23: 459 | K23: 418 | L23: =AC23-SUM(I23:K23) | M23: 407 | N23: 433 | O23: 416 | P23: =AD23-SUM(M23:O23) | Q23: 397 | R23: 393 | S23: 370 | T23: =AE23-SUM(Q23:S23) | U23: 378 | V23: 368 | W23: 477 | X23: =AF23-SUM(U23:W23) | Y23: 430 | Z23: 432 | AB23: 1718 | AC23: 1760 | AD23: 1696 | AE23: 1537 | AF23: 1654 | AH23: =SUM(S23:V23) | AI23: =SUM(W23:Z23)
D24: Goodwill impairment | E24: 0 | F24: 0 | G24: 0 | H24: =AB24-SUM(E24:G24) | I24: 0 | J24: 0 | K24: 412 | L24: =AC24-SUM(I24:K24) | M24: 0 | N24: 0 | O24: 0 | P24: =AD24-SUM(M24:O24) | Q24: 0 | R24: 0 | S24: 1058 | T24: =AE24-SUM(Q24:S24) | U24: 0 | V24: 0 | W24: 0 | X24: =AF24-SUM(U24:W24) | Y24: 0 | Z24: 0 | AB24: 781 | AC24: 412 | AD24: 0 | AE24: 1058 | AF24: 0 | AH24: =SUM(S24:V24) | AI24: =SUM(W24:Z24)
D25: Restructuring and related costs, net | E25: 17 | F25: 12 | G25: 10 | H25: =AB25-SUM(E25:G25) | I25: 18 | J25: 1 | K25: 22 | L25: =AC25-SUM(I25:K25) | M25: 2 | N25: 23 | O25: 10 | P25: =AD25-SUM(M25:O25) | Q25: 39 | R25: 12 | S25: 56 | T25: =AE25-SUM(Q25:S25) | U25: -1 | V25: 10 | W25: 59 | X25: =AF25-SUM(U25:W25) | Y25: 45 | Z25: 23 | AB25: 38 | AC25: 65 | AD25: 167 | AE25: 112 | AF25: 66 | AH25: =SUM(S25:V25) | AI25: =SUM(W25:Z25)
D26: Amortization of intangible assets | E26: 15 | F26: 14 | G26: 13 | H26: =AB26-SUM(E26:G26) | I26: 11 | J26: 10 | K26: 10 | L26: =AC26-SUM(I26:K26) | M26: 11 | N26: 10 | O26: 12 | P26: =AD26-SUM(M26:O26) | Q26: 10 | R26: 10 | S26: 10 | T26: =AE26-SUM(Q26:S26) | U26: 10 | V26: 10 | W26: 30 | X26: =AF26-SUM(U26:W26) | Y26: 30 | Z26: 30 | AB26: 55 | AC26: 42 | AD26: 43 | AE26: 73 | AF26: 83 | AH26: =SUM(S26:V26) | AI26: =SUM(W26:Z26)
D27: Divestitures | E27: 0 | F27: 0 | G27: 0 | H27: =AB27-SUM(E27:G27) | I27: 0 | J27: 0 | K27: 0 | L27: =AC27-SUM(I27:K27) | M27: 0 | N27: 0 | O27: 0 | P27: =AD27-SUM(M27:O27) | Q27: 54 | R27: -3 | S27: 0 | T27: =AE27-SUM(Q27:S27) | U27: -4 | V27: 0 | W27: 0 | X27: =AF27-SUM(U27:W27) | Y27: 0 | Z27: 0 | AB27: 0 | AC27: 0 | AD27: 0 | AE27: 47 | AF27: -4 | AH27: =SUM(S27:V27) | AI27: =SUM(W27:Z27)
D28: PARC donation | E28: 0 | F28: 0 | G28: 0 | H28: =AB28-SUM(E28:G28) | I28: 0 | J28: 0 | K28: 0 | L28: =AC28-SUM(I28:K28) | M28: 0 | N28: 132 | O28: 0 | P28: =AD28-SUM(M28:O28) | Q28: 0 | R28: 0 | S28: 0 | T28: =AE28-SUM(Q28:S28) | U28: 0 | V28: 0 | W28: 0 | X28: =AF28-SUM(U28:W28) | Y28: 0 | Z28: 0 | AB28: 0 | AC28: 0 | AD28: 132 | AE28: 0 | AF28: 0 | AH28: =SUM(S28:V28) | AI28: =SUM(W28:Z28)
D29: Total operating expenses | E29: =SUM(E22:E28) | F29: =SUM(F22:F28) | G29: =SUM(G22:G28) | H29: =SUM(H22:H28) | I29: =SUM(I22:I28) | J29: =SUM(J22:J28) | K29: =SUM(K22:K28) | L29: =SUM(L22:L28) | ... Z29: =SUM(Z22:Z28) | AB29: =SUM(AB22:AB28) | AC29: =SUM(AC22:AC28) | AD29: =SUM(AD22:AD28) | AE29: =SUM(AE22:AE28) | AF29: =SUM(AF22:AF28) | AH29: =SUM(AH22:AH28) | AI29: =SUM(AI22:AI28)
D30: Operating (loss) income | E30: =E20-E29 | F30: =F20-F29 | G30: =G20-G29 | H30: =H20-H29 | I30: =I20-I29 | J30: =J20-J29 | K30: =K20-K29 | L30: =L20-L29 | ... Z30: =Z20-Z29 | AB30: =AB20-AB29 | AC30: =AC20-AC29 | AD30: =AD20-AD29 | AE30: =AE20-AE29 | AF30: =AF20-AF29 | AH30: =AH20-AH29 | AI30: =AI20-AI29
D32: Non-financing interest expense | E32: =52-28 | F32: =52-28 | G32: =52-29 | H32: =AB32-SUM(E32:G32) | I32: =53-24 | J32: =49-26 | K32: =49-28 | L32: =AC32-SUM(I32:K32) | M32: =50-36 | N32: =46-34 | O32: =44-30 | P32: =AD32-SUM(M32:O32) | Q32: 26 | R32: 31 | S32: 31 | T32: =AE32-SUM(Q32:S32) | U32: 33 | V32: 55 | W32: 80 | X32: =AF32-SUM(U32:W32) | Y32: 84 | Z32: 100 | AB32: =207-111 | AC32: =199-108 | AD32: =198-130 | AE32: 119 | AF32: 248 | AH32: =SUM(S32:V32) | AI32: =SUM(W32:Z32)
D33: Other expenses (income), net | E33: =4-0-24 | F33: =1-1-24 | G33: =-33-1-23 | H33: =AB33-SUM(E33:G33) | I33: =57-1-29 | J33: =8-1-23 | K33: =1-1-21 | L33: =AC33-SUM(I33:K33) | M33: =20-0-14 | N33: =31-1-12 | O33: =-17-1-14 | P33: =AD33-SUM(M33:O33) | Q33: =44-26 | R33: =33-31 | S33: =43-31 | T33: =AE33-SUM(Q33:S33) | U33: 35 | V33: 25 | W33: =105-80 | X33: =AF33-SUM(U33:W33) | Y33: -31 | Z33: 5 | AB33: =-27-(207-111) | AC33: =60-(199-108) | AD33: =75-(198-130) | AE33: =158-119 | AF33: =360-248 | AH33: =SUM(S33:V33) | AI33: =SUM(W33:Z33)
D34: (Loss) income before income taxes | E34: =E30-E32-E33 | F34: =F30-F32-F33 | G34: =G30-G32-G33 | H34: =H30-H32-H33 | I34: =I30-I32-I33 | J34: =J30-J32-J33 | K34: =K30-K32-K33 | L34: =L30-L32-L33 | ... Z34: =Z30-Z32-Z33 | AB34: =AB30-AB32-AB33 | AC34: =AC30-AC32-AC33 | AD34: =AD30-AD32-AD33 | AE34: =AE30-AE32-AE33 | AF34: =AF30-AF32-AF33 | AH34: =AH30-AH32-AH33 | AI34: =AI30-AI32-AI33
D35: Income tax expense (benefit) | E35: 14 | F35: 9 | G35: -4 | H35: =AB35-SUM(E35:G35) | I35: -31 | J35: 1 | K35: 3 | L35: =AC35-SUM(I35:K35) | M35: 14 | N35: -28 | O35: 15 | P35: =AD35-SUM(M35:O35) | Q35: -37 | R35: 7 | S35: 118 | T35: =AE35-SUM(Q35:S35) | U35: 23 | V35: 46 | W35: 460 | X35: =AF35-SUM(U35:W35) | Y35: 32 | Z35: 18 | AB35: -17 | AC35: -3 | AD35: -29 | AE35: 105 | AF35: 541 | AH35: =SUM(S35:V35) | AI35: =SUM(W35:Z35)
D36: Net (loss) income | E36: =E34-E35 | F36: =F34-F35 | G36: =G34-G35 | H36: =H34-H35 | I36: =I34-I35 | J36: =J34-J35 | K36: =K34-K35 | L36: =L34-L35 | ... Z36: =Z34-Z35 | AB36: =AB34-AB35 | AC36: =AC34-AC35 | AD36: =AD34-AD35 | AE36: =AE34-AE35 | AF36: =AF34-AF35 | AH36: =AH34-AH35 | AI36: =AI34-AI35
D37: Less: net (income) loss attributable to noncontrolling interests | E37: 0 | F37: 0 | G37: 1 | H37: =AB37-SUM(E37:G37) | I37: 1 | J37: 1 | K37: -1 | L37: =AC37-SUM(I37:K37) | M37: 0 | N37: -1 | O37: 0 | P37: =AD37-SUM(M37:O37) | Q37: 0 | R37: 0 | S37: 0 | T37: =AE37-SUM(Q37:S37) | U37: 0 | V37: 0 | W37: 0 | X37: =AF37-SUM(U37:W37) | Y37: 0 | Z37: 0 | AB37: 0 | AC37: 0 | AD37: 0 | AE37: 0 | AF37: 0 | AH37: =SUM(S37:V37) | AI37: =SUM(W37:Z37)
D38: Net (loss) income attributable to Xerox Holdings | E38: =E36+E37 | F38: =F36+F37 | G38: =G36+G37 | H38: =H36+H37 | I38: =I36+I37 | J38: =J36+J37 | K38: =K36+K37 | L38: =L36+L37 | ... Z38: =Z36+Z37 | AB38: =AB36+AB37 | AC38: =AC36+AC37 | AD38: =AD36+AD37 | AE38: =AE36+AE37 | AF38: =AF36+AF37 | AH38: =AH36+AH37 | AI38: =AI36+AI37
D39: Net (loss) income attributable to Xerox Holdings (reported) | E39: 39 | F39: 91 | G39: 90 | H39: -675 | I39: -56 | J39: -4 | K39: -383 | L39: 121 | M39: 71 | N39: -61 | O39: 49 | P39: -58 | Q39: -113 | R39: 18 | S39: -1205 | T39: -21 | U39: -90 | V39: -106 | W39: -760 | X39: -73 | Y39: -105 | Z39: 13 | AB39: -455 | AC39: -322 | AD39: 1 | AE39: -1321 | AF39: -1029
D40: Check | E40: =E38-E39 | F40: =F38-F39 | G40: =G38-G39 | H40: =H38-H39 | I40: =I38-I39 | J40: =J38-J39 | K40: =K38-K39 | L40: =L38-L39 | ... Z40: =Z38-Z39 | AB40: =AB38-AB39 | AC40: =AC38-AC39 | AD40: =AD38-AD39 | AE40: =AE38-AE39 | AF40: =AF38-AF39
D41: Less: preferred stock dividends, net | E41: -4 | F41: -3 | G41: -4 | H41: =AB41-SUM(E41:G41) | I41: -4 | J41: -3 | K41: -4 | L41: =AC41-SUM(I41:K41) | M41: -4 | N41: -3 | O41: -4 | P41: =AD41-SUM(M41:O41) | Q41: -4 | R41: -3 | S41: -4 | T41: =AE41-SUM(Q41:S41) | U41: -4 | V41: -3 | W41: -4 | X41: =AF41-SUM(U41:W41) | Y41: -4 | Z41: -3 | AB41: -14 | AC41: -14 | AD41: -14 | AE41: -14 | AF41: -14 | AH41: =SUM(S41:V41) | AI41: =SUM(W41:Z41)
D42: Net (loss) income attributable to common shareholders | E42: =E38+E41 | F42: =F38+F41 | G42: =G38+G41 | H42: =H38+H41 | I42: =I38+I41 | J42: =J38+J41 | K42: =K38+K41 | L42: =L38+L41 | ... Z42: =Z38+Z41 | AB42: =AB38+AB41 | AC42: =AC38+AC41 | AD42: =AD38+AD41 | AE42: =AE38+AE41 | AF42: =AF38+AF41 | AH42: =AH38+AH41 | AI42: =AI38+AI41
D43: Diluted (loss) earnings per share | E43: 0.18 | F43: 0.46 | G43: 0.48 | H43: -3.97 | I43: -0.38 | J43: -0.05 | K43: -2.48 | L43: 0.74 | M43: 0.43 | N43: -0.41 | O43: 0.28 | P43: -0.5 | Q43: -0.94 | R43: 0.11 | S43: -9.71 | T43: -0.2 | U43: -0.75 | V43: -0.87 | W43: -6.01 | X43: -0.6 | Y43: -0.84 | Z43: 0.07 | AB43: -2.56 | AC43: -2.15 | AD43: -0.09 | AE43: -10.75 | AF43: -8.25
D45: Adjusted EBITDA reconciliation (company definition)
D46: Net (loss) income | E46: =E36 | F46: =F36 | G46: =G36 | H46: =H36 | I46: =I36 | J46: =J36 | K46: =K36 | L46: =L36 | ... Z46: =Z36 | AB46: =AB36 | AC46: =AC36 | AD46: =AD36 | AE46: =AE36 | AF46: =AF36 | AH46: =SUM(S46:V46) | AI46: =SUM(W46:Z46)
...

Sheet IS Out
A1: =D3 | B1: ='Cover Page'!A1
D3: Income Statement Summary & Adjusted EBITDA
D4: Xerox Holdings Corporation – All values in $ millions (USD), except per-share values. Data as of June 30, 2026 (2Q'26).
A8: x | D8: Income Statement Summary | E8: Year Ended December 31, | J8: LTM
E9: 2021 | F9: 2022 | G9: 2023 | H9: 2024 | I9: 2025 | J9: LTM 2Q'25 | K9: LTM 2Q'26
D11: Sales | E11: =IS!AB11 | F11: =IS!AC11 | G11: =IS!AD11 | H11: =IS!AE11 | I11: =IS!AF11 | J11: =IS!AH11 | K11: =IS!AI11
D12: Services, maintenance, rentals and other | E12: =IS!AB12 | F12: =IS!AC12 | G12: =IS!AD12 | H12: =IS!AE12 | I12: =IS!AF12 | J12: =IS!AH12 | K12: =IS!AI12
D13: Total revenues | E13: =E11+E12 | F13: =F11+F12 | G13: =G11+G12 | H13: =H11+H12 | I13: =I11+I12 | J13: =J11+J12 | K13: =K11+K12
D14: Cost of revenues | E14: =-IS!AB19 | F14: =-IS!AC19 | G14: =-IS!AD19 | H14: =-IS!AE19 | I14: =-IS!AF19 | J14: =-IS!AH19 | K14: =-IS!AI19
D15: Gross profit | E15: =E13+E14 | F15: =F13+F14 | G15: =G13+G14 | H15: =H13+H14 | I15: =I13+I14 | J15: =J13+J14 | K15: =K13+K14
D16: Research, development and engineering | E16: =-IS!AB22 | F16: =-IS!AC22 | G16: =-IS!AD22 | H16: =-IS!AE22 | I16: =-IS!AF22 | J16: =-IS!AH22 | K16: =-IS!AI22
D17: Selling, administrative and general | E17: =-IS!AB23 | F17: =-IS!AC23 | G17: =-IS!AD23 | H17: =-IS!AE23 | I17: =-IS!AF23 | J17: =-IS!AH23 | K17: =-IS!AI23
D18: Restructuring and related costs, net | E18: =-IS!AB25 | F18: =-IS!AC25 | G18: =-IS!AD25 | H18: =-IS!AE25 | I18: =-IS!AF25 | J18: =-IS!AH25 | K18: =-IS!AI25
D19: Amortization of intangible assets | E19: =-IS!AB26 | F19: =-IS!AC26 | G19: =-IS!AD26 | H19: =-IS!AE26 | I19: =-IS!AF26 | J19: =-IS!AH26 | K19: =-IS!AI26
D20: Divestitures | E20: =-IS!AB27 | F20: =-IS!AC27 | G20: =-IS!AD27 | H20: =-IS!AE27 | I20: =-IS!AF27 | J20: =-IS!AH27 | K20: =-IS!AI27
D21: PARC donation | E21: =-IS!AB28 | F21: =-IS!AC28 | G21: =-IS!AD28 | H21: =-IS!AE28 | I21: =-IS!AF28 | J21: =-IS!AH28 | K21: =-IS!AI28
D22: Depreciation and amortization (add-back) | E22: =IS!AB50 | F22: =IS!AC50 | G22: =IS!AD50 | H22: =IS!AE50 | I22: =IS!AF50 | J22: =IS!AH50 | K22: =IS!AI50
D23: EBITDA | E23: =E15+SUM(E16:E22) | F23: =F15+SUM(F16:F22) | G23: =G15+SUM(G16:G22) | H23: =H15+SUM(H16:H22) | I23: =I15+SUM(I16:I22) | J23: =J15+SUM(J16:J22) | K23: =K15+SUM(K16:K22)
D25: Stock-based compensation | E25: =IS!AB54 | F25: =IS!AC54 | G25: =IS!AD54 | H25: =IS!AE54 | I25: =IS!AF54 | J25: =IS!AH54 | K25: =IS!AI54
D26: Restructuring and related costs, net | E26: =IS!AB25 | F26: =IS!AC25 | G26: =IS!AD25 | H26: =IS!AE25 | I26: =IS!AF25 | J26: =IS!AH25 | K26: =IS!AI25
D27: PARC donation | E27: =IS!AB28 | F27: =IS!AC28 | G27: =IS!AD28 | H27: =IS!AE28 | I27: =IS!AF28 | J27: =IS!AH28 | K27: =IS!AI28
D28: Divestitures | E28: =IS!AB27 | F28: =IS!AC27 | G28: =IS!AD27 | H28: =IS!AE27 | I28: =IS!AF27 | J28: =IS!AH27 | K28: =IS!AI27
D29: Transformation-related costs | E29: =IS!AB58 | F29: =IS!AC58 | G29: =IS!AD58 | H29: =IS!AE58 | I29: =IS!AF58 | J29: =IS!AH58 | K29: =IS!AI58
D30: Transaction and related costs, net | E30: =IS!AB59 | F30: =IS!AC59 | G30: =IS!AD59 | H30: =IS!AE59 | I30: =IS!AF59 | J30: =IS!AH59 | K30: =IS!AI59
D31: Inventory impact, exit of Production Print manufacturing | E31: =IS!AB60 | F31: =IS!AC60 | G31: =IS!AD60 | H31: =IS!AE60 | I31: =IS!AF60 | J31: =IS!AH60 | K31: =IS!AI60
D32: Lexmark inventory purchase accounting adjustment | E32: =IS!AB61 | F32: =IS!AC61 | G32: =IS!AD61 | H32: =IS!AE61 | I32: =IS!AF61 | J32: =IS!AH61 | K32: =IS!AI61
D33: Lexmark settlement of pre-existing employment agreements | E33: =IS!AB62 | F33: =IS!AC62 | G33: =IS!AD62 | H33: =IS!AE62 | I33: =IS!AF62 | J33: =IS!AH62 | K33: =IS!AI62
D34: Adjusted EBITDA | E34: =E23+SUM(E25:E33) | F34: =F23+SUM(F25:F33) | G34: =G23+SUM(G25:G33) | H34: =H23+SUM(H25:H33) | I34: =I23+SUM(I25:I33) | J34: =J23+SUM(J25:J33) | K34: =K23+SUM(K25:K33)
D35: IS Adjusted EBITDA | E35: =IS!AB63 | F35: =IS!AC63 | G35: =IS!AD63 | H35: =IS!AE63 | I35: =IS!AF63 | J35: =IS!AH63 | K35: =IS!AI63
D36: Check | E36: =E34-E35 | F36: =F34-F35 | G36: =G34-G35 | H36: =H34-H35 | I36: =I34-I35 | J36: =J34-J35 | K36: =K34-K35
D38: Less: IEEPA tariff refund benefit | E38: =IS!AB67 | F38: =IS!AC67 | G38: =IS!AD67 | H38: =IS!AE67 | I38: =IS!AF67 | J38: =IS!AH67 | K38: =IS!AI67
D39: Adjusted EBITDA excl. IEEPA tariff benefit | E39: =E34+E38 | F39: =F34+F38 | G39: =G34+G38 | H39: =H34+H38 | I39: =I34+I38 | J39: =J34+J38 | K39: =K34+K38
D41: Memo:
D42: Total revenue growth (YoY) | F42: =F13/E13-1 | G42: =G13/F13-1 | H42: =H13/G13-1 | I42: =I13/H13-1 | J42: =IS!AH71 | K42: =IS!AI71
D43: Gross margin % | E43: =E15/E13 | F43: =F15/F13 | G43: =G15/G13 | H43: =H15/H13 | I43: =I15/I13 | J43: =J15/J13 | K43: =K15/K13
D44: EBITDA margin % | E44: =E23/E13 | F44: =F23/F13 | G44: =G23/G13 | H44: =H23/H13 | I44: =I23/I13 | J44: =J23/J13 | K44: =K23/K13
D45: Adjusted EBITDA margin % | E45: =E34/E13 | F45: =F34/F13 | G45: =G34/G13 | H45: =H34/H13 | I45: =I34/I13 | J45: =J34/J13 | K45: =K34/K13
D46: Adjusted EBITDA excl. IEEPA margin % | E46: =E39/E13 | F46: =F39/F13 | G46: =G39/G13 | H46: =H39/H13 | I46: =I39/I13 | J46: =J39/J13 | K46: =K39/K13
D48: Notes:
D49: (1) Shown in Xerox's current presentation (see IS tab notes).
...

Sheet CFS
A1: =D3 | B1: ='Cover Page'!A1
D3: Statement of Cash Flows Spread
D4: Xerox Holdings Corporation – All values in $ millions (USD), except per-share values. Data as of June 30, 2026 (2Q'26).
A6: x | D6: Cash Flow Statement | F6: Quarter Ended | AC6: Fiscal Year Ended December 31, | AI6: LTM
F7: 1 | G7: 2 | H7: 3 | I7: 4 | J7: 1 | K7: 2 | L7: 3 | M7: 4 | N7: 1 | O7: 2 | P7: 3 | Q7: 4 | R7: 1 | S7: 2 | T7: 3 | U7: 4 | V7: 1 | W7: 2 | X7: 3 | Y7: 4 | Z7: 1 | AA7: 2
F8: 2021 | G8: 2021 | H8: 2021 | I8: 2021 | J8: 2022 | K8: 2022 | L8: 2022 | M8: 2022 | N8: 2023 | O8: 2023 | P8: 2023 | Q8: 2023 | R8: 2024 | S8: 2024 | T8: 2024 | U8: 2024 | V8: 2025 | W8: 2025 | X8: 2025 | Y8: 2025 | Z8: 2026 | AA8: 2026 | AC8: 2021 | AD8: 2022 | AE8: 2023 | AF8: 2024 | AG8: 2025
F9: 44286 | G9: 44377 | H9: 44469 | I9: 44561 | J9: 44651 | K9: 44742 | L9: 44834 | M9: 44926 | N9: 45016 | O9: 45107 | P9: 45199 | Q9: 45291 | R9: 45382 | S9: 45473 | T9: 45565 | U9: 45657 | V9: 45747 | W9: 45838 | X9: 45930 | Y9: 46022 | Z9: 46112 | AA9: 46203 | AC9: 44561 | AD9: 44926 | AE9: 45291 | AF9: 45657 | AG9: 46022
F11: =F7&"Q'"&RIGHT(F8,2) | G11: =G7&"Q'"&RIGHT(G8,2) | H11: =H7&"Q'"&RIGHT(H8,2) | I11: =I7&"Q'"&RIGHT(I8,2) | J11: =J7&"Q'"&RIGHT(J8,2) | K11: =K7&"Q'"&RIGHT(K8,2) | L11: =L7&"Q'"&RIGHT(L8,2) | M11: =M7&"Q'"&RIGHT(M8,2) | ... AA11: =AA7&"Q'"&RIGHT(AA8,2) | AC11: 2021 | AD11: 2022 | AE11: 2023 | AF11: 2024 | AG11: 2025 | AI11: LTM 2Q'25 | AJ11: LTM 2Q'26
D13: OPERATING ACTIVITIES
D14: Net (loss) income | F14: =IS!E36 | G14: =IS!F36 | H14: =IS!G36 | I14: =IS!H36 | J14: =IS!I36 | K14: =IS!J36 | L14: =IS!K36 | M14: =IS!L36 | ... AA14: =IS!Z36 | AC14: =IS!AB36 | AD14: =IS!AC36 | AE14: =IS!AD36 | AF14: =IS!AE36 | AG14: =IS!AF36 | AI14: =SUM(T14:W14) | AJ14: =SUM(X14:AA14)
D15: Adjustments required to reconcile net (loss) income to cash flows from operating activities:
D16: Depreciation and amortization | F16: 86 | G16: =170-F16 | H16: =249-SUM(F16:G16) | I16: =AC16-SUM(F16:H16) | J16: 72 | K16: =140-J16 | L16: =205-SUM(J16:K16) | M16: =AD16-SUM(J16:L16) | N16: 64 | O16: =126-N16 | P16: =189-SUM(N16:O16) | Q16: =AE16-SUM(N16:P16) | R16: 59 | S16: =118-R16 | T16: =177-SUM(R16:S16) | U16: =AF16-SUM(R16:T16) | V16: 60 | W16: =117-V16 | X16: =224-SUM(V16:W16) | Y16: =AG16-SUM(V16:X16) | Z16: 100 | AA16: =201-Z16 | AC16: 327 | AD16: 270 | AE16: 251 | AF16: 274 | AG16: 331 | AI16: =SUM(T16:W16) | AJ16: =SUM(X16:AA16)
D17: Provisions | F17: 20 | G17: =34-F17 | H17: =38-SUM(F17:G17) | I17: =AC17-SUM(F17:H17) | J17: 19 | K17: =35-J17 | L17: =48-SUM(J17:K17) | M17: =AD17-SUM(J17:L17) | N17: 0 | O17: =21-N17 | P17: =37-SUM(N17:O17) | Q17: =AE17-SUM(N17:P17) | R17: 57 | S17: =79-R17 | T17: =92-SUM(R17:S17) | U17: =AF17-SUM(R17:T17) | V17: 18 | W17: =48-V17 | X17: =67-SUM(V17:W17) | Y17: =AG17-SUM(V17:X17) | Z17: 18 | AA17: =36-Z17 | AC17: 46 | AD17: 65 | AE17: 54 | AF17: 110 | AG17: 85 | AI17: =SUM(T17:W17) | AJ17: =SUM(X17:AA17)
D18: Net (gain) loss on early extinguishment of debt | Z18: -56 | AA18: =-95-Z18 | AI18: =SUM(T18:W18) | AJ18: =SUM(X18:AA18)
D19: Net (gain) loss on sales of businesses and assets | F19: 0 | G19: =-1-F19 | H19: =-40-SUM(F19:G19) | I19: =AC19-SUM(F19:H19) | J19: 0 | K19: =-1-J19 | L19: =-17-SUM(J19:K19) | M19: =AD19-SUM(J19:L19) | N19: 0 | O19: =-2-N19 | P19: =-37-SUM(N19:O19) | Q19: =AE19-SUM(N19:P19) | R19: 0 | S19: =-1-R19 | T19: =-3-SUM(R19:S19) | U19: =AF19-SUM(R19:T19) | V19: -3 | W19: =-5-V19 | X19: =-6-SUM(V19:W19) | Y19: =AG19-SUM(V19:X19) | Z19: 2 | AA19: =2-Z19 | AC19: -40 | AD19: -56 | AE19: -39 | AF19: -8 | AG19: -5 | AI19: =SUM(T19:W19) | AJ19: =SUM(X19:AA19)
D20: Inventory-related purchase accounting adjustment, noncash (Lexmark) | V20: 0 | W20: =0-V20 | X20: =102-SUM(V20:W20) | Y20: =AG20-SUM(V20:X20) | AG20: 102 | AI20: =SUM(T20:W20) | AJ20: =SUM(X20:AA20)
D21: Effective settlement of pre-existing relationship between Lexmark and Xerox | V21: 0 | W21: =0-V21 | X21: =-43-SUM(V21:W21) | Y21: =AG21-SUM(V21:X21) | AG21: -43 | AI21: =SUM(T21:W21) | AJ21: =SUM(X21:AA21)
D22: Divestitures | F22: =IS!E27 | G22: =IS!F27 | H22: =IS!G27 | I22: =IS!H27 | J22: =IS!I27 | K22: =IS!J27 | L22: =IS!K27 | M22: =IS!L27 | ... AA22: =IS!Z27 | AC22: =IS!AB27 | AD22: =IS!AC27 | AE22: =IS!AD27 | AF22: =IS!AE27 | AG22: =IS!AF27 | AI22: =SUM(T22:W22) | AJ22: =SUM(X22:AA22)
D23: PARC donation | F23: =IS!E28 | G23: =IS!F28 | H23: =IS!G28 | I23: =IS!H28 | J23: =IS!I28 | K23: =IS!J28 | L23: =IS!K28 | M23: =IS!L28 | ... AA23: =IS!Z28 | AC23: =IS!AB28 | AD23: =IS!AC28 | AE23: =IS!AD28 | AF23: =IS!AE28 | AG23: =IS!AF28 | AI23: =SUM(T23:W23) | AJ23: =SUM(X23:AA23)
D24: Goodwill impairment | F24: =IS!E24 | G24: =IS!F24 | H24: =IS!G24 | I24: =IS!H24 | J24: =IS!I24 | K24: =IS!J24 | L24: =IS!K24 | M24: =IS!L24 | ... AA24: =IS!Z24 | AC24: =IS!AB24 | AD24: =IS!AC24 | AE24: =IS!AD24 | AF24: =IS!AE24 | AG24: =IS!AF24 | AI24: =SUM(T24:W24) | AJ24: =SUM(X24:AA24)
D25: Stock-based compensation | F25: 16 | G25: =30-F25 | H25: =44-SUM(F25:G25) | I25: =AC25-SUM(F25:H25) | J25: 15 | K25: =50-J25 | L25: =63-SUM(J25:K25) | M25: =AD25-SUM(J25:L25) | N25: 14 | O25: =28-N25 | P25: =40-SUM(N25:O25) | Q25: =AE25-SUM(N25:P25) | R25: 12 | S25: =29-R25 | T25: =38-SUM(R25:S25) | U25: =AF25-SUM(R25:T25) | V25: 12 | W25: =26-V25 | X25: =33-SUM(V25:W25) | Y25: =AG25-SUM(V25:X25) | Z25: 9 | AA25: =18-Z25 | AC25: 54 | AD25: 75 | AE25: 54 | AF25: 52 | AG25: 45 | AI25: =SUM(T25:W25) | AJ25: =SUM(X25:AA25)
D26: Restructuring and asset impairment charges | F26: 21 | G26: =25-F26 | H26: =28-SUM(F26:G26) | I26: =AC26-SUM(F26:H26) | J26: 20 | K26: =22-J26 | L26: =44-SUM(J26:K26) | M26: =AD26-SUM(J26:L26) | N26: 1 | O26: =14-N26 | P26: =25-SUM(N26:O26) | Q26: =AE26-SUM(N26:P26) | R26: 31 | S26: =34-R26 | T26: =80-SUM(R26:S26) | U26: =AF26-SUM(R26:T26) | V26: -1 | W26: =10-V26 | X26: =69-SUM(V26:W26) | Y26: =AG26-SUM(V26:X26) | Z26: 44 | AA26: =65-Z26 | AC26: 27 | AD26: 62 | AE26: 146 | AF26: 87 | AG26: 67 | AI26: =SUM(T26:W26) | AJ26: =SUM(X26:AA26)
D27: Payments for restructurings | F27: -27 | G27: =-49-F27 | H27: =-61-SUM(F27:G27) | I27: =AC27-SUM(F27:H27) | J27: -7 | K27: =-21-J27 | L27: =-38-SUM(J27:K27) | M27: =AD27-SUM(J27:L27) | N27: -6 | O27: =-14-N27 | P27: =-23-SUM(N27:O27) | Q27: =AE27-SUM(N27:P27) | R27: -16 | S27: =-47-R27 | T27: =-58-SUM(R27:S27) | U27: =AF27-SUM(R27:T27) | V27: -18 | W27: =-33-V27 | X27: =-41-SUM(V27:W27) | Y27: =AG27-SUM(V27:X27) | Z27: -21 | AA27: =-40-Z27 | AC27: -72 | AD27: -52 | AE27: -27 | AF27: -78 | AG27: -69 | AI27: =SUM(T27:W27) | AJ27: =SUM(X27:AA27)
D28: Non-service retirement-related costs | F28: 0 | G28: =-2-F28 | H28: =-5-SUM(F28:G28) | I28: =AC28-SUM(F28:H28) | J28: -7 | K28: =-11-J28 | L28: =-18-SUM(J28:K28) | M28: =AD28-SUM(J28:L28) | N28: -1 | O28: =10-N28 | P28: =14-SUM(N28:O28) | Q28: =AE28-SUM(N28:P28) | R28: 23 | S28: =49-R28 | T28: =74-SUM(R28:S28) | U28: =AF28-SUM(R28:T28) | V28: 18 | W28: =37-V28 | X28: =57-SUM(V28:W28) | Y28: =AG28-SUM(V28:X28) | Z28: 21 | AA28: =42-Z28 | AC28: -10 | AD28: -12 | AE28: 19 | AF28: 80 | AG28: 78 | AI28: =SUM(T28:W28) | AJ28: =SUM(X28:AA28)
D29: Contributions to retirement plans | F29: -35 | G29: =-69-F29 | H29: =-102-SUM(F29:G29) | I29: =AC29-SUM(F29:H29) | J29: -38 | K29: =-72-J29 | L29: =-106-SUM(J29:K29) | M29: =AD29-SUM(J29:L29) | N29: -17 | O29: =-32-N29 | P29: =-75-SUM(N29:O29) | Q29: =AE29-SUM(N29:P29) | R29: -31 | S29: =-58-R29 | T29: =-114-SUM(R29:S29) | U29: =AF29-SUM(R29:T29) | V29: -34 | W29: =-67-V29 | X29: =-123-SUM(V29:W29) | Y29: =AG29-SUM(V29:X29) | Z29: -36 | AA29: =-72-Z29 | AC29: -135 | AD29: -124 | AE29: -102 | AF29: -145 | AG29: -161 | AI29: =SUM(T29:W29) | AJ29: =SUM(X29:AA29)
D30: Changes in operating assets and liabilities:
D31: (Increase) decrease in accounts receivable and billed portion of finance receivables | F31: 92 | G31: =37-F31 | H31: =-30-SUM(F31:G31) | I31: =AC31-SUM(F31:H31) | J31: 13 | K31: =-49-J31 | L31: =-48-SUM(J31:K31) | M31: =AD31-SUM(J31:L31) | N31: 39 | O31: =-36-N31 | P31: =-47-SUM(N31:O31) | Q31: =AE31-SUM(N31:P31) | R31: -19 | S31: =-32-R31 | T31: =18-SUM(R31:S31) | U31: =AF31-SUM(R31:T31) | V31: -12 | W31: =-44-V31 | X31: =-41-SUM(V31:W31) | Y31: =AG31-SUM(V31:X31) | Z31: -106 | AA31: =-86-Z31 | AC31: 41 | AD31: -48 | AE31: -5 | AF31: 71 | AG31: -36 | AI31: =SUM(T31:W31) | AJ31: =SUM(X31:AA31)
D32: (Increase) decrease in inventories | F32: -18 | G32: =4-F32 | H32: =10-SUM(F32:G32) | I32: =AC32-SUM(F32:H32) | J32: -31 | K32: =-95-J32 | L32: =-136-SUM(J32:K32) | M32: =AD32-SUM(J32:L32) | N32: -64 | O32: =12-N32 | P32: =50-SUM(N32:O32) | Q32: =AE32-SUM(N32:P32) | R32: -133 | S32: =-148-R32 | T32: =-136-SUM(R32:S32) | U32: =AF32-SUM(R32:T32) | V32: -137 | W32: =-160-V32 | X32: =-123-SUM(V32:W32) | Y32: =AG32-SUM(V32:X32) | Z32: -49 | AA32: =-60-Z32 | AC32: 88 | AD32: -143 | AE32: 123 | AF32: -122 | AG32: -12 | AI32: =SUM(T32:W32) | AJ32: =SUM(X32:AA32)
D33: Increase in equipment on operating leases | F33: -28 | G33: =-63-F33 | H33: =-92-SUM(F33:G33) | I33: =AC33-SUM(F33:H33) | J33: -36 | K33: =-47-J33 | L33: =-74-SUM(J33:K33) | M33: =AD33-SUM(J33:L33) | N33: -40 | O33: =-77-N33 | P33: =-109-SUM(N33:O33) | Q33: =AE33-SUM(N33:P33) | R33: -22 | S33: =-50-R33 | T33: =-78-SUM(R33:S33) | U33: =AF33-SUM(R33:T33) | V33: -30 | W33: =-52-V33 | X33: =-88-SUM(V33:W33) | Y33: =AG33-SUM(V33:X33) | Z33: -32 | AA33: =-67-Z33 | AC33: -129 | AD33: -112 | AE33: -141 | AF33: -107 | AG33: -126 | AI33: =SUM(T33:W33) | AJ33: =SUM(X33:AA33)
D34: Decrease (increase) in finance receivables | F34: 37 | G34: =12-F34 | H34: =33-SUM(F34:G34) | I34: =AC34-SUM(F34:H34) | J34: 41 | K34: =17-J34 | L34: =-10-SUM(J34:K34) | M34: =AD34-SUM(J34:L34) | N34: 160 | O34: =407-N34 | P34: =490-SUM(N34:O34) | Q34: =AE34-SUM(N34:P34) | R34: 210 | S34: =399-R34 | T34: =496-SUM(R34:S34) | U34: =AF34-SUM(R34:T34) | V34: 128 | W34: =212-V34 | X34: =338-SUM(V34:W34) | Y34: =AG34-SUM(V34:X34) | Z34: 66 | AA34: =157-Z34 | AC34: 20 | AD34: -141 | AE34: 614 | AF34: 663 | AG34: 489 | AI34: =SUM(T34:W34) | AJ34: =SUM(X34:AA34)
D35: (Increase) decrease in other current and long-term assets | F35: 18 | G35: =66-F35 | H35: =64-SUM(F35:G35) | I35: =AC35-SUM(F35:H35) | J35: -1 | K35: =35-J35 | L35: =36-SUM(J35:K35) | M35: =AD35-SUM(J35:L35) | N35: 3 | O35: =15-N35 | P35: =-8-SUM(N35:O35) | Q35: =AE35-SUM(N35:P35) | R35: -2 | S35: =14-R35 | T35: =16-SUM(R35:S35) | U35: =AF35-SUM(R35:T35) | V35: -16 | W35: =16-V35 | X35: =4-SUM(V35:W35) | Y35: =AG35-SUM(V35:X35) | Z35: -38 | AA35: =-120-Z35 | AC35: 68 | AD35: 27 | AE35: 16 | AF35: -14 | AG35: 9 | AI35: =SUM(T35:W35) | AJ35: =SUM(X35:AA35)
D36: Increase (decrease) in accounts payable | F36: -31 | G36: =-33-F36 | H36: =74-SUM(F36:G36) | I36: =AC36-SUM(F36:H36) | J36: 111 | K36: =172-J36 | L36: =198-SUM(J36:K36) | M36: =AD36-SUM(J36:L36) | N36: -41 | O36: =-290-N36 | P36: =-290-SUM(N36:O36) | Q36: =AE36-SUM(N36:P36) | R36: 17 | S36: =-88-R36 | T36: =-143-SUM(R36:S36) | U36: =AF36-SUM(R36:T36) | V36: 89 | W36: =25-V36 | X36: =4-SUM(V36:W36) | Y36: =AG36-SUM(V36:X36) | Z36: 58 | AA36: =-30-Z36 | AC36: 118 | AD36: 278 | AE36: -290 | AF36: -48 | AG36: 24 | AI36: =SUM(T36:W36) | AJ36: =SUM(X36:AA36)
D37: Increase (decrease) in accrued compensation | F37: -36 | G37: =-35-F37 | H37: =-56-SUM(F37:G37) | I37: =AC37-SUM(F37:H37) | J37: 22 | K37: =7-J37 | L37: =29-SUM(J37:K37) | M37: =AD37-SUM(J37:L37) | N37: -16 | O37: =-7-N37 | P37: =16-SUM(N37:O37) | Q37: =AE37-SUM(N37:P37) | R37: -86 | S37: =-93-R37 | T37: =-78-SUM(R37:S37) | U37: =AF37-SUM(R37:T37) | V37: -30 | W37: =-51-V37 | X37: =-39-SUM(V37:W37) | Y37: =AG37-SUM(V37:X37) | Z37: -8 | AA37: =18-Z37 | AC37: -95 | AD37: 34 | AE37: 48 | AF37: -78 | AG37: -53 | AI37: =SUM(T37:W37) | AJ37: =SUM(X37:AA37)
D38: Increase (decrease) in other current and long-term liabilities | F38: -35 | G38: =92-F38 | H38: =80-SUM(F38:G38) | I38: =AC38-SUM(F38:H38) | J38: -43 | K38: =-48-J38 | L38: =-73-SUM(J38:K38) | M38: =AD38-SUM(J38:L38) | N38: -128 | O38: =-139-N38 | P38: =-159-SUM(N38:O38) | Q38: =AE38-SUM(N38:P38) | R38: -77 | S38: =-52-R38 | T38: =-83-SUM(R38:S38) | U38: =AF38-SUM(R38:T38) | V38: -48 | W38: =-40-V38 | X38: =58-SUM(V38:W38) | Y38: =AG38-SUM(V38:X38) | Z38: -9 | AA38: =6-Z38 | AC38: 89 | AD38: 9 | AE38: -114 | AF38: -47 | AG38: 33 | AI38: =SUM(T38:W38) | AJ38: =SUM(X38:AA38)
D39: Net change in income tax assets and liabilities (incl. deferred taxes) | F39: 6 | G39: =2-F39 | H39: =-11-SUM(F39:G39) | I39: =AC39-SUM(F39:H39) | J39: -39 | K39: =-76-J39 | L39: =-81-SUM(J39:K39) | M39: =AD39-SUM(J39:L39) | N39: 18 | O39: =-17-N39 | P39: =-24-SUM(N39:O39) | Q39: =AE39-SUM(N39:P39) | R39: -44 | S39: =-64-R39 | T39: =44-SUM(R39:S39) | U39: =AF39-SUM(R39:T39) | V39: -2 | W39: =35-V39 | X39: =479-SUM(V39:W39) | Y39: =AG39-SUM(V39:X39) | Z39: 12 | AA39: =6-Z39 | AC39: =10-89 | AD39: =-27-27 | AE39: =-12-68 | AF39: =-50+90 | AG39: =-26+502 | AI39: =SUM(T39:W39) | AJ39: =SUM(X39:AA39)
D40: Net change in derivative assets and liabilities | F40: 3 | G40: =-2-F40 | H40: =-1-SUM(F40:G40) | I40: =AC40-SUM(F40:H40) | J40: 7 | K40: =-6-J40 | L40: =-10-SUM(J40:K40) | M40: =AD40-SUM(J40:L40) | N40: 13 | O40: =22-N40 | P40: =16-SUM(N40:O40) | Q40: =AE40-SUM(N40:P40) | R40: 6 | S40: =6-R40 | T40: =9-SUM(R40:S40) | U40: =AF40-SUM(R40:T40) | V40: 0 | W40: =-2-V40 | X40: =-1-SUM(V40:W40) | Y40: =AG40-SUM(V40:X40) | AC40: 2 | AD40: -22 | AE40: 13 | AF40: 10 | AG40: -12 | AI40: =SUM(T40:W40) | AJ40: =SUM(X40:AA40)
D41: Other operating, net | F41: -11 | G41: =-17-F41 | H41: =-10-SUM(F41:G41) | I41: =AC41-SUM(F41:H41) | J41: 5 | K41: =-9-J41 | L41: =-7-SUM(J41:K41) | M41: =AD41-SUM(J41:L41) | N41: 8 | O41: =-11-N41 | P41: =0-SUM(N41:O41) | Q41: =AE41-SUM(N41:P41) | R41: -5 | S41: =-7-R41 | T41: =0-SUM(R41:S41) | U41: =AF41-SUM(R41:T41) | V41: 11 | W41: =28-V41 | X41: =46-SUM(V41:W41) | Y41: =AG41-SUM(V41:X41) | Z41: -14 | AA41: =4-Z41 | AC41: -17 | AD41: 13 | AE41: 13 | AF41: -13 | AG41: 35 | AI41: =SUM(T41:W41) | AJ41: =SUM(X41:AA41)
D42: Net cash provided by (used in) operating activities | F42: =SUM(F14:F41) | G42: =SUM(G14:G41) | H42: =SUM(H14:H41) | I42: =SUM(I14:I41) | J42: =SUM(J14:J41) | K42: =SUM(K14:K41) | L42: =SUM(L14:L41) | M42: =SUM(M14:M41) | ... AA42: =SUM(AA14:AA41) | AC42: =SUM(AC14:AC41) | AD42: =SUM(AD14:AD41) | AE42: =SUM(AE14:AE41) | AF42: =SUM(AF14:AF41) | AG42: =SUM(AG14:AG41) | AI42: =SUM(AI14:AI41) | AJ42: =SUM(AJ14:AJ41)
D43: Net cash provided by (used in) operating activities | F43: 117 | G43: =331-117 | H43: =431-331 | I43: =629-431 | J43: 66 | K43: =-19-66 | L43: =-27-(-19) | M43: =159-(-27) | N43: 78 | O43: =173-78 | P43: =297-173 | Q43: =686-297 | R43: -79 | S43: =44-(-79) | T43: =160-44 | U43: =511-160 | V43: -89 | W43: =-100-(-89) | X43: =16-(-100) | Y43: =224-16 | Z43: -144 | AA43: =-107-(-144) | AC43: 629 | AD43: 159 | AE43: 686 | AF43: 511 | AG43: 224 | AI43: =SUM(T43:W43) | AJ43: =SUM(X43:AA43)
D44: Check | F44: =F42-F43 | G44: =G42-G43 | H44: =H42-H43 | I44: =I42-I43 | J44: =J42-J43 | K44: =K42-K43 | L44: =L42-L43 | M44: =M42-M43 | ... AA44: =AA42-AA43 | AC44: =AC42-AC43 | AD44: =AD42-AD43 | AE44: =AE42-AE43 | AF44: =AF42-AF43 | AG44: =AG42-AG43
...

Sheet CFS Out
A1: =D3 | B1: ='Cover Page'!A1
D3: Cash Flow Statement Summary
D4: Xerox Holdings Corporation – All values in $ millions (USD), except per-share values. Data as of June 30, 2026 (2Q'26).
A8: x | D8: Cash Flow Statement Summary | E8: Year Ended December 31, | K8: Quarter Ended
E10: 2021 | F10: 2022 | G10: 2023 | H10: 2024 | I10: 2025 | J10: LTM 2Q'26 | K10: 2Q'25 | L10: 2Q'26
D12: Net (loss) income | E12: =SUMIFS(CFS!$F$14:$AJ$14,CFS!$F$11:$AJ$11,E$10) | F12: =SUMIFS(CFS!$F$14:$AJ$14,CFS!$F$11:$AJ$11,F$10) | G12: =SUMIFS(CFS!$F$14:$AJ$14,CFS!$F$11:$AJ$11,G$10) | H12: =SUMIFS(CFS!$F$14:$AJ$14,CFS!$F$11:$AJ$11,H$10) | I12: =SUMIFS(CFS!$F$14:$AJ$14,CFS!$F$11:$AJ$11,I$10) | J12: =SUMIFS(CFS!$F$14:$AJ$14,CFS!$F$11:$AJ$11,J$10) | K12: =SUMIFS(CFS!$F$14:$AJ$14,CFS!$F$11:$AJ$11,K$10) | L12: =SUMIFS(CFS!$F$14:$AJ$14,CFS!$F$11:$AJ$11,L$10)
D13: Depreciation and amortization | E13: =SUMIFS(CFS!$F$16:$AJ$16,CFS!$F$11:$AJ$11,E$10) | F13: =SUMIFS(CFS!$F$16:$AJ$16,CFS!$F$11:$AJ$11,F$10) | G13: =SUMIFS(CFS!$F$16:$AJ$16,CFS!$F$11:$AJ$11,G$10) | H13: =SUMIFS(CFS!$F$16:$AJ$16,CFS!$F$11:$AJ$11,H$10) | I13: =SUMIFS(CFS!$F$16:$AJ$16,CFS!$F$11:$AJ$11,I$10) | J13: =SUMIFS(CFS!$F$16:$AJ$16,CFS!$F$11:$AJ$11,J$10) | K13: =SUMIFS(CFS!$F$16:$AJ$16,CFS!$F$11:$AJ$11,K$10) | L13: =SUMIFS(CFS!$F$16:$AJ$16,CFS!$F$11:$AJ$11,L$10)
D14: Goodwill impairment | E14: =SUMIFS(CFS!$F$24:$AJ$24,CFS!$F$11:$AJ$11,E$10) | F14: =SUMIFS(CFS!$F$24:$AJ$24,CFS!$F$11:$AJ$11,F$10) | G14: =SUMIFS(CFS!$F$24:$AJ$24,CFS!$F$11:$AJ$11,G$10) | H14: =SUMIFS(CFS!$F$24:$AJ$24,CFS!$F$11:$AJ$11,H$10) | I14: =SUMIFS(CFS!$F$24:$AJ$24,CFS!$F$11:$AJ$11,I$10) | J14: =SUMIFS(CFS!$F$24:$AJ$24,CFS!$F$11:$AJ$11,J$10) | K14: =SUMIFS(CFS!$F$24:$AJ$24,CFS!$F$11:$AJ$11,K$10) | L14: =SUMIFS(CFS!$F$24:$AJ$24,CFS!$F$11:$AJ$11,L$10)
D15: Stock-based compensation | E15: =SUMIFS(CFS!$F$25:$AJ$25,CFS!$F$11:$AJ$11,E$10) | F15: =SUMIFS(CFS!$F$25:$AJ$25,CFS!$F$11:$AJ$11,F$10) | G15: =SUMIFS(CFS!$F$25:$AJ$25,CFS!$F$11:$AJ$11,G$10) | H15: =SUMIFS(CFS!$F$25:$AJ$25,CFS!$F$11:$AJ$11,H$10) | I15: =SUMIFS(CFS!$F$25:$AJ$25,CFS!$F$11:$AJ$11,I$10) | J15: =SUMIFS(CFS!$F$25:$AJ$25,CFS!$F$11:$AJ$11,J$10) | K15: =SUMIFS(CFS!$F$25:$AJ$25,CFS!$F$11:$AJ$11,K$10) | L15: =SUMIFS(CFS!$F$25:$AJ$25,CFS!$F$11:$AJ$11,L$10)
D16: Provisions | E16: =SUMIFS(CFS!$F$17:$AJ$17,CFS!$F$11:$AJ$11,E$10) | F16: =SUMIFS(CFS!$F$17:$AJ$17,CFS!$F$11:$AJ$11,F$10) | G16: =SUMIFS(CFS!$F$17:$AJ$17,CFS!$F$11:$AJ$11,G$10) | H16: =SUMIFS(CFS!$F$17:$AJ$17,CFS!$F$11:$AJ$11,H$10) | I16: =SUMIFS(CFS!$F$17:$AJ$17,CFS!$F$11:$AJ$11,I$10) | J16: =SUMIFS(CFS!$F$17:$AJ$17,CFS!$F$11:$AJ$11,J$10) | K16: =SUMIFS(CFS!$F$17:$AJ$17,CFS!$F$11:$AJ$11,K$10) | L16: =SUMIFS(CFS!$F$17:$AJ$17,CFS!$F$11:$AJ$11,L$10)
D17: Restructuring and asset impairment charges | E17: =SUMIFS(CFS!$F$26:$AJ$26,CFS!$F$11:$AJ$11,E$10) | F17: =SUMIFS(CFS!$F$26:$AJ$26,CFS!$F$11:$AJ$11,F$10) | G17: =SUMIFS(CFS!$F$26:$AJ$26,CFS!$F$11:$AJ$11,G$10) | H17: =SUMIFS(CFS!$F$26:$AJ$26,CFS!$F$11:$AJ$11,H$10) | I17: =SUMIFS(CFS!$F$26:$AJ$26,CFS!$F$11:$AJ$11,I$10) | J17: =SUMIFS(CFS!$F$26:$AJ$26,CFS!$F$11:$AJ$11,J$10) | K17: =SUMIFS(CFS!$F$26:$AJ$26,CFS!$F$11:$AJ$11,K$10) | L17: =SUMIFS(CFS!$F$26:$AJ$26,CFS!$F$11:$AJ$11,L$10)
D18: Payments for restructurings | E18: =SUMIFS(CFS!$F$27:$AJ$27,CFS!$F$11:$AJ$11,E$10) | F18: =SUMIFS(CFS!$F$27:$AJ$27,CFS!$F$11:$AJ$11,F$10) | G18: =SUMIFS(CFS!$F$27:$AJ$27,CFS!$F$11:$AJ$11,G$10) | H18: =SUMIFS(CFS!$F$27:$AJ$27,CFS!$F$11:$AJ$11,H$10) | I18: =SUMIFS(CFS!$F$27:$AJ$27,CFS!$F$11:$AJ$11,I$10) | J18: =SUMIFS(CFS!$F$27:$AJ$27,CFS!$F$11:$AJ$11,J$10) | K18: =SUMIFS(CFS!$F$27:$AJ$27,CFS!$F$11:$AJ$11,K$10) | L18: =SUMIFS(CFS!$F$27:$AJ$27,CFS!$F$11:$AJ$11,L$10)
D19: Contributions to retirement plans | E19: =SUMIFS(CFS!$F$29:$AJ$29,CFS!$F$11:$AJ$11,E$10) | F19: =SUMIFS(CFS!$F$29:$AJ$29,CFS!$F$11:$AJ$11,F$10) | G19: =SUMIFS(CFS!$F$29:$AJ$29,CFS!$F$11:$AJ$11,G$10) | H19: =SUMIFS(CFS!$F$29:$AJ$29,CFS!$F$11:$AJ$11,H$10) | I19: =SUMIFS(CFS!$F$29:$AJ$29,CFS!$F$11:$AJ$11,I$10) | J19: =SUMIFS(CFS!$F$29:$AJ$29,CFS!$F$11:$AJ$11,J$10) | K19: =SUMIFS(CFS!$F$29:$AJ$29,CFS!$F$11:$AJ$11,K$10) | L19: =SUMIFS(CFS!$F$29:$AJ$29,CFS!$F$11:$AJ$11,L$10)
D20: Decrease (increase) in finance receivables | E20: =SUMIFS(CFS!$F$34:$AJ$34,CFS!$F$11:$AJ$11,E$10) | F20: =SUMIFS(CFS!$F$34:$AJ$34,CFS!$F$11:$AJ$11,F$10) | G20: =SUMIFS(CFS!$F$34:$AJ$34,CFS!$F$11:$AJ$11,G$10) | H20: =SUMIFS(CFS!$F$34:$AJ$34,CFS!$F$11:$AJ$11,H$10) | I20: =SUMIFS(CFS!$F$34:$AJ$34,CFS!$F$11:$AJ$11,I$10) | J20: =SUMIFS(CFS!$F$34:$AJ$34,CFS!$F$11:$AJ$11,J$10) | K20: =SUMIFS(CFS!$F$34:$AJ$34,CFS!$F$11:$AJ$11,K$10) | L20: =SUMIFS(CFS!$F$34:$AJ$34,CFS!$F$11:$AJ$11,L$10)
D21: Increase in equipment on operating leases | E21: =SUMIFS(CFS!$F$33:$AJ$33,CFS!$F$11:$AJ$11,E$10) | F21: =SUMIFS(CFS!$F$33:$AJ$33,CFS!$F$11:$AJ$11,F$10) | G21: =SUMIFS(CFS!$F$33:$AJ$33,CFS!$F$11:$AJ$11,G$10) | H21: =SUMIFS(CFS!$F$33:$AJ$33,CFS!$F$11:$AJ$11,H$10) | I21: =SUMIFS(CFS!$F$33:$AJ$33,CFS!$F$11:$AJ$11,I$10) | J21: =SUMIFS(CFS!$F$33:$AJ$33,CFS!$F$11:$AJ$11,J$10) | K21: =SUMIFS(CFS!$F$33:$AJ$33,CFS!$F$11:$AJ$11,K$10) | L21: =SUMIFS(CFS!$F$33:$AJ$33,CFS!$F$11:$AJ$11,L$10)
D22: Change in NWC | E22: =SUMIFS(CFS!$F$46:$AJ$46,CFS!$F$11:$AJ$11,E$10) | F22: =SUMIFS(CFS!$F$46:$AJ$46,CFS!$F$11:$AJ$11,F$10) | G22: =SUMIFS(CFS!$F$46:$AJ$46,CFS!$F$11:$AJ$11,G$10) | H22: =SUMIFS(CFS!$F$46:$AJ$46,CFS!$F$11:$AJ$11,H$10) | I22: =SUMIFS(CFS!$F$46:$AJ$46,CFS!$F$11:$AJ$11,I$10) | J22: =SUMIFS(CFS!$F$46:$AJ$46,CFS!$F$11:$AJ$11,J$10) | K22: =SUMIFS(CFS!$F$46:$AJ$46,CFS!$F$11:$AJ$11,K$10) | L22: =SUMIFS(CFS!$F$46:$AJ$46,CFS!$F$11:$AJ$11,L$10)
D23: Other operating activities | E23: =SUM(E24:E31) | F23: =SUM(F24:F31) | G23: =SUM(G24:G31) | H23: =SUM(H24:H31) | I23: =SUM(I24:I31) | J23: =SUM(J24:J31) | K23: =SUM(K24:K31) | L23: =SUM(L24:L31)
D24: Non-service retirement-related costs | E24: =SUMIFS(CFS!$F$28:$AJ$28,CFS!$F$11:$AJ$11,E$10) | F24: =SUMIFS(CFS!$F$28:$AJ$28,CFS!$F$11:$AJ$11,F$10) | G24: =SUMIFS(CFS!$F$28:$AJ$28,CFS!$F$11:$AJ$11,G$10) | H24: =SUMIFS(CFS!$F$28:$AJ$28,CFS!$F$11:$AJ$11,H$10) | I24: =SUMIFS(CFS!$F$28:$AJ$28,CFS!$F$11:$AJ$11,I$10) | J24: =SUMIFS(CFS!$F$28:$AJ$28,CFS!$F$11:$AJ$11,J$10) | K24: =SUMIFS(CFS!$F$28:$AJ$28,CFS!$F$11:$AJ$11,K$10) | L24: =SUMIFS(CFS!$F$28:$AJ$28,CFS!$F$11:$AJ$11,L$10)
D25: Net (gain) loss on sales of businesses and assets | E25: =SUMIFS(CFS!$F$19:$AJ$19,CFS!$F$11:$AJ$11,E$10) | F25: =SUMIFS(CFS!$F$19:$AJ$19,CFS!$F$11:$AJ$11,F$10) | G25: =SUMIFS(CFS!$F$19:$AJ$19,CFS!$F$11:$AJ$11,G$10) | H25: =SUMIFS(CFS!$F$19:$AJ$19,CFS!$F$11:$AJ$11,H$10) | I25: =SUMIFS(CFS!$F$19:$AJ$19,CFS!$F$11:$AJ$11,I$10) | J25: =SUMIFS(CFS!$F$19:$AJ$19,CFS!$F$11:$AJ$11,J$10) | K25: =SUMIFS(CFS!$F$19:$AJ$19,CFS!$F$11:$AJ$11,K$10) | L25: =SUMIFS(CFS!$F$19:$AJ$19,CFS!$F$11:$AJ$11,L$10)
D26: Net (gain) loss on early extinguishment of debt | E26: =SUMIFS(CFS!$F$18:$AJ$18,CFS!$F$11:$AJ$11,E$10) | F26: =SUMIFS(CFS!$F$18:$AJ$18,CFS!$F$11:$AJ$11,F$10) | G26: =SUMIFS(CFS!$F$18:$AJ$18,CFS!$F$11:$AJ$11,G$10) | H26: =SUMIFS(CFS!$F$18:$AJ$18,CFS!$F$11:$AJ$11,H$10) | I26: =SUMIFS(CFS!$F$18:$AJ$18,CFS!$F$11:$AJ$11,I$10) | J26: =SUMIFS(CFS!$F$18:$AJ$18,CFS!$F$11:$AJ$11,J$10) | K26: =SUMIFS(CFS!$F$18:$AJ$18,CFS!$F$11:$AJ$11,K$10) | L26: =SUMIFS(CFS!$F$18:$AJ$18,CFS!$F$11:$AJ$11,L$10)
D27: Lexmark inventory purchase accounting adjustment, noncash | E27: =SUMIFS(CFS!$F$20:$AJ$20,CFS!$F$11:$AJ$11,E$10) | F27: =SUMIFS(CFS!$F$20:$AJ$20,CFS!$F$11:$AJ$11,F$10) | G27: =SUMIFS(CFS!$F$20:$AJ$20,CFS!$F$11:$AJ$11,G$10) | H27: =SUMIFS(CFS!$F$20:$AJ$20,CFS!$F$11:$AJ$11,H$10) | I27: =SUMIFS(CFS!$F$20:$AJ$20,CFS!$F$11:$AJ$11,I$10) | J27: =SUMIFS(CFS!$F$20:$AJ$20,CFS!$F$11:$AJ$11,J$10) | K27: =SUMIFS(CFS!$F$20:$AJ$20,CFS!$F$11:$AJ$11,K$10) | L27: =SUMIFS(CFS!$F$20:$AJ$20,CFS!$F$11:$AJ$11,L$10)
D28: Effective settlement of pre-existing Lexmark relationship | E28: =SUMIFS(CFS!$F$21:$AJ$21,CFS!$F$11:$AJ$11,E$10) | F28: =SUMIFS(CFS!$F$21:$AJ$21,CFS!$F$11:$AJ$11,F$10) | G28: =SUMIFS(CFS!$F$21:$AJ$21,CFS!$F$11:$AJ$11,G$10) | H28: =SUMIFS(CFS!$F$21:$AJ$21,CFS!$F$11:$AJ$11,H$10) | I28: =SUMIFS(CFS!$F$21:$AJ$21,CFS!$F$11:$AJ$11,I$10) | J28: =SUMIFS(CFS!$F$21:$AJ$21,CFS!$F$11:$AJ$11,J$10) | K28: =SUMIFS(CFS!$F$21:$AJ$21,CFS!$F$11:$AJ$11,K$10) | L28: =SUMIFS(CFS!$F$21:$AJ$21,CFS!$F$11:$AJ$11,L$10)
D29: Divestitures | E29: =SUMIFS(CFS!$F$22:$AJ$22,CFS!$F$11:$AJ$11,E$10) | F29: =SUMIFS(CFS!$F$22:$AJ$22,CFS!$F$11:$AJ$11,F$10) | G29: =SUMIFS(CFS!$F$22:$AJ$22,CFS!$F$11:$AJ$11,G$10) | H29: =SUMIFS(CFS!$F$22:$AJ$22,CFS!$F$11:$AJ$11,H$10) | I29: =SUMIFS(CFS!$F$22:$AJ$22,CFS!$F$11:$AJ$11,I$10) | J29: =SUMIFS(CFS!$F$22:$AJ$22,CFS!$F$11:$AJ$11,J$10) | K29: =SUMIFS(CFS!$F$22:$AJ$22,CFS!$F$11:$AJ$11,K$10) | L29: =SUMIFS(CFS!$F$22:$AJ$22,CFS!$F$11:$AJ$11,L$10)
D30: PARC donation | E30: =SUMIFS(CFS!$F$23:$AJ$23,CFS!$F$11:$AJ$11,E$10) | F30: =SUMIFS(CFS!$F$23:$AJ$23,CFS!$F$11:$AJ$11,F$10) | G30: =SUMIFS(CFS!$F$23:$AJ$23,CFS!$F$11:$AJ$11,G$10) | H30: =SUMIFS(CFS!$F$23:$AJ$23,CFS!$F$11:$AJ$11,H$10) | I30: =SUMIFS(CFS!$F$23:$AJ$23,CFS!$F$11:$AJ$11,I$10) | J30: =SUMIFS(CFS!$F$23:$AJ$23,CFS!$F$11:$AJ$11,J$10) | K30: =SUMIFS(CFS!$F$23:$AJ$23,CFS!$F$11:$AJ$11,K$10) | L30: =SUMIFS(CFS!$F$23:$AJ$23,CFS!$F$11:$AJ$11,L$10)
D31: Other operating, net | E31: =SUMIFS(CFS!$F$41:$AJ$41,CFS!$F$11:$AJ$11,E$10) | F31: =SUMIFS(CFS!$F$41:$AJ$41,CFS!$F$11:$AJ$11,F$10) | G31: =SUMIFS(CFS!$F$41:$AJ$41,CFS!$F$11:$AJ$11,G$10) | H31: =SUMIFS(CFS!$F$41:$AJ$41,CFS!$F$11:$AJ$11,H$10) | I31: =SUMIFS(CFS!$F$41:$AJ$41,CFS!$F$11:$AJ$11,I$10) | J31: =SUMIFS(CFS!$F$41:$AJ$41,CFS!$F$11:$AJ$11,J$10) | K31: =SUMIFS(CFS!$F$41:$AJ$41,CFS!$F$11:$AJ$11,K$10) | L31: =SUMIFS(CFS!$F$41:$AJ$41,CFS!$F$11:$AJ$11,L$10)
D32: Cash Flow from Operations | E32: =SUM(E12:E23) | F32: =SUM(F12:F23) | G32: =SUM(G12:G23) | H32: =SUM(H12:H23) | I32: =SUM(I12:I23) | J32: =SUM(J12:J23) | K32: =SUM(K12:K23) | L32: =SUM(L12:L23)
D33: CFO | E33: =SUMIFS(CFS!$F$43:$AJ$43,CFS!$F$11:$AJ$11,E$10) | F33: =SUMIFS(CFS!$F$43:$AJ$43,CFS!$F$11:$AJ$11,F$10) | G33: =SUMIFS(CFS!$F$43:$AJ$43,CFS!$F$11:$AJ$11,G$10) | H33: =SUMIFS(CFS!$F$43:$AJ$43,CFS!$F$11:$AJ$11,H$10) | I33: =SUMIFS(CFS!$F$43:$AJ$43,CFS!$F$11:$AJ$11,I$10) | J33: =SUMIFS(CFS!$F$43:$AJ$43,CFS!$F$11:$AJ$11,J$10) | K33: =SUMIFS(CFS!$F$43:$AJ$43,CFS!$F$11:$AJ$11,K$10) | L33: =SUMIFS(CFS!$F$43:$AJ$43,CFS!$F$11:$AJ$11,L$10)
D34: Check | E34: =E32-E33 | F34: =F32-F33 | G34: =G32-G33 | H34: =H32-H33 | I34: =I32-I33 | J34: =J32-J33 | K34: =K32-K33 | L34: =L32-L33
D36: Capital expenditures | E36: =SUMIFS(CFS!$F$49:$AJ$49,CFS!$F$11:$AJ$11,E$10) | F36: =SUMIFS(CFS!$F$49:$AJ$49,CFS!$F$11:$AJ$11,F$10) | G36: =SUMIFS(CFS!$F$49:$AJ$49,CFS!$F$11:$AJ$11,G$10) | H36: =SUMIFS(CFS!$F$49:$AJ$49,CFS!$F$11:$AJ$11,H$10) | I36: =SUMIFS(CFS!$F$49:$AJ$49,CFS!$F$11:$AJ$11,I$10) | J36: =SUMIFS(CFS!$F$49:$AJ$49,CFS!$F$11:$AJ$11,J$10) | K36: =SUMIFS(CFS!$F$49:$AJ$49,CFS!$F$11:$AJ$11,K$10) | L36: =SUMIFS(CFS!$F$49:$AJ$49,CFS!$F$11:$AJ$11,L$10)
D37: Acquisitions, net of cash acquired | E37: =SUMIFS(CFS!$F$51:$AJ$51,CFS!$F$11:$AJ$11,E$10) | F37: =SUMIFS(CFS!$F$51:$AJ$51,CFS!$F$11:$AJ$11,F$10) | G37: =SUMIFS(CFS!$F$51:$AJ$51,CFS!$F$11:$AJ$11,G$10) | H37: =SUMIFS(CFS!$F$51:$AJ$51,CFS!$F$11:$AJ$11,H$10) | I37: =SUMIFS(CFS!$F$51:$AJ$51,CFS!$F$11:$AJ$11,I$10) | J37: =SUMIFS(CFS!$F$51:$AJ$51,CFS!$F$11:$AJ$11,J$10) | K37: =SUMIFS(CFS!$F$51:$AJ$51,CFS!$F$11:$AJ$11,K$10) | L37: =SUMIFS(CFS!$F$51:$AJ$51,CFS!$F$11:$AJ$11,L$10)
D38: Proceeds from sales of businesses and assets | E38: =SUMIFS(CFS!$F$50:$AJ$50,CFS!$F$11:$AJ$11,E$10) | F38: =SUMIFS(CFS!$F$50:$AJ$50,CFS!$F$11:$AJ$11,F$10) | G38: =SUMIFS(CFS!$F$50:$AJ$50,CFS!$F$11:$AJ$11,G$10) | H38: =SUMIFS(CFS!$F$50:$AJ$50,CFS!$F$11:$AJ$11,H$10) | I38: =SUMIFS(CFS!$F$50:$AJ$50,CFS!$F$11:$AJ$11,I$10) | J38: =SUMIFS(CFS!$F$50:$AJ$50,CFS!$F$11:$AJ$11,J$10) | K38: =SUMIFS(CFS!$F$50:$AJ$50,CFS!$F$11:$AJ$11,K$10) | L38: =SUMIFS(CFS!$F$50:$AJ$50,CFS!$F$11:$AJ$11,L$10)
D39: Other investing activities | E39: =SUM(E40:E40) | F39: =SUM(F40:F40) | G39: =SUM(G40:G40) | H39: =SUM(H40:H40) | I39: =SUM(I40:I40) | J39: =SUM(J40:J40) | K39: =SUM(K40:K40) | L39: =SUM(L40:L40)
D40: Other investing, net | E40: =SUMIFS(CFS!$F$52:$AJ$52,CFS!$F$11:$AJ$11,E$10) | F40: =SUMIFS(CFS!$F$52:$AJ$52,CFS!$F$11:$AJ$11,F$10) | G40: =SUMIFS(CFS!$F$52:$AJ$52,CFS!$F$11:$AJ$11,G$10) | H40: =SUMIFS(CFS!$F$52:$AJ$52,CFS!$F$11:$AJ$11,H$10) | I40: =SUMIFS(CFS!$F$52:$AJ$52,CFS!$F$11:$AJ$11,I$10) | J40: =SUMIFS(CFS!$F$52:$AJ$52,CFS!$F$11:$AJ$11,J$10) | K40: =SUMIFS(CFS!$F$52:$AJ$52,CFS!$F$11:$AJ$11,K$10) | L40: =SUMIFS(CFS!$F$52:$AJ$52,CFS!$F$11:$AJ$11,L$10)
D41: Cash Flow from Investing | E41: =SUM(E36:E39) | F41: =SUM(F36:F39) | G41: =SUM(G36:G39) | H41: =SUM(H36:H39) | I41: =SUM(I36:I39) | J41: =SUM(J36:J39) | K41: =SUM(K36:K39) | L41: =SUM(L36:L39)
D42: CFI | E42: =SUMIFS(CFS!$F$54:$AJ$54,CFS!$F$11:$AJ$11,E$10) | F42: =SUMIFS(CFS!$F$54:$AJ$54,CFS!$F$11:$AJ$11,F$10) | G42: =SUMIFS(CFS!$F$54:$AJ$54,CFS!$F$11:$AJ$11,G$10) | H42: =SUMIFS(CFS!$F$54:$AJ$54,CFS!$F$11:$AJ$11,H$10) | I42: =SUMIFS(CFS!$F$54:$AJ$54,CFS!$F$11:$AJ$11,I$10) | J42: =SUMIFS(CFS!$F$54:$AJ$54,CFS!$F$11:$AJ$11,J$10) | K42: =SUMIFS(CFS!$F$54:$AJ$54,CFS!$F$11:$AJ$11,K$10) | L42: =SUMIFS(CFS!$F$54:$AJ$54,CFS!$F$11:$AJ$11,L$10)
D43: Check | E43: =E41-E42 | F43: =F41-F42 | G43: =G41-G42 | H43: =H41-H42 | I43: =I41-I42 | J43: =J41-J42 | K43: =K41-K42 | L43: =L41-L42
D45: Proceeds from issuance of long-term debt | E45: =SUMIFS(CFS!$F$59:$AJ$59,CFS!$F$11:$AJ$11,E$10) | F45: =SUMIFS(CFS!$F$59:$AJ$59,CFS!$F$11:$AJ$11,F$10) | G45: =SUMIFS(CFS!$F$59:$AJ$59,CFS!$F$11:$AJ$11,G$10) | H45: =SUMIFS(CFS!$F$59:$AJ$59,CFS!$F$11:$AJ$11,H$10) | I45: =SUMIFS(CFS!$F$59:$AJ$59,CFS!$F$11:$AJ$11,I$10) | J45: =SUMIFS(CFS!$F$59:$AJ$59,CFS!$F$11:$AJ$11,J$10) | K45: =SUMIFS(CFS!$F$59:$AJ$59,CFS!$F$11:$AJ$11,K$10) | L45: =SUMIFS(CFS!$F$59:$AJ$59,CFS!$F$11:$AJ$11,L$10)
D46: Payments on long-term debt | E46: =SUMIFS(CFS!$F$60:$AJ$60,CFS!$F$11:$AJ$11,E$10) | F46: =SUMIFS(CFS!$F$60:$AJ$60,CFS!$F$11:$AJ$11,F$10) | G46: =SUMIFS(CFS!$F$60:$AJ$60,CFS!$F$11:$AJ$11,G$10) | H46: =SUMIFS(CFS!$F$60:$AJ$60,CFS!$F$11:$AJ$11,H$10) | I46: =SUMIFS(CFS!$F$60:$AJ$60,CFS!$F$11:$AJ$11,I$10) | J46: =SUMIFS(CFS!$F$60:$AJ$60,CFS!$F$11:$AJ$11,J$10) | K46: =SUMIFS(CFS!$F$60:$AJ$60,CFS!$F$11:$AJ$11,K$10) | L46: =SUMIFS(CFS!$F$60:$AJ$60,CFS!$F$11:$AJ$11,L$10)
D47: Net proceeds (payments) on short-term debt | E47: =SUMIFS(CFS!$F$58:$AJ$58,CFS!$F$11:$AJ$11,E$10) | F47: =SUMIFS(CFS!$F$58:$AJ$58,CFS!$F$11:$AJ$11,F$10) | G47: =SUMIFS(CFS!$F$58:$AJ$58,CFS!$F$11:$AJ$11,G$10) | H47: =SUMIFS(CFS!$F$58:$AJ$58,CFS!$F$11:$AJ$11,H$10) | I47: =SUMIFS(CFS!$F$58:$AJ$58,CFS!$F$11:$AJ$11,I$10) | J47: =SUMIFS(CFS!$F$58:$AJ$58,CFS!$F$11:$AJ$11,J$10) | K47: =SUMIFS(CFS!$F$58:$AJ$58,CFS!$F$11:$AJ$11,K$10) | L47: =SUMIFS(CFS!$F$58:$AJ$58,CFS!$F$11:$AJ$11,L$10)
D48: Dividends | E48: =SUMIFS(CFS!$F$63:$AJ$63,CFS!$F$11:$AJ$11,E$10) | F48: =SUMIFS(CFS!$F$63:$AJ$63,CFS!$F$11:$AJ$11,F$10) | G48: =SUMIFS(CFS!$F$63:$AJ$63,CFS!$F$11:$AJ$11,G$10) | H48: =SUMIFS(CFS!$F$63:$AJ$63,CFS!$F$11:$AJ$11,H$10) | I48: =SUMIFS(CFS!$F$63:$AJ$63,CFS!$F$11:$AJ$11,I$10) | J48: =SUMIFS(CFS!$F$63:$AJ$63,CFS!$F$11:$AJ$11,J$10) | K48: =SUMIFS(CFS!$F$63:$AJ$63,CFS!$F$11:$AJ$11,K$10) | L48: =SUMIFS(CFS!$F$63:$AJ$63,CFS!$F$11:$AJ$11,L$10)
...

Sheet BS
A1: =D3 | B1: ='Cover Page'!A1
D3: Balance Sheet Spread
D4: Xerox Holdings Corporation – All values in $ millions (USD), except per-share values. Data as of June 30, 2026 (2Q'26).
A5: x | D5: Balance Sheet | F5: Quarter Ended | AC5: Fiscal Year Ended December 31, | AI5: Variance
F6: 1 | G6: 2 | H6: 3 | I6: 4 | J6: 1 | K6: 2 | L6: 3 | M6: 4 | N6: 1 | O6: 2 | P6: 3 | Q6: 4 | R6: 1 | S6: 2 | T6: 3 | U6: 4 | V6: 1 | W6: 2 | X6: 3 | Y6: 4 | Z6: 1 | AA6: 2
F7: 2021 | G7: 2021 | H7: 2021 | I7: 2021 | J7: 2022 | K7: 2022 | L7: 2022 | M7: 2022 | N7: 2023 | O7: 2023 | P7: 2023 | Q7: 2023 | R7: 2024 | S7: 2024 | T7: 2024 | U7: 2024 | V7: 2025 | W7: 2025 | X7: 2025 | Y7: 2025 | Z7: 2026 | AA7: 2026 | AC7: 2021 | AD7: 2022 | AE7: 2023 | AF7: 2024 | AG7: 2025
F8: 44286 | G8: 44377 | H8: 44469 | I8: 44561 | J8: 44651 | K8: 44742 | L8: 44834 | M8: 44926 | N8: 45016 | O8: 45107 | P8: 45199 | Q8: 45291 | R8: 45382 | S8: 45473 | T8: 45565 | U8: 45657 | V8: 45747 | W8: 45838 | X8: 45930 | Y8: 46022 | Z8: 46112 | AA8: 46203 | AC8: 44561 | AD8: 44926 | AE8: 45291 | AF8: 45657 | AG8: 46022
F10: =F6&"Q'"&RIGHT(F7,2) | G10: =G6&"Q'"&RIGHT(G7,2) | H10: =H6&"Q'"&RIGHT(H7,2) | I10: =I6&"Q'"&RIGHT(I7,2) | J10: =J6&"Q'"&RIGHT(J7,2) | K10: =K6&"Q'"&RIGHT(K7,2) | L10: =L6&"Q'"&RIGHT(L7,2) | M10: =M6&"Q'"&RIGHT(M7,2) | ... AA10: =AA6&"Q'"&RIGHT(AA7,2) | AC10: 2021 | AD10: 2022 | AE10: 2023 | AF10: 2024 | AG10: 2025 | AI10: $ Chg '25 | AJ10: % Chg '25
D12: ASSETS
D13: Cash and cash equivalents | F13: 2379 | G13: 2124 | H13: 2209 | I13: 1840 | J13: 1681 | K13: 1151 | L13: 932 | M13: 1045 | N13: 591 | O13: 477 | P13: 532 | Q13: 519 | R13: 685 | S13: 485 | T13: 521 | U13: 576 | V13: 336 | W13: 449 | X13: 479 | Y13: 512 | Z13: 585 | AA13: 495 | AC13: =I13 | AD13: =M13 | AE13: =Q13 | AF13: =U13 | AG13: =Y13 | AI13: =AG13-AF13 | AJ13: =IFERROR(AI13/ABS(AF13),0)
D14: Accounts receivable, net | F14: 781 | G14: 846 | H14: 891 | I14: 818 | J14: 807 | K14: 852 | L14: 835 | M14: 857 | N14: 818 | O14: 903 | P14: 880 | Q14: 850 | R14: 846 | S14: 847 | T14: 821 | U14: 796 | V14: 819 | W14: 862 | X14: 1196 | Y14: 1122 | Z14: 1218 | AA14: 1185 | AC14: =I14 | AD14: =M14 | AE14: =Q14 | AF14: =U14 | AG14: =Y14 | AI14: =AG14-AF14 | AJ14: =IFERROR(AI14/ABS(AF14),0)
D15: Billed portion of finance receivables, net | F15: 92 | G15: 89 | H15: 100 | I15: 94 | J15: 89 | K15: 83 | L15: 91 | M15: 93 | N15: 94 | O15: 70 | P15: 80 | Q15: 71 | R15: 67 | S15: 70 | T15: 50 | U15: 48 | V15: 43 | W15: 46 | X15: 53 | Y15: 46 | Z15: 43 | AA15: 40 | AC15: =I15 | AD15: =M15 | AE15: =Q15 | AF15: =U15 | AG15: =Y15 | AI15: =AG15-AF15 | AJ15: =IFERROR(AI15/ABS(AF15),0)
D16: Finance receivables, net | F16: 1065 | G16: 1057 | H16: 1039 | I16: 1042 | J16: 1023 | K16: 1019 | L16: 995 | M16: 1061 | N16: 1022 | O16: 940 | P16: 906 | Q16: 842 | R16: 783 | S16: 713 | T16: 664 | U16: 608 | V16: 583 | W16: 584 | X16: 553 | Y16: 510 | Z16: 476 | AA16: 442 | AC16: =I16 | AD16: =M16 | AE16: =Q16 | AF16: =U16 | AG16: =Y16 | AI16: =AG16-AF16 | AJ16: =IFERROR(AI16/ABS(AF16),0)
D17: Inventories | F17: 841 | G17: 815 | H17: 788 | I17: 696 | J17: 732 | K17: 765 | L17: 777 | M17: 797 | N17: 863 | O17: 782 | P17: 728 | Q17: 661 | R17: 736 | S17: 737 | T17: 732 | U17: 695 | V17: 836 | W17: 871 | X17: 1143 | Y17: 1016 | Z17: 1043 | AA17: 1043 | AC17: =I17 | AD17: =M17 | AE17: =Q17 | AF17: =U17 | AG17: =Y17 | AI17: =AG17-AF17 | AJ17: =IFERROR(AI17/ABS(AF17),0)
D18: Other current assets | F18: 262 | G18: 244 | H18: 209 | I18: 211 | J18: 234 | K18: 232 | L18: 265 | M18: 254 | N18: 252 | O18: 218 | P18: 228 | Q18: 234 | R18: 231 | S18: 199 | T18: 223 | U18: 212 | V18: 250 | W18: 731 | X18: 329 | Y18: 362 | Z18: 415 | AA18: 492 | AC18: =I18 | AD18: =M18 | AE18: =Q18 | AF18: =U18 | AG18: =Y18 | AI18: =AG18-AF18 | AJ18: =IFERROR(AI18/ABS(AF18),0)
D19: Total current assets | F19: =SUM(F13:F18) | G19: =SUM(G13:G18) | H19: =SUM(H13:H18) | I19: =SUM(I13:I18) | J19: =SUM(J13:J18) | K19: =SUM(K13:K18) | L19: =SUM(L13:L18) | M19: =SUM(M13:M18) | ... AA19: =SUM(AA13:AA18) | AC19: =SUM(AC13:AC18) | AD19: =SUM(AD13:AD18) | AE19: =SUM(AE13:AE18) | AF19: =SUM(AF13:AF18) | AG19: =SUM(AG13:AG18) | AI19: =AG19-AF19 | AJ19: =IFERROR(AI19/ABS(AF19),0)
D20: Total current assets | F20: 5420 | G20: 5175 | H20: 5236 | I20: 4701 | J20: 4566 | K20: 4102 | L20: 3895 | M20: 4107 | N20: 3640 | O20: 3390 | P20: 3354 | Q20: 3177 | R20: 3348 | S20: 3051 | T20: 3011 | U20: 2935 | V20: 2867 | W20: 3543 | X20: 3753 | Y20: 3568 | Z20: 3780 | AA20: 3697 | AC20: =I20 | AD20: =M20 | AE20: =Q20 | AF20: =U20 | AG20: =Y20
D21: Check | F21: =F19-F20 | G21: =G19-G20 | H21: =H19-H20 | I21: =I19-I20 | J21: =J19-J20 | K21: =K19-K20 | L21: =L19-L20 | M21: =M19-M20 | ... AA21: =AA19-AA20 | AC21: =AC19-AC20 | AD21: =AD19-AD20 | AE21: =AE19-AE20 | AF21: =AF19-AF20 | AG21: =AG19-AG20
D22: Finance receivables due after one year, net | F22: 1920 | G22: 1971 | H22: 1936 | I22: 1934 | J22: 1893 | K22: 1845 | L22: 1814 | M22: 1948 | N22: 1864 | O22: 1697 | P22: 1605 | Q22: 1597 | R22: 1408 | S22: 1277 | T22: 1275 | U22: 1089 | V22: 1013 | W22: 990 | X22: 950 | Y22: 846 | Z22: 797 | AA22: 732 | AC22: =I22 | AD22: =M22 | AE22: =Q22 | AF22: =U22 | AG22: =Y22 | AI22: =AG22-AF22 | AJ22: =IFERROR(AI22/ABS(AF22),0)
D23: Equipment on operating leases, net | F23: 277 | G23: 271 | H23: 254 | I23: 253 | J23: 254 | K23: 226 | L23: 216 | M23: 235 | N23: 250 | O23: 259 | P23: 257 | Q23: 265 | R23: 257 | S23: 253 | T23: 255 | U23: 245 | V23: 248 | W23: 249 | X23: 300 | Y23: 299 | Z23: 292 | AA23: 283 | AC23: =I23 | AD23: =M23 | AE23: =Q23 | AF23: =U23 | AG23: =Y23 | AI23: =AG23-AF23 | AJ23: =IFERROR(AI23/ABS(AF23),0)
D24: Land, buildings and equipment, net | F24: 393 | G24: 372 | H24: 370 | I24: 358 | J24: 350 | K24: 334 | L24: 315 | M24: 320 | N24: 311 | O24: 281 | P24: 273 | Q24: 266 | R24: 245 | S24: 227 | T24: 225 | U24: 251 | V24: 195 | W24: 187 | X24: 427 | Y24: 390 | Z24: 378 | AA24: 378 | AC24: =I24 | AD24: =M24 | AE24: =Q24 | AF24: =U24 | AG24: =Y24 | AI24: =AG24-AF24 | AJ24: =IFERROR(AI24/ABS(AF24),0)
D25: Intangible assets, net | F25: 223 | G25: 230 | H25: 216 | I25: 211 | J25: 240 | K25: 223 | L25: 216 | M25: 208 | N25: 202 | O25: 194 | P25: 183 | Q25: 177 | R25: 165 | S25: 155 | T25: 149 | U25: 236 | V25: 228 | W25: 222 | X25: 954 | Y25: 921 | Z25: 891 | AA25: 857 | AC25: =I25 | AD25: =M25 | AE25: =Q25 | AF25: =U25 | AG25: =Y25 | AI25: =AG25-AF25 | AJ25: =IFERROR(AI25/ABS(AF25),0)
D26: Goodwill, net | F26: 4075 | G26: 4104 | H26: 4066 | I26: 3287 | J26: 3300 | K26: 3217 | L26: 2753 | M26: 2820 | N26: 2850 | O26: 2751 | P26: 2716 | Q26: 2747 | R26: 2720 | S26: 2719 | T26: 1709 | U26: 1937 | V26: 1954 | W26: 1984 | X26: 2182 | Y26: 2222 | Z26: 2201 | AA26: 2234 | AC26: =I26 | AD26: =M26 | AE26: =Q26 | AF26: =U26 | AG26: =Y26 | AI26: =AG26-AF26 | AJ26: =IFERROR(AI26/ABS(AF26),0)
D27: Deferred tax assets | F27: 510 | G27: 491 | H27: 511 | I27: 519 | J27: 528 | K27: 539 | L27: 496 | M27: 582 | N27: 598 | O27: 620 | P27: 701 | Q27: 745 | R27: 749 | S27: 760 | T27: 635 | U27: 615 | V27: 607 | W27: 551 | X27: 101 | Y27: 98 | Z27: 96 | AA27: 86 | AC27: =I27 | AD27: =M27 | AE27: =Q27 | AF27: =U27 | AG27: =Y27 | AI27: =AG27-AF27 | AJ27: =IFERROR(AI27/ABS(AF27),0)
D28: Other long-term assets | F28: 1454 | G28: 1496 | H28: 1492 | I28: 1960 | J28: 1951 | K28: 1784 | L28: 1715 | M28: 1323 | N28: 1331 | O28: 1377 | P28: 1355 | Q28: 1034 | R28: 1052 | S28: 1049 | T28: 1063 | U28: 1057 | V28: 1099 | W28: 1148 | X28: 1401 | Y28: 1479 | Z28: 1467 | AA28: 1457 | AC28: =I28 | AD28: =M28 | AE28: =Q28 | AF28: =U28 | AG28: =Y28 | AI28: =AG28-AF28 | AJ28: =IFERROR(AI28/ABS(AF28),0)
D29: Total assets | F29: =SUM(F22:F28)+F19 | G29: =SUM(G22:G28)+G19 | H29: =SUM(H22:H28)+H19 | I29: =SUM(I22:I28)+I19 | J29: =SUM(J22:J28)+J19 | K29: =SUM(K22:K28)+K19 | L29: =SUM(L22:L28)+L19 | M29: =SUM(M22:M28)+M19 | ... AA29: =SUM(AA22:AA28)+AA19 | AC29: =SUM(AC22:AC28)+AC19 | AD29: =SUM(AD22:AD28)+AD19 | AE29: =SUM(AE22:AE28)+AE19 | AF29: =SUM(AF22:AF28)+AF19 | AG29: =SUM(AG22:AG28)+AG19 | AI29: =AG29-AF29 | AJ29: =IFERROR(AI29/ABS(AF29),0)
D30: Total assets | F30: 14272 | G30: 14110 | H30: 14081 | I30: 13223 | J30: 13082 | K30: 12270 | L30: 11420 | M30: 11543 | N30: 11046 | O30: 10569 | P30: 10444 | Q30: 10008 | R30: 9944 | S30: 9491 | T30: 8322 | U30: 8365 | V30: 8211 | W30: 8874 | X30: 10068 | Y30: 9823 | Z30: 9902 | AA30: 9724 | AC30: =I30 | AD30: =M30 | AE30: =Q30 | AF30: =U30 | AG30: =Y30
D31: Check | F31: =F29-F30 | G31: =G29-G30 | H31: =H29-H30 | I31: =I29-I30 | J31: =J29-J30 | K31: =K29-K30 | L31: =L29-L30 | M31: =M29-M30 | ... AA31: =AA29-AA30 | AC31: =AC29-AC30 | AD31: =AD29-AD30 | AE31: =AE29-AE30 | AF31: =AF29-AF30 | AG31: =AG29-AG30
D33: LIABILITIES AND EQUITY
D34: Current liabilities
