Workbook
Name Active_Case: '[1]Cover Page'!$E$13
Name Circ: '[1]Cover Page'!$E$14
Name Days: '[1]Cover Page'!$E$19
Name Divest: '[1]Cover Page'!$E$18
Name Exit: '[1]Cover Page'!$E$20
Name Exit_Case: '[1]Cover Page'!$E$15

Sheet Cover Page
A1: Return to Cover
C2: Xerox Holdings Corporation (NASDAQ: XRX) – Restructuring Model
C3: All $ in Millions (USD), except Per-Share Values
C8: Credit & Restructuring Analysis
C10: Last Updated | F10: =TODAY() | H10: Data As Of | J10: 2Q'26 (June 30, 2026)
C12: Color Coding | D12: R | E12: G | F12: B | H12: Links (Ctrl + [ to Jump to Sheet)
C13: Formulas | D13: 0 | E13: 0 | F13: 0 | H13: Financial Statements
C14: Hard-Code | D14: 0 | E14: 0 | F14: 255 | H14: ='Income Statement'!A1
C15: Link to Other Sheets | D15: 0 | E15: 128 | F15: 0 | H15: ='Income Statement Output'!A1
C16: Highlight Value (Check) | D16: 255 | E16: 0 | F16: 0 | H16: ='Cash Flow Statement'!A1
H17: ='Cash Flow Statement Output'!A1
C18: Heading 1 | D18: 0 | E18: 32 | F18: 96 | H18: ='Balance Sheet'!A1
C19: Heading 2 | D19: 128 | E19: 128 | F19: 128 | H19: ='Balance Sheet Output'!A1
H20: Credit Analysis
C21: Input/Driver | D21: 255 | E21: 242 | F21: 204 | H21: ='NWC'!A1
H22: ='Quarterly NWC'!A1
C23: Sources | H23: ='Capital Structure'!A1
C24: SEC EDGAR – Xerox 10-K & 10-Q Filings | H24: ='Maturity Schedule'!A1
C25: Xerox Investor Relations – Earnings Materials
C26: Moody's & S&P Rating Actions | H26: Analysis
C27: TRACE-Based Bond Quotes (Indicative) | H27: ='Precedent Transactions'!A1
C28: Federal Reserve Bank of New York – SOFR | H28: ='$XRX Comparable Companies'!A1
C29: Note: All Financials Pulled from Xerox 10-Qs & 10-Ks | H29: ='$XRX Revenue Build'!A1
H30: ='$XRX DCF Operating Assumptions'!A1
C31: Active Case (DCF / Revenue Build) | F31: Base | H31: ='$XRX DCF'!A1
H32: ='Liquidity Analysis'!A1
H34: Stock Performance & Valuation
H35: ='$XRX Stock Performance'!A1
H36: ='$FRSH Valuation FF'!A1
H37: ='Charts'!A1

Sheet Financial Statement Inputs >
A1: Financial Statements > | B1: ='Cover Page'!A1

Sheet Income Statement
A1: =C3 | B1: ='Cover Page'!A1
C3: Historical Income Statement | AH3: Xerox Holding Corporation
C4: All values in $ millions (USD), except per-share values
A6: x | B6: x | C6: Income Statement | D6: Quarter Ended | AA6: Fiscal Year Ended December 31, | AG6: LTM
D7: 1Q'21 | E7: 2Q'21 | F7: 3Q'21 | G7: 4Q'21 | H7: 1Q'22 | I7: 2Q'22 | J7: 3Q'22 | K7: 4Q'22 | L7: 1Q'23 | M7: 2Q'23 | N7: 3Q'23 | O7: 4Q'23 | P7: 1Q'24 | Q7: 2Q'24 | R7: 3Q'24 | S7: 4Q'24 | T7: 1Q'25 | U7: 2Q'25 | V7: 3Q'25 | W7: 4Q'25 | X7: 1Q'26 | Y7: 2Q'26 | AA7: FY2021 | AB7: FY2022 | AC7: FY2023 | AD7: FY2024 | AE7: FY2025 | AG7: LTM 2Q'25 | AH7: LTM 2Q'26
C9: Revenues:
C10: Sales | D10: 602 | E10: 670 | F10: 657 | G10: =AA10-SUM(D10:F10) | H10: 592 | I10: 667 | J10: 690 | K10: =AB10-SUM(H10:J10) | L10: 659 | M10: 696 | N10: 644 | O10: =AC10-SUM(L10:N10) | P10: 523 | Q10: 611 | R10: 588 | S10: =AD10-SUM(P10:R10) | T10: 557 | U10: 665 | V10: 993 | W10: =AE10-SUM(T10:V10) | X10: 920 | Y10: 996 | AA10: 2582 | AB10: 2800 | AC10: 2720 | AD10: 2378 | AE10: 3283 | AG10: =SUM(R10:U10) | AH10: =SUM(V10:Y10)
C11: Services, maintenance, rentals and other | D11: =1053+55 | E11: =1067+56 | F11: =1046+55 | G11: =AA11-SUM(D11:F11) | H11: =1023+53 | I11: =1028+52 | J11: =1010+51 | K11: =AB11-SUM(H11:J11) | L11: =1004+52 | M11: =1009+49 | N11: =962+46 | O11: =AC11-SUM(L11:N11) | P11: 979 | Q11: 967 | R11: 940 | S11: =AD11-SUM(P11:R11) | T11: 900 | U11: 911 | V11: 968 | W11: =AE11-SUM(T11:V11) | X11: 926 | Y11: 926 | AA11: =4235+221 | AB11: =4100+207 | AC11: 4166 | AD11: 3843 | AE11: 3739 | AG11: =SUM(R11:U11) | AH11: =SUM(V11:Y11)
C12: Total revenues | D12: =D10+D11 | E12: =E10+E11 | F12: =F10+F11 | G12: =G10+G11 | H12: =H10+H11 | I12: =I10+I11 | J12: =J10+J11 | K12: =K10+K11 | ... Y12: =Y10+Y11 | AA12: =AA10+AA11 | AB12: =AB10+AB11 | AC12: =AC10+AC11 | AD12: =AD10+AD11 | AE12: =AE10+AE11 | AG12: =AG10+AG11 | AH12: =AH10+AH11
C14: Expenses:
C15: Cost of sales | D15: 420 | E15: 468 | F15: 498 | G15: =AA15-SUM(D15:F15) | H15: 435 | I15: 487 | J15: 508 | K15: =AB15-SUM(H15:J15) | L15: 425 | M15: 452 | N15: 435 | O15: =AC15-SUM(L15:N15) | P15: 340 | Q15: 387 | R15: 390 | S15: =AD15-SUM(P15:R15) | T15: 382 | U15: 480 | V15: 788 | W15: =AE15-SUM(T15:V15) | X15: 600 | Y15: 579 | AA15: 1862 | AB15: 2002 | AC15: 1778 | AD15: 1562 | AE15: 2367 | AG15: =SUM(R15:U15) | AH15: =SUM(V15:Y15)
C16: Cost of services, maintenance, rentals and other | D16: =651+28 | E16: =658+28 | F16: =662+29 | G16: =AA16-SUM(D16:F16) | H16: =679+24 | I16: =677+26 | J16: =659+28 | K16: =AB16-SUM(H16:J16) | L16: =665+36 | M16: =671+34 | N16: =651+30 | O16: =AC16-SUM(L16:N16) | P16: 719 | Q16: 671 | R16: 643 | S16: =AD16-SUM(P16:R16) | T16: 649 | U16: 645 | V16: 728 | W16: =AE16-SUM(T16:V16) | X16: 697 | Y16: 655 | AA16: =2662+111 | AB16: =2679+108 | AC16: 2794 | AD16: 2699 | AE16: 2754 | AG16: =SUM(R16:U16) | AH16: =SUM(V16:Y16)
C17: Total cost of revenues | D17: =D15+D16 | E17: =E15+E16 | F17: =F15+F16 | G17: =G15+G16 | H17: =H15+H16 | I17: =I15+I16 | J17: =J15+J16 | K17: =K15+K16 | ... Y17: =Y15+Y16 | AA17: =AA15+AA16 | AB17: =AB15+AB16 | AC17: =AC15+AC16 | AD17: =AD15+AD16 | AE17: =AE15+AE16 | AG17: =AG15+AG16 | AH17: =AH15+AH16
C18: Gross profit | D18: =D12-D17 | E18: =E12-E17 | F18: =F12-F17 | G18: =G12-G17 | H18: =H12-H17 | I18: =I12-I17 | J18: =J12-J17 | K18: =K12-K17 | ... Y18: =Y12-Y17 | AA18: =AA12-AA17 | AB18: =AB12-AB17 | AC18: =AC12-AC17 | AD18: =AD12-AD17 | AE18: =AE12-AE17 | AG18: =AG12-AG17 | AH18: =AH12-AH17
C19: Research, development and engineering expenses | D19: 74 | E19: 79 | F19: 82 | G19: =AA19-SUM(D19:F19) | H19: 78 | I19: 84 | J19: 73 | K19: =AB19-SUM(H19:J19) | L19: 64 | M19: 57 | N19: 52 | O19: =AC19-SUM(L19:N19) | P19: 49 | Q19: 50 | R19: 45 | S19: =AD19-SUM(P19:R19) | T19: 42 | U19: 43 | V19: 74 | W19: =AE19-SUM(T19:V19) | X19: 64 | Y19: 67 | AA19: 310 | AB19: 304 | AC19: 229 | AD19: 191 | AE19: 230 | AG19: =SUM(R19:U19) | AH19: =SUM(V19:Y19)
C20: Selling, administrative and general expenses | D20: 448 | E20: 434 | F20: 413 | G20: =AA20-SUM(D20:F20) | H20: 455 | I20: 459 | J20: 418 | K20: =AB20-SUM(H20:J20) | L20: 407 | M20: 433 | N20: 416 | O20: =AC20-SUM(L20:N20) | P20: 397 | Q20: 393 | R20: 370 | S20: =AD20-SUM(P20:R20) | T20: 378 | U20: 368 | V20: 477 | W20: =AE20-SUM(T20:V20) | X20: 430 | Y20: 432 | AA20: 1718 | AB20: 1760 | AC20: 1696 | AD20: 1537 | AE20: 1654 | AG20: =SUM(R20:U20) | AH20: =SUM(V20:Y20)
C21: Goodwill impairment | D21: 0 | E21: 0 | F21: 0 | G21: =AA21-SUM(D21:F21) | H21: 0 | I21: 0 | J21: 412 | K21: =AB21-SUM(H21:J21) | L21: 0 | M21: 0 | N21: 0 | O21: =AC21-SUM(L21:N21) | P21: 0 | Q21: 0 | R21: 1058 | S21: =AD21-SUM(P21:R21) | T21: 0 | U21: 0 | V21: 0 | W21: =AE21-SUM(T21:V21) | X21: 0 | Y21: 0 | AA21: 781 | AB21: 412 | AC21: 0 | AD21: 1058 | AE21: 0 | AG21: =SUM(R21:U21) | AH21: =SUM(V21:Y21)
C22: Restructuring and related costs, net | D22: 17 | E22: 12 | F22: 10 | G22: =AA22-SUM(D22:F22) | H22: 18 | I22: 1 | J22: 22 | K22: =AB22-SUM(H22:J22) | L22: 2 | M22: 23 | N22: 10 | O22: =AC22-SUM(L22:N22) | P22: 39 | Q22: 12 | R22: 56 | S22: =AD22-SUM(P22:R22) | T22: -1 | U22: 10 | V22: 59 | W22: =AE22-SUM(T22:V22) | X22: 45 | Y22: 23 | AA22: 38 | AB22: 65 | AC22: 167 | AD22: 112 | AE22: 66 | AG22: =SUM(R22:U22) | AH22: =SUM(V22:Y22)
C23: Amortization of intangible assets | D23: 15 | E23: 14 | F23: 13 | G23: =AA23-SUM(D23:F23) | H23: 11 | I23: 10 | J23: 10 | K23: =AB23-SUM(H23:J23) | L23: 11 | M23: 10 | N23: 12 | O23: =AC23-SUM(L23:N23) | P23: 10 | Q23: 10 | R23: 10 | S23: =AD23-SUM(P23:R23) | T23: 10 | U23: 10 | V23: 30 | W23: =AE23-SUM(T23:V23) | X23: 30 | Y23: 30 | AA23: 55 | AB23: 42 | AC23: 43 | AD23: 73 | AE23: 83 | AG23: =SUM(R23:U23) | AH23: =SUM(V23:Y23)
C24: Divestitures | D24: 0 | E24: 0 | F24: 0 | G24: =AA24-SUM(D24:F24) | H24: 0 | I24: 0 | J24: 0 | K24: =AB24-SUM(H24:J24) | L24: 0 | M24: 0 | N24: 0 | O24: =AC24-SUM(L24:N24) | P24: 54 | Q24: -3 | R24: 0 | S24: =AD24-SUM(P24:R24) | T24: -4 | U24: 0 | V24: 0 | W24: =AE24-SUM(T24:V24) | X24: 0 | Y24: 0 | AA24: 0 | AB24: 0 | AC24: 0 | AD24: 47 | AE24: -4 | AG24: =SUM(R24:U24) | AH24: =SUM(V24:Y24)
C25: PARC donation | D25: 0 | E25: 0 | F25: 0 | G25: =AA25-SUM(D25:F25) | H25: 0 | I25: 0 | J25: 0 | K25: =AB25-SUM(H25:J25) | L25: 0 | M25: 132 | N25: 0 | O25: =AC25-SUM(L25:N25) | P25: 0 | Q25: 0 | R25: 0 | S25: =AD25-SUM(P25:R25) | T25: 0 | U25: 0 | V25: 0 | W25: =AE25-SUM(T25:V25) | X25: 0 | Y25: 0 | AA25: 0 | AB25: 0 | AC25: 132 | AD25: 0 | AE25: 0 | AG25: =SUM(R25:U25) | AH25: =SUM(V25:Y25)
C26: Total operating expenses | D26: =SUM(D19:D25) | E26: =SUM(E19:E25) | F26: =SUM(F19:F25) | G26: =SUM(G19:G25) | H26: =SUM(H19:H25) | I26: =SUM(I19:I25) | J26: =SUM(J19:J25) | K26: =SUM(K19:K25) | ... Y26: =SUM(Y19:Y25) | AA26: =SUM(AA19:AA25) | AB26: =SUM(AB19:AB25) | AC26: =SUM(AC19:AC25) | AD26: =SUM(AD19:AD25) | AE26: =SUM(AE19:AE25) | AG26: =SUM(AG19:AG25) | AH26: =SUM(AH19:AH25)
C27: Operating (loss) income | D27: =D18-D26 | E27: =E18-E26 | F27: =F18-F26 | G27: =G18-G26 | H27: =H18-H26 | I27: =I18-I26 | J27: =J18-J26 | K27: =K18-K26 | ... Y27: =Y18-Y26 | AA27: =AA18-AA26 | AB27: =AB18-AB26 | AC27: =AC18-AC26 | AD27: =AD18-AD26 | AE27: =AE18-AE26 | AG27: =AG18-AG26 | AH27: =AH18-AH26
C28: Non-financing interest expense | D28: =52-28 | E28: =52-28 | F28: =52-29 | G28: =AA28-SUM(D28:F28) | H28: =53-24 | I28: =49-26 | J28: =49-28 | K28: =AB28-SUM(H28:J28) | L28: =50-36 | M28: =46-34 | N28: =44-30 | O28: =AC28-SUM(L28:N28) | P28: 26 | Q28: 31 | R28: 31 | S28: =AD28-SUM(P28:R28) | T28: 33 | U28: 55 | V28: 80 | W28: =AE28-SUM(T28:V28) | X28: 84 | Y28: 100 | AA28: =207-111 | AB28: =199-108 | AC28: =198-130 | AD28: 119 | AE28: 248 | AG28: =SUM(R28:U28) | AH28: =SUM(V28:Y28)
C29: Other expenses (income), net | D29: =4-0-24 | E29: =1-1-24 | F29: =-33-1-23 | G29: =AA29-SUM(D29:F29) | H29: =57-1-29 | I29: =8-1-23 | J29: =1-1-21 | K29: =AB29-SUM(H29:J29) | L29: =20-0-14 | M29: =31-1-12 | N29: =-17-1-14 | O29: =AC29-SUM(L29:N29) | P29: =44-26 | Q29: =33-31 | R29: =43-31 | S29: =AD29-SUM(P29:R29) | T29: 35 | U29: 25 | V29: =105-80 | W29: =AE29-SUM(T29:V29) | X29: -31 | Y29: 5 | AA29: =-27-(207-111) | AB29: =60-(199-108) | AC29: =75-(198-130) | AD29: =158-119 | AE29: =360-248 | AG29: =SUM(R29:U29) | AH29: =SUM(V29:Y29)
C30: Income (loss) before income taxes | D30: =D27-D28-D29 | E30: =E27-E28-E29 | F30: =F27-F28-F29 | G30: =G27-G28-G29 | H30: =H27-H28-H29 | I30: =I27-I28-I29 | J30: =J27-J28-J29 | K30: =K27-K28-K29 | ... Y30: =Y27-Y28-Y29 | AA30: =AA27-AA28-AA29 | AB30: =AB27-AB28-AB29 | AC30: =AC27-AC28-AC29 | AD30: =AD27-AD28-AD29 | AE30: =AE27-AE28-AE29 | AG30: =AG27-AG28-AG29 | AH30: =AH27-AH28-AH29
C31: Income tax expense (benefit) | D31: 14 | E31: 9 | F31: -4 | G31: =AA31-SUM(D31:F31) | H31: -31 | I31: 1 | J31: 3 | K31: =AB31-SUM(H31:J31) | L31: 14 | M31: -28 | N31: 15 | O31: =AC31-SUM(L31:N31) | P31: -37 | Q31: 7 | R31: 118 | S31: =AD31-SUM(P31:R31) | T31: 23 | U31: 46 | V31: 460 | W31: =AE31-SUM(T31:V31) | X31: 32 | Y31: 18 | AA31: -17 | AB31: -3 | AC31: -29 | AD31: 105 | AE31: 541 | AG31: =SUM(R31:U31) | AH31: =SUM(V31:Y31)
C32: Net Income (loss) | D32: =D30-D31 | E32: =E30-E31 | F32: =F30-F31 | G32: =G30-G31 | H32: =H30-H31 | I32: =I30-I31 | J32: =J30-J31 | K32: =K30-K31 | ... Y32: =Y30-Y31 | AA32: =AA30-AA31 | AB32: =AB30-AB31 | AC32: =AC30-AC31 | AD32: =AD30-AD31 | AE32: =AE30-AE31 | AG32: =AG30-AG31 | AH32: =AH30-AH31
C33: Less: net (income) loss attributable to noncontrolling interests | D33: 0 | E33: 0 | F33: 1 | G33: =AA33-SUM(D33:F33) | H33: 1 | I33: 1 | J33: -1 | K33: =AB33-SUM(H33:J33) | L33: 0 | M33: -1 | N33: 0 | O33: =AC33-SUM(L33:N33) | P33: 0 | Q33: 0 | R33: 0 | S33: =AD33-SUM(P33:R33) | T33: 0 | U33: 0 | V33: 0 | W33: =AE33-SUM(T33:V33) | X33: 0 | Y33: 0 | AA33: 0 | AB33: 0 | AC33: 0 | AD33: 0 | AE33: 0 | AG33: =SUM(R33:U33) | AH33: =SUM(V33:Y33)
B34: x | C34: Net (loss) income attributable to Xerox Holdings | D34: =D32+D33 | E34: =E32+E33 | F34: =F32+F33 | G34: =G32+G33 | H34: =H32+H33 | I34: =I32+I33 | J34: =J32+J33 | K34: =K32+K33 | ... Y34: =Y32+Y33 | AA34: =AA32+AA33 | AB34: =AB32+AB33 | AC34: =AC32+AC33 | AD34: =AD32+AD33 | AE34: =AE32+AE33 | AG34: =AG32+AG33 | AH34: =AH32+AH33
B38: x | C38: Adjusted EBITDA Build | D38: Quarter Ended | AA38: Fiscal Year Ended December 31, | AG38: LTM
C39: Net (loss) income | D39: =D32 | E39: =E32 | F39: =F32 | G39: =G32 | H39: =H32 | I39: =I32 | J39: =J32 | K39: =K32 | ... Y39: =Y32 | AA39: =AA32 | AB39: =AB32 | AC39: =AC32 | AD39: =AD32 | AE39: =AE32 | AG39: =SUM(R39:U39) | AH39: =SUM(V39:Y39)
C40: Non-financing interest expense | D40: =D28 | E40: =E28 | F40: =F28 | G40: =G28 | H40: =H28 | I40: =I28 | J40: =J28 | K40: =K28 | ... Y40: =Y28 | AA40: =AA28 | AB40: =AB28 | AC40: =AC28 | AD40: =AD28 | AE40: =AE28 | AG40: =SUM(R40:U40) | AH40: =SUM(V40:Y40)
C41: Other expenses (income), net | D41: =D29 | E41: =E29 | F41: =F29 | G41: =G29 | H41: =H29 | I41: =I29 | J41: =J29 | K41: =K29 | ... Y41: =Y29 | AA41: =AA29 | AB41: =AB29 | AC41: =AC29 | AD41: =AD29 | AE41: =AE29 | AG41: =SUM(R41:U41) | AH41: =SUM(V41:Y41)
C42: Income tax expense (benefit) | D42: =D31 | E42: =E31 | F42: =F31 | G42: =G31 | H42: =H31 | I42: =I31 | J42: =J31 | K42: =K31 | ... Y42: =Y31 | AA42: =AA31 | AB42: =AB31 | AC42: =AC31 | AD42: =AD31 | AE42: =AE31 | AG42: =SUM(R42:U42) | AH42: =SUM(V42:Y42)
C43: Depreciation and amortization (excl. customer contract costs) | D43: ='Cash Flow Statement'!E16 | E43: ='Cash Flow Statement'!F16 | F43: ='Cash Flow Statement'!G16 | G43: ='Cash Flow Statement'!H16 | H43: ='Cash Flow Statement'!I16 | I43: ='Cash Flow Statement'!J16 | J43: ='Cash Flow Statement'!K16 | K43: ='Cash Flow Statement'!L16 | ... Y43: ='Cash Flow Statement'!Z16 | AA43: ='Cash Flow Statement'!AB16 | AB43: ='Cash Flow Statement'!AC16 | AC43: ='Cash Flow Statement'!AD16 | AD43: ='Cash Flow Statement'!AE16 | AE43: ='Cash Flow Statement'!AF16 | AG43: =SUM(R43:U43) | AH43: =SUM(V43:Y43)
C44: Goodwill impairment | D44: =D21 | E44: =E21 | F44: =F21 | G44: =G21 | H44: =H21 | I44: =I21 | J44: =J21 | K44: =K21 | ... Y44: =Y21 | AA44: =AA21 | AB44: =AB21 | AC44: =AC21 | AD44: =AD21 | AE44: =AE21 | AG44: =SUM(R44:U44) | AH44: =SUM(V44:Y44)
C45: EBITDA | D45: =SUM(D39:D44) | E45: =SUM(E39:E44) | F45: =SUM(F39:F44) | G45: =SUM(G39:G44) | H45: =SUM(H39:H44) | I45: =SUM(I39:I44) | J45: =SUM(J39:J44) | K45: =SUM(K39:K44) | ... Y45: =SUM(Y39:Y44) | AA45: =SUM(AA39:AA44) | AB45: =SUM(AB39:AB44) | AC45: =SUM(AC39:AC44) | AD45: =SUM(AD39:AD44) | AE45: =SUM(AE39:AE44) | AG45: =SUM(AG39:AG44) | AH45: =SUM(AH39:AH44)
C46: Stock-based compensation | D46: ='Cash Flow Statement'!E25 | E46: ='Cash Flow Statement'!F25 | F46: ='Cash Flow Statement'!G25 | G46: ='Cash Flow Statement'!H25 | H46: ='Cash Flow Statement'!I25 | I46: ='Cash Flow Statement'!J25 | J46: ='Cash Flow Statement'!K25 | K46: ='Cash Flow Statement'!L25 | ... Y46: ='Cash Flow Statement'!Z25 | AA46: ='Cash Flow Statement'!AB25 | AB46: ='Cash Flow Statement'!AC25 | AC46: ='Cash Flow Statement'!AD25 | AD46: ='Cash Flow Statement'!AE25 | AE46: ='Cash Flow Statement'!AF25 | AG46: =SUM(R46:U46) | AH46: =SUM(V46:Y46)
C47: Restructuring and related costs, net | D47: =D22 | E47: =E22 | F47: =F22 | G47: =G22 | H47: =H22 | I47: =I22 | J47: =J22 | K47: =K22 | ... Y47: =Y22 | AA47: =AA22 | AB47: =AB22 | AC47: =AC22 | AD47: =AD22 | AE47: =AE22 | AG47: =SUM(R47:U47) | AH47: =SUM(V47:Y47)
...

Sheet Balance Sheet
A1: =C3 | B1: ='Cover Page'!A1
C3: Balance Sheet | AI3: Xerox Holdings Corporation
C4: All values in $ millions (USD)
E6: 1 | F6: 2 | G6: 3 | H6: 4 | I6: 1 | J6: 2 | K6: 3 | L6: 4 | M6: 1 | N6: 2 | O6: 3 | P6: 4 | Q6: 1 | R6: 2 | S6: 3 | T6: 4 | U6: 1 | V6: 2 | W6: 3 | X6: 4 | Y6: 1 | Z6: 2
E7: 2021 | F7: 2021 | G7: 2021 | H7: 2021 | I7: 2022 | J7: 2022 | K7: 2022 | L7: 2022 | M7: 2023 | N7: 2023 | O7: 2023 | P7: 2023 | Q7: 2024 | R7: 2024 | S7: 2024 | T7: 2024 | U7: 2025 | V7: 2025 | W7: 2025 | X7: 2025 | Y7: 2026 | Z7: 2026 | AB7: 2021 | AC7: 2022 | AD7: 2023 | AE7: 2024 | AF7: 2025
E8: 44286 | F8: 44377 | G8: 44469 | H8: 44561 | I8: 44651 | J8: 44742 | K8: 44834 | L8: 44926 | M8: 45016 | N8: 45107 | O8: 45199 | P8: 45291 | Q8: 45382 | R8: 45473 | S8: 45565 | T8: 45657 | U8: 45747 | V8: 45838 | W8: 45930 | X8: 46022 | Y8: 46112 | Z8: 46203 | AB8: 44561 | AC8: 44926 | AD8: 45291 | AE8: 45657 | AF8: 46022
A9: x | B9: x | C9: Balance Sheet | E9: Quarter Ended | AB9: Fiscal Year Ended December 31, | AH9: LTM
E10: =E6&"Q'"&RIGHT(E7,2) | F10: =F6&"Q'"&RIGHT(F7,2) | G10: =G6&"Q'"&RIGHT(G7,2) | H10: =H6&"Q'"&RIGHT(H7,2) | I10: =I6&"Q'"&RIGHT(I7,2) | J10: =J6&"Q'"&RIGHT(J7,2) | K10: =K6&"Q'"&RIGHT(K7,2) | L10: =L6&"Q'"&RIGHT(L7,2) | ... Z10: =Z6&"Q'"&RIGHT(Z7,2) | AB10: 2021 | AC10: 2022 | AD10: 2023 | AE10: 2024 | AF10: 2025 | AH10: $ Chg '25 | AI10: % Chg '25
C12: Assets:
C13: Cash and cash equivalents | E13: 2379 | F13: 2124 | G13: 2209 | H13: 1840 | I13: 1681 | J13: 1151 | K13: 932 | L13: 1045 | M13: 591 | N13: 477 | O13: 532 | P13: 519 | Q13: 685 | R13: 485 | S13: 521 | T13: 576 | U13: 336 | V13: 449 | W13: 479 | X13: 512 | Y13: 585 | Z13: 495 | AB13: =H13 | AC13: =L13 | AD13: =P13 | AE13: =T13 | AF13: =X13 | AH13: =AF13-AE13 | AI13: =IFERROR(AH13/ABS(AE13),0)
C14: Accounts receivable, net | E14: 781 | F14: 846 | G14: 891 | H14: 818 | I14: 807 | J14: 852 | K14: 835 | L14: 857 | M14: 818 | N14: 903 | O14: 880 | P14: 850 | Q14: 846 | R14: 847 | S14: 821 | T14: 796 | U14: 819 | V14: 862 | W14: 1196 | X14: 1122 | Y14: 1218 | Z14: 1185 | AB14: =H14 | AC14: =L14 | AD14: =P14 | AE14: =T14 | AF14: =X14 | AH14: =AF14-AE14 | AI14: =IFERROR(AH14/ABS(AE14),0)
C15: Billed portion of finance receivables, net | E15: 92 | F15: 89 | G15: 100 | H15: 94 | I15: 89 | J15: 83 | K15: 91 | L15: 93 | M15: 94 | N15: 70 | O15: 80 | P15: 71 | Q15: 67 | R15: 70 | S15: 50 | T15: 48 | U15: 43 | V15: 46 | W15: 53 | X15: 46 | Y15: 43 | Z15: 40 | AB15: =H15 | AC15: =L15 | AD15: =P15 | AE15: =T15 | AF15: =X15 | AH15: =AF15-AE15 | AI15: =IFERROR(AH15/ABS(AE15),0)
C16: Finance receivables, net | E16: 1065 | F16: 1057 | G16: 1039 | H16: 1042 | I16: 1023 | J16: 1019 | K16: 995 | L16: 1061 | M16: 1022 | N16: 940 | O16: 906 | P16: 842 | Q16: 783 | R16: 713 | S16: 664 | T16: 608 | U16: 583 | V16: 584 | W16: 553 | X16: 510 | Y16: 476 | Z16: 442 | AB16: =H16 | AC16: =L16 | AD16: =P16 | AE16: =T16 | AF16: =X16 | AH16: =AF16-AE16 | AI16: =IFERROR(AH16/ABS(AE16),0)
C17: Inventories | E17: 841 | F17: 815 | G17: 788 | H17: 696 | I17: 732 | J17: 765 | K17: 777 | L17: 797 | M17: 863 | N17: 782 | O17: 728 | P17: 661 | Q17: 736 | R17: 737 | S17: 732 | T17: 695 | U17: 836 | V17: 871 | W17: 1143 | X17: 1016 | Y17: 1043 | Z17: 1043 | AB17: =H17 | AC17: =L17 | AD17: =P17 | AE17: =T17 | AF17: =X17 | AH17: =AF17-AE17 | AI17: =IFERROR(AH17/ABS(AE17),0)
C18: Other current assets | E18: 262 | F18: 244 | G18: 209 | H18: 211 | I18: 234 | J18: 232 | K18: 265 | L18: 254 | M18: 252 | N18: 218 | O18: 228 | P18: 234 | Q18: 231 | R18: 199 | S18: 223 | T18: 212 | U18: 250 | V18: 731 | W18: 329 | X18: 362 | Y18: 415 | Z18: 492 | AB18: =H18 | AC18: =L18 | AD18: =P18 | AE18: =T18 | AF18: =X18 | AH18: =AF18-AE18 | AI18: =IFERROR(AH18/ABS(AE18),0)
C19: Total current assets | E19: =SUM(E13:E18) | F19: =SUM(F13:F18) | G19: =SUM(G13:G18) | H19: =SUM(H13:H18) | I19: =SUM(I13:I18) | J19: =SUM(J13:J18) | K19: =SUM(K13:K18) | L19: =SUM(L13:L18) | ... Z19: =SUM(Z13:Z18) | AB19: =SUM(AB13:AB18) | AC19: =SUM(AC13:AC18) | AD19: =SUM(AD13:AD18) | AE19: =SUM(AE13:AE18) | AF19: =SUM(AF13:AF18) | AH19: =AF19-AE19 | AI19: =IFERROR(AH19/ABS(AE19),0)
C20: Total current assets | E20: 5420 | F20: 5175 | G20: 5236 | H20: 4701 | I20: 4566 | J20: 4102 | K20: 3895 | L20: 4107 | M20: 3640 | N20: 3390 | O20: 3354 | P20: 3177 | Q20: 3348 | R20: 3051 | S20: 3011 | T20: 2935 | U20: 2867 | V20: 3543 | W20: 3753 | X20: 3568 | Y20: 3780 | Z20: 3697 | AB20: =H20 | AC20: =L20 | AD20: =P20 | AE20: =T20 | AF20: =X20
C21: Check | E21: =E19-E20 | F21: =F19-F20 | G21: =G19-G20 | H21: =H19-H20 | I21: =I19-I20 | J21: =J19-J20 | K21: =K19-K20 | L21: =L19-L20 | ... Z21: =Z19-Z20 | AB21: =AB19-AB20 | AC21: =AC19-AC20 | AD21: =AD19-AD20 | AE21: =AE19-AE20 | AF21: =AF19-AF20
C22: Finance receivables due after one year, net | E22: 1920 | F22: 1971 | G22: 1936 | H22: 1934 | I22: 1893 | J22: 1845 | K22: 1814 | L22: 1948 | M22: 1864 | N22: 1697 | O22: 1605 | P22: 1597 | Q22: 1408 | R22: 1277 | S22: 1275 | T22: 1089 | U22: 1013 | V22: 990 | W22: 950 | X22: 846 | Y22: 797 | Z22: 732 | AB22: =H22 | AC22: =L22 | AD22: =P22 | AE22: =T22 | AF22: =X22 | AH22: =AF22-AE22 | AI22: =IFERROR(AH22/ABS(AE22),0)
C23: Equipment on operating leases, net | E23: 277 | F23: 271 | G23: 254 | H23: 253 | I23: 254 | J23: 226 | K23: 216 | L23: 235 | M23: 250 | N23: 259 | O23: 257 | P23: 265 | Q23: 257 | R23: 253 | S23: 255 | T23: 245 | U23: 248 | V23: 249 | W23: 300 | X23: 299 | Y23: 292 | Z23: 283 | AB23: =H23 | AC23: =L23 | AD23: =P23 | AE23: =T23 | AF23: =X23 | AH23: =AF23-AE23 | AI23: =IFERROR(AH23/ABS(AE23),0)
C24: Land, buildings and equipment, net | E24: 393 | F24: 372 | G24: 370 | H24: 358 | I24: 350 | J24: 334 | K24: 315 | L24: 320 | M24: 311 | N24: 281 | O24: 273 | P24: 266 | Q24: 245 | R24: 227 | S24: 225 | T24: 251 | U24: 195 | V24: 187 | W24: 427 | X24: 390 | Y24: 378 | Z24: 378 | AB24: =H24 | AC24: =L24 | AD24: =P24 | AE24: =T24 | AF24: =X24 | AH24: =AF24-AE24 | AI24: =IFERROR(AH24/ABS(AE24),0)
C25: Intangible assets, net | E25: 223 | F25: 230 | G25: 216 | H25: 211 | I25: 240 | J25: 223 | K25: 216 | L25: 208 | M25: 202 | N25: 194 | O25: 183 | P25: 177 | Q25: 165 | R25: 155 | S25: 149 | T25: 236 | U25: 228 | V25: 222 | W25: 954 | X25: 921 | Y25: 891 | Z25: 857 | AB25: =H25 | AC25: =L25 | AD25: =P25 | AE25: =T25 | AF25: =X25 | AH25: =AF25-AE25 | AI25: =IFERROR(AH25/ABS(AE25),0)
C26: Goodwill, net | E26: 4075 | F26: 4104 | G26: 4066 | H26: 3287 | I26: 3300 | J26: 3217 | K26: 2753 | L26: 2820 | M26: 2850 | N26: 2751 | O26: 2716 | P26: 2747 | Q26: 2720 | R26: 2719 | S26: 1709 | T26: 1937 | U26: 1954 | V26: 1984 | W26: 2182 | X26: 2222 | Y26: 2201 | Z26: 2234 | AB26: =H26 | AC26: =L26 | AD26: =P26 | AE26: =T26 | AF26: =X26 | AH26: =AF26-AE26 | AI26: =IFERROR(AH26/ABS(AE26),0)
C27: Deferred tax assets | E27: 510 | F27: 491 | G27: 511 | H27: 519 | I27: 528 | J27: 539 | K27: 496 | L27: 582 | M27: 598 | N27: 620 | O27: 701 | P27: 745 | Q27: 749 | R27: 760 | S27: 635 | T27: 615 | U27: 607 | V27: 551 | W27: 101 | X27: 98 | Y27: 96 | Z27: 86 | AB27: =H27 | AC27: =L27 | AD27: =P27 | AE27: =T27 | AF27: =X27 | AH27: =AF27-AE27 | AI27: =IFERROR(AH27/ABS(AE27),0)
C28: Other long-term assets | E28: 1454 | F28: 1496 | G28: 1492 | H28: 1960 | I28: 1951 | J28: 1784 | K28: 1715 | L28: 1323 | M28: 1331 | N28: 1377 | O28: 1355 | P28: 1034 | Q28: 1052 | R28: 1049 | S28: 1063 | T28: 1057 | U28: 1099 | V28: 1148 | W28: 1401 | X28: 1479 | Y28: 1467 | Z28: 1457 | AB28: =H28 | AC28: =L28 | AD28: =P28 | AE28: =T28 | AF28: =X28 | AH28: =AF28-AE28 | AI28: =IFERROR(AH28/ABS(AE28),0)
C29: Total assets | E29: =SUM(E22:E28)+E19 | F29: =SUM(F22:F28)+F19 | G29: =SUM(G22:G28)+G19 | H29: =SUM(H22:H28)+H19 | I29: =SUM(I22:I28)+I19 | J29: =SUM(J22:J28)+J19 | K29: =SUM(K22:K28)+K19 | L29: =SUM(L22:L28)+L19 | ... Z29: =SUM(Z22:Z28)+Z19 | AB29: =SUM(AB22:AB28)+AB19 | AC29: =SUM(AC22:AC28)+AC19 | AD29: =SUM(AD22:AD28)+AD19 | AE29: =SUM(AE22:AE28)+AE19 | AF29: =SUM(AF22:AF28)+AF19 | AH29: =AF29-AE29 | AI29: =IFERROR(AH29/ABS(AE29),0)
C30: Total assets | E30: 14272 | F30: 14110 | G30: 14081 | H30: 13223 | I30: 13082 | J30: 12270 | K30: 11420 | L30: 11543 | M30: 11046 | N30: 10569 | O30: 10444 | P30: 10008 | Q30: 9944 | R30: 9491 | S30: 8322 | T30: 8365 | U30: 8211 | V30: 8874 | W30: 10068 | X30: 9823 | Y30: 9902 | Z30: 9724 | AB30: =H30 | AC30: =L30 | AD30: =P30 | AE30: =T30 | AF30: =X30
C31: Check | E31: =E29-E30 | F31: =F29-F30 | G31: =G29-G30 | H31: =H29-H30 | I31: =I29-I30 | J31: =J29-J30 | K31: =K29-K30 | L31: =L29-L30 | ... Z31: =Z29-Z30 | AB31: =AB29-AB30 | AC31: =AC29-AC30 | AD31: =AD29-AD30 | AE31: =AE29-AE30 | AF31: =AF29-AF30
C33: Liabilities and Equity:
C34: Current liabilities:
C35: Short-term debt and current portion of long-term debt | E35: 678 | F35: 642 | G35: 646 | H35: 650 | I35: 1450 | J35: 1108 | K35: 1070 | L35: 860 | M35: 553 | N35: 891 | O35: 870 | P35: 567 | Q35: 405 | R35: 129 | S35: 519 | T35: 585 | U35: 599 | V35: 458 | W35: 354 | X35: 231 | Y35: 165 | Z35: 70 | AB35: =H35 | AC35: =L35 | AD35: =P35 | AE35: =T35 | AF35: =X35 | AH35: =AF35-AE35 | AI35: =IFERROR(AH35/ABS(AE35),0)
C36: Financing liability, tariff receivables monetization | E36: 0 | F36: 0 | G36: 0 | H36: 0 | I36: 0 | J36: 0 | K36: 0 | L36: 0 | M36: 0 | N36: 0 | O36: 0 | P36: 0 | Q36: 0 | R36: 0 | S36: 0 | T36: 0 | U36: 0 | V36: 0 | W36: 0 | X36: 0 | Y36: 0 | Z36: 90 | AB36: =H36 | AC36: =L36 | AD36: =P36 | AE36: =T36 | AF36: =X36 | AH36: =AF36-AE36 | AI36: =IFERROR(AH36/ABS(AE36),0)
C37: Accounts payable | E37: 932 | F37: 935 | G37: 1032 | H37: 1069 | I37: 1183 | J37: 1207 | K37: 1213 | L37: 1331 | M37: 1301 | N37: 1041 | O37: 1031 | P37: 1044 | Q37: 1046 | R37: 936 | S37: 895 | T37: 1023 | U37: 1120 | V37: 1080 | W37: 1481 | X37: 1498 | Y37: 1548 | Z37: 1456 | AB37: =H37 | AC37: =L37 | AD37: =P37 | AE37: =T37 | AF37: =X37 | AH37: =AF37-AE37 | AI37: =IFERROR(AH37/ABS(AE37),0)
C38: Accrued compensation and benefits costs | E38: 241 | F38: 263 | G38: 262 | H38: 239 | I38: 258 | J38: 233 | K38: 250 | L38: 258 | M38: 243 | N38: 251 | O38: 276 | P38: 306 | Q38: 213 | R38: 205 | S38: 227 | T38: 227 | U38: 199 | V38: 182 | W38: 247 | X38: 235 | Y38: 223 | Z38: 246 | AB38: =H38 | AC38: =L38 | AD38: =P38 | AE38: =T38 | AF38: =X38 | AH38: =AF38-AE38 | AI38: =IFERROR(AH38/ABS(AE38),0)
C39: Accrued expenses and other current liabilities | E39: 794 | F39: 851 | G39: 844 | H39: 871 | I39: 878 | J39: 867 | K39: 810 | L39: 881 | M39: 782 | N39: 766 | O39: 829 | P39: 862 | Q39: 774 | R39: 776 | S39: 752 | T39: 784 | U39: 721 | V39: 706 | W39: 1317 | X39: 1258 | Y39: 1266 | Z39: 1264 | AB39: =H39 | AC39: =L39 | AD39: =P39 | AE39: =T39 | AF39: =X39 | AH39: =AF39-AE39 | AI39: =IFERROR(AH39/ABS(AE39),0)
C40: Total current liabilities | E40: =SUM(E35:E39) | F40: =SUM(F35:F39) | G40: =SUM(G35:G39) | H40: =SUM(H35:H39) | I40: =SUM(I35:I39) | J40: =SUM(J35:J39) | K40: =SUM(K35:K39) | L40: =SUM(L35:L39) | ... Z40: =SUM(Z35:Z39) | AB40: =SUM(AB35:AB39) | AC40: =SUM(AC35:AC39) | AD40: =SUM(AD35:AD39) | AE40: =SUM(AE35:AE39) | AF40: =SUM(AF35:AF39) | AH40: =AF40-AE40 | AI40: =IFERROR(AH40/ABS(AE40),0)
C41: Total current liabilities | E41: 2645 | F41: 2691 | G41: 2784 | H41: 2829 | I41: 3769 | J41: 3415 | K41: 3343 | L41: 3330 | M41: 2879 | N41: 2949 | O41: 3006 | P41: 2779 | Q41: 2438 | R41: 2046 | S41: 2393 | T41: 2619 | U41: 2639 | V41: 2426 | W41: 3399 | X41: 3222 | Y41: 3202 | Z41: 3126 | AB41: =H41 | AC41: =L41 | AD41: =P41 | AE41: =T41 | AF41: =X41
C42: Check | E42: =E40-E41 | F42: =F40-F41 | G42: =G40-G41 | H42: =H40-H41 | I42: =I40-I41 | J42: =J40-J41 | K42: =K40-K41 | L42: =L40-L41 | ... Z42: =Z40-Z41 | AB42: =AB40-AB41 | AC42: =AC40-AC41 | AD42: =AD40-AD41 | AE42: =AE40-AE41 | AF42: =AF40-AF41
C43: Long-term debt | E43: 3674 | F43: 3597 | G43: 3673 | H43: 3596 | I43: 2821 | J43: 2764 | K43: 2676 | L43: 2866 | M43: 2726 | N43: 2225 | O43: 2739 | P43: 2710 | Q43: 3199 | R43: 3174 | S43: 2752 | T43: 2814 | U43: 2699 | V43: 3484 | W43: 4052 | X43: 4016 | Y43: 4281 | Z43: 4153 | AB43: =H43 | AC43: =L43 | AD43: =P43 | AE43: =T43 | AF43: =X43 | AH43: =AF43-AE43 | AI43: =IFERROR(AH43/ABS(AE43),0)
C44: Pension and other benefit liabilities | E44: 1473 | F44: 1436 | G44: 1381 | H44: 1373 | I44: 1359 | J44: 1310 | K44: 1298 | L44: 1175 | M44: 1168 | N44: 1206 | O44: 1131 | P44: 1216 | Q44: 1183 | R44: 1180 | S44: 1126 | T44: 1088 | U44: 1077 | V44: 1083 | W44: 1150 | X44: 1068 | Y44: 1037 | Z44: 1027 | AB44: =H44 | AC44: =L44 | AD44: =P44 | AE44: =T44 | AF44: =X44 | AH44: =AF44-AE44 | AI44: =IFERROR(AH44/ABS(AE44),0)
...

Sheet Cash Flow Statement
A1: =C3 | B1: ='Cover Page'!A1
C3: Statement of Cash Flows | AI3: Xerox Holdings Corporation
C4: All values in $ millions (USD)
E7: 1 | F7: 2 | G7: 3 | H7: 4 | I7: 1 | J7: 2 | K7: 3 | L7: 4 | M7: 1 | N7: 2 | O7: 3 | P7: 4 | Q7: 1 | R7: 2 | S7: 3 | T7: 4 | U7: 1 | V7: 2 | W7: 3 | X7: 4 | Y7: 1 | Z7: 2
E8: 2021 | F8: 2021 | G8: 2021 | H8: 2021 | I8: 2022 | J8: 2022 | K8: 2022 | L8: 2022 | M8: 2023 | N8: 2023 | O8: 2023 | P8: 2023 | Q8: 2024 | R8: 2024 | S8: 2024 | T8: 2024 | U8: 2025 | V8: 2025 | W8: 2025 | X8: 2025 | Y8: 2026 | Z8: 2026 | AB8: 2021 | AC8: 2022 | AD8: 2023 | AE8: 2024 | AF8: 2025
E9: 44286 | F9: 44377 | G9: 44469 | H9: 44561 | I9: 44651 | J9: 44742 | K9: 44834 | L9: 44926 | M9: 45016 | N9: 45107 | O9: 45199 | P9: 45291 | Q9: 45382 | R9: 45473 | S9: 45565 | T9: 45657 | U9: 45747 | V9: 45838 | W9: 45930 | X9: 46022 | Y9: 46112 | Z9: 46203 | AB9: 44561 | AC9: 44926 | AD9: 45291 | AE9: 45657 | AF9: 46022
A10: x | B10: x | C10: Cash Flow Statement | E10: Quarter Ended | AB10: Fiscal Year Ended December 31, | AH10: LTM
E11: =E7&"Q'"&RIGHT(E8,2) | F11: =F7&"Q'"&RIGHT(F8,2) | G11: =G7&"Q'"&RIGHT(G8,2) | H11: =H7&"Q'"&RIGHT(H8,2) | I11: =I7&"Q'"&RIGHT(I8,2) | J11: =J7&"Q'"&RIGHT(J8,2) | K11: =K7&"Q'"&RIGHT(K8,2) | L11: =L7&"Q'"&RIGHT(L8,2) | ... Z11: =Z7&"Q'"&RIGHT(Z8,2) | AB11: 2021 | AC11: 2022 | AD11: 2023 | AE11: 2024 | AF11: 2025 | AH11: LTM 2Q'25 | AI11: LTM 2Q'26
C13: Operating Activities:
C14: Net (loss) income | E14: ='Income Statement'!D32 | F14: ='Income Statement'!E32 | G14: ='Income Statement'!F32 | H14: ='Income Statement'!G32 | I14: ='Income Statement'!H32 | J14: ='Income Statement'!I32 | K14: ='Income Statement'!J32 | L14: ='Income Statement'!K32 | ... Z14: ='Income Statement'!Y32 | AB14: ='Income Statement'!AA32 | AC14: ='Income Statement'!AB32 | AD14: ='Income Statement'!AC32 | AE14: ='Income Statement'!AD32 | AF14: ='Income Statement'!AE32 | AH14: =SUM(S14:V14) | AI14: =SUM(W14:Z14)
C15: Adjustments required to reconcile net (loss) income to cash flows from operating activities:
C16: Depreciation and amortization | E16: 86 | F16: =170-E16 | G16: =249-SUM(E16:F16) | H16: =AB16-SUM(E16:G16) | I16: 72 | J16: =140-I16 | K16: =205-SUM(I16:J16) | L16: =AC16-SUM(I16:K16) | M16: 64 | N16: =126-M16 | O16: =189-SUM(M16:N16) | P16: =AD16-SUM(M16:O16) | Q16: 59 | R16: =118-Q16 | S16: =177-SUM(Q16:R16) | T16: =AE16-SUM(Q16:S16) | U16: 60 | V16: =117-U16 | W16: =224-SUM(U16:V16) | X16: =AF16-SUM(U16:W16) | Y16: 100 | Z16: =201-Y16 | AB16: 327 | AC16: 270 | AD16: 251 | AE16: 274 | AF16: 331 | AH16: =SUM(S16:V16) | AI16: =SUM(W16:Z16)
C17: Provisions | E17: 20 | F17: =34-E17 | G17: =38-SUM(E17:F17) | H17: =AB17-SUM(E17:G17) | I17: 19 | J17: =35-I17 | K17: =48-SUM(I17:J17) | L17: =AC17-SUM(I17:K17) | M17: 0 | N17: =21-M17 | O17: =37-SUM(M17:N17) | P17: =AD17-SUM(M17:O17) | Q17: 57 | R17: =79-Q17 | S17: =92-SUM(Q17:R17) | T17: =AE17-SUM(Q17:S17) | U17: 18 | V17: =48-U17 | W17: =67-SUM(U17:V17) | X17: =AF17-SUM(U17:W17) | Y17: 18 | Z17: =36-Y17 | AB17: 46 | AC17: 65 | AD17: 54 | AE17: 110 | AF17: 85 | AH17: =SUM(S17:V17) | AI17: =SUM(W17:Z17)
C18: Net (gain) loss on early extinguishment of debt | Y18: -56 | Z18: =-95-Y18 | AH18: =SUM(S18:V18) | AI18: =SUM(W18:Z18)
C19: Net (gain) loss on sales of businesses and assets | E19: 0 | F19: =-1-E19 | G19: =-40-SUM(E19:F19) | H19: =AB19-SUM(E19:G19) | I19: 0 | J19: =-1-I19 | K19: =-17-SUM(I19:J19) | L19: =AC19-SUM(I19:K19) | M19: 0 | N19: =-2-M19 | O19: =-37-SUM(M19:N19) | P19: =AD19-SUM(M19:O19) | Q19: 0 | R19: =-1-Q19 | S19: =-3-SUM(Q19:R19) | T19: =AE19-SUM(Q19:S19) | U19: -3 | V19: =-5-U19 | W19: =-6-SUM(U19:V19) | X19: =AF19-SUM(U19:W19) | Y19: 2 | Z19: =2-Y19 | AB19: -40 | AC19: -56 | AD19: -39 | AE19: -8 | AF19: -5 | AH19: =SUM(S19:V19) | AI19: =SUM(W19:Z19)
C20: Inventory-related purchase accounting adjustment, noncash (Lexmark) | U20: 0 | V20: =0-U20 | W20: =102-SUM(U20:V20) | X20: =AF20-SUM(U20:W20) | AF20: 102 | AH20: =SUM(S20:V20) | AI20: =SUM(W20:Z20)
C21: Effective settlement of pre-existing relationship between Lexmark and Xerox | U21: 0 | V21: =0-U21 | W21: =-43-SUM(U21:V21) | X21: =AF21-SUM(U21:W21) | AF21: -43 | AH21: =SUM(S21:V21) | AI21: =SUM(W21:Z21)
C22: Divestitures | E22: ='Income Statement'!D24 | F22: ='Income Statement'!E24 | G22: ='Income Statement'!F24 | H22: ='Income Statement'!G24 | I22: ='Income Statement'!H24 | J22: ='Income Statement'!I24 | K22: ='Income Statement'!J24 | L22: ='Income Statement'!K24 | ... Z22: ='Income Statement'!Y24 | AB22: ='Income Statement'!AA24 | AC22: ='Income Statement'!AB24 | AD22: ='Income Statement'!AC24 | AE22: ='Income Statement'!AD24 | AF22: ='Income Statement'!AE24 | AH22: =SUM(S22:V22) | AI22: =SUM(W22:Z22)
C23: PARC donation | E23: ='Income Statement'!D25 | F23: ='Income Statement'!E25 | G23: ='Income Statement'!F25 | H23: ='Income Statement'!G25 | I23: ='Income Statement'!H25 | J23: ='Income Statement'!I25 | K23: ='Income Statement'!J25 | L23: ='Income Statement'!K25 | ... Z23: ='Income Statement'!Y25 | AB23: ='Income Statement'!AA25 | AC23: ='Income Statement'!AB25 | AD23: ='Income Statement'!AC25 | AE23: ='Income Statement'!AD25 | AF23: ='Income Statement'!AE25 | AH23: =SUM(S23:V23) | AI23: =SUM(W23:Z23)
C24: Goodwill impairment | E24: ='Income Statement'!D21 | F24: ='Income Statement'!E21 | G24: ='Income Statement'!F21 | H24: ='Income Statement'!G21 | I24: ='Income Statement'!H21 | J24: ='Income Statement'!I21 | K24: ='Income Statement'!J21 | L24: ='Income Statement'!K21 | ... Z24: ='Income Statement'!Y21 | AB24: ='Income Statement'!AA21 | AC24: ='Income Statement'!AB21 | AD24: ='Income Statement'!AC21 | AE24: ='Income Statement'!AD21 | AF24: ='Income Statement'!AE21 | AH24: =SUM(S24:V24) | AI24: =SUM(W24:Z24)
C25: Stock-based compensation | E25: 16 | F25: =30-E25 | G25: =44-SUM(E25:F25) | H25: =AB25-SUM(E25:G25) | I25: 15 | J25: =50-I25 | K25: =63-SUM(I25:J25) | L25: =AC25-SUM(I25:K25) | M25: 14 | N25: =28-M25 | O25: =40-SUM(M25:N25) | P25: =AD25-SUM(M25:O25) | Q25: 12 | R25: =29-Q25 | S25: =38-SUM(Q25:R25) | T25: =AE25-SUM(Q25:S25) | U25: 12 | V25: =26-U25 | W25: =33-SUM(U25:V25) | X25: =AF25-SUM(U25:W25) | Y25: 9 | Z25: =18-Y25 | AB25: 54 | AC25: 75 | AD25: 54 | AE25: 52 | AF25: 45 | AH25: =SUM(S25:V25) | AI25: =SUM(W25:Z25)
C26: Restructuring and asset impairment charges | E26: 21 | F26: =25-E26 | G26: =28-SUM(E26:F26) | H26: =AB26-SUM(E26:G26) | I26: 20 | J26: =22-I26 | K26: =44-SUM(I26:J26) | L26: =AC26-SUM(I26:K26) | M26: 1 | N26: =14-M26 | O26: =25-SUM(M26:N26) | P26: =AD26-SUM(M26:O26) | Q26: 31 | R26: =34-Q26 | S26: =80-SUM(Q26:R26) | T26: =AE26-SUM(Q26:S26) | U26: -1 | V26: =10-U26 | W26: =69-SUM(U26:V26) | X26: =AF26-SUM(U26:W26) | Y26: 44 | Z26: =65-Y26 | AB26: 27 | AC26: 62 | AD26: 146 | AE26: 87 | AF26: 67 | AH26: =SUM(S26:V26) | AI26: =SUM(W26:Z26)
C27: Payments for restructurings | E27: -27 | F27: =-49-E27 | G27: =-61-SUM(E27:F27) | H27: =AB27-SUM(E27:G27) | I27: -7 | J27: =-21-I27 | K27: =-38-SUM(I27:J27) | L27: =AC27-SUM(I27:K27) | M27: -6 | N27: =-14-M27 | O27: =-23-SUM(M27:N27) | P27: =AD27-SUM(M27:O27) | Q27: -16 | R27: =-47-Q27 | S27: =-58-SUM(Q27:R27) | T27: =AE27-SUM(Q27:S27) | U27: -18 | V27: =-33-U27 | W27: =-41-SUM(U27:V27) | X27: =AF27-SUM(U27:W27) | Y27: -21 | Z27: =-40-Y27 | AB27: -72 | AC27: -52 | AD27: -27 | AE27: -78 | AF27: -69 | AH27: =SUM(S27:V27) | AI27: =SUM(W27:Z27)
C28: Non-service retirement-related costs | E28: 0 | F28: =-2-E28 | G28: =-5-SUM(E28:F28) | H28: =AB28-SUM(E28:G28) | I28: -7 | J28: =-11-I28 | K28: =-18-SUM(I28:J28) | L28: =AC28-SUM(I28:K28) | M28: -1 | N28: =10-M28 | O28: =14-SUM(M28:N28) | P28: =AD28-SUM(M28:O28) | Q28: 23 | R28: =49-Q28 | S28: =74-SUM(Q28:R28) | T28: =AE28-SUM(Q28:S28) | U28: 18 | V28: =37-U28 | W28: =57-SUM(U28:V28) | X28: =AF28-SUM(U28:W28) | Y28: 21 | Z28: =42-Y28 | AB28: -10 | AC28: -12 | AD28: 19 | AE28: 80 | AF28: 78 | AH28: =SUM(S28:V28) | AI28: =SUM(W28:Z28)
C29: Contributions to retirement plans | E29: -35 | F29: =-69-E29 | G29: =-102-SUM(E29:F29) | H29: =AB29-SUM(E29:G29) | I29: -38 | J29: =-72-I29 | K29: =-106-SUM(I29:J29) | L29: =AC29-SUM(I29:K29) | M29: -17 | N29: =-32-M29 | O29: =-75-SUM(M29:N29) | P29: =AD29-SUM(M29:O29) | Q29: -31 | R29: =-58-Q29 | S29: =-114-SUM(Q29:R29) | T29: =AE29-SUM(Q29:S29) | U29: -34 | V29: =-67-U29 | W29: =-123-SUM(U29:V29) | X29: =AF29-SUM(U29:W29) | Y29: -36 | Z29: =-72-Y29 | AB29: -135 | AC29: -124 | AD29: -102 | AE29: -145 | AF29: -161 | AH29: =SUM(S29:V29) | AI29: =SUM(W29:Z29)
C30: Changes in operating assets and liabilities:
C31: (Increase) decrease in accounts receivable and billed portion of finance receivables | E31: 92 | F31: =37-E31 | G31: =-30-SUM(E31:F31) | H31: =AB31-SUM(E31:G31) | I31: 13 | J31: =-49-I31 | K31: =-48-SUM(I31:J31) | L31: =AC31-SUM(I31:K31) | M31: 39 | N31: =-36-M31 | O31: =-47-SUM(M31:N31) | P31: =AD31-SUM(M31:O31) | Q31: -19 | R31: =-32-Q31 | S31: =18-SUM(Q31:R31) | T31: =AE31-SUM(Q31:S31) | U31: -12 | V31: =-44-U31 | W31: =-41-SUM(U31:V31) | X31: =AF31-SUM(U31:W31) | Y31: -106 | Z31: =-86-Y31 | AB31: 41 | AC31: -48 | AD31: -5 | AE31: 71 | AF31: -36 | AH31: =SUM(S31:V31) | AI31: =SUM(W31:Z31)
C32: (Increase) decrease in inventories | E32: -18 | F32: =4-E32 | G32: =10-SUM(E32:F32) | H32: =AB32-SUM(E32:G32) | I32: -31 | J32: =-95-I32 | K32: =-136-SUM(I32:J32) | L32: =AC32-SUM(I32:K32) | M32: -64 | N32: =12-M32 | O32: =50-SUM(M32:N32) | P32: =AD32-SUM(M32:O32) | Q32: -133 | R32: =-148-Q32 | S32: =-136-SUM(Q32:R32) | T32: =AE32-SUM(Q32:S32) | U32: -137 | V32: =-160-U32 | W32: =-123-SUM(U32:V32) | X32: =AF32-SUM(U32:W32) | Y32: -49 | Z32: =-60-Y32 | AB32: 88 | AC32: -143 | AD32: 123 | AE32: -122 | AF32: -12 | AH32: =SUM(S32:V32) | AI32: =SUM(W32:Z32)
C33: Increase in equipment on operating leases | E33: -28 | F33: =-63-E33 | G33: =-92-SUM(E33:F33) | H33: =AB33-SUM(E33:G33) | I33: -36 | J33: =-47-I33 | K33: =-74-SUM(I33:J33) | L33: =AC33-SUM(I33:K33) | M33: -40 | N33: =-77-M33 | O33: =-109-SUM(M33:N33) | P33: =AD33-SUM(M33:O33) | Q33: -22 | R33: =-50-Q33 | S33: =-78-SUM(Q33:R33) | T33: =AE33-SUM(Q33:S33) | U33: -30 | V33: =-52-U33 | W33: =-88-SUM(U33:V33) | X33: =AF33-SUM(U33:W33) | Y33: -32 | Z33: =-67-Y33 | AB33: -129 | AC33: -112 | AD33: -141 | AE33: -107 | AF33: -126 | AH33: =SUM(S33:V33) | AI33: =SUM(W33:Z33)
C34: Decrease (increase) in finance receivables | E34: 37 | F34: =12-E34 | G34: =33-SUM(E34:F34) | H34: =AB34-SUM(E34:G34) | I34: 41 | J34: =17-I34 | K34: =-10-SUM(I34:J34) | L34: =AC34-SUM(I34:K34) | M34: 160 | N34: =407-M34 | O34: =490-SUM(M34:N34) | P34: =AD34-SUM(M34:O34) | Q34: 210 | R34: =399-Q34 | S34: =496-SUM(Q34:R34) | T34: =AE34-SUM(Q34:S34) | U34: 128 | V34: =212-U34 | W34: =338-SUM(U34:V34) | X34: =AF34-SUM(U34:W34) | Y34: 66 | Z34: =157-Y34 | AB34: 20 | AC34: -141 | AD34: 614 | AE34: 663 | AF34: 489 | AH34: =SUM(S34:V34) | AI34: =SUM(W34:Z34)
C35: (Increase) decrease in other current and long-term assets | E35: 18 | F35: =66-E35 | G35: =64-SUM(E35:F35) | H35: =AB35-SUM(E35:G35) | I35: -1 | J35: =35-I35 | K35: =36-SUM(I35:J35) | L35: =AC35-SUM(I35:K35) | M35: 3 | N35: =15-M35 | O35: =-8-SUM(M35:N35) | P35: =AD35-SUM(M35:O35) | Q35: -2 | R35: =14-Q35 | S35: =16-SUM(Q35:R35) | T35: =AE35-SUM(Q35:S35) | U35: -16 | V35: =16-U35 | W35: =4-SUM(U35:V35) | X35: =AF35-SUM(U35:W35) | Y35: -38 | Z35: =-120-Y35 | AB35: 68 | AC35: 27 | AD35: 16 | AE35: -14 | AF35: 9 | AH35: =SUM(S35:V35) | AI35: =SUM(W35:Z35)
C36: Increase (decrease) in accounts payable | E36: -31 | F36: =-33-E36 | G36: =74-SUM(E36:F36) | H36: =AB36-SUM(E36:G36) | I36: 111 | J36: =172-I36 | K36: =198-SUM(I36:J36) | L36: =AC36-SUM(I36:K36) | M36: -41 | N36: =-290-M36 | O36: =-290-SUM(M36:N36) | P36: =AD36-SUM(M36:O36) | Q36: 17 | R36: =-88-Q36 | S36: =-143-SUM(Q36:R36) | T36: =AE36-SUM(Q36:S36) | U36: 89 | V36: =25-U36 | W36: =4-SUM(U36:V36) | X36: =AF36-SUM(U36:W36) | Y36: 58 | Z36: =-30-Y36 | AB36: 118 | AC36: 278 | AD36: -290 | AE36: -48 | AF36: 24 | AH36: =SUM(S36:V36) | AI36: =SUM(W36:Z36)
C37: Increase (decrease) in accrued compensation | E37: -36 | F37: =-35-E37 | G37: =-56-SUM(E37:F37) | H37: =AB37-SUM(E37:G37) | I37: 22 | J37: =7-I37 | K37: =29-SUM(I37:J37) | L37: =AC37-SUM(I37:K37) | M37: -16 | N37: =-7-M37 | O37: =16-SUM(M37:N37) | P37: =AD37-SUM(M37:O37) | Q37: -86 | R37: =-93-Q37 | S37: =-78-SUM(Q37:R37) | T37: =AE37-SUM(Q37:S37) | U37: -30 | V37: =-51-U37 | W37: =-39-SUM(U37:V37) | X37: =AF37-SUM(U37:W37) | Y37: -8 | Z37: =18-Y37 | AB37: -95 | AC37: 34 | AD37: 48 | AE37: -78 | AF37: -53 | AH37: =SUM(S37:V37) | AI37: =SUM(W37:Z37)
C38: Increase (decrease) in other current and long-term liabilities | E38: -35 | F38: =92-E38 | G38: =80-SUM(E38:F38) | H38: =AB38-SUM(E38:G38) | I38: -43 | J38: =-48-I38 | K38: =-73-SUM(I38:J38) | L38: =AC38-SUM(I38:K38) | M38: -128 | N38: =-139-M38 | O38: =-159-SUM(M38:N38) | P38: =AD38-SUM(M38:O38) | Q38: -77 | R38: =-52-Q38 | S38: =-83-SUM(Q38:R38) | T38: =AE38-SUM(Q38:S38) | U38: -48 | V38: =-40-U38 | W38: =58-SUM(U38:V38) | X38: =AF38-SUM(U38:W38) | Y38: -9 | Z38: =6-Y38 | AB38: 89 | AC38: 9 | AD38: -114 | AE38: -47 | AF38: 33 | AH38: =SUM(S38:V38) | AI38: =SUM(W38:Z38)
C39: Net change in income tax assets and liabilities (incl. deferred taxes) | E39: 6 | F39: =2-E39 | G39: =-11-SUM(E39:F39) | H39: =AB39-SUM(E39:G39) | I39: -39 | J39: =-76-I39 | K39: =-81-SUM(I39:J39) | L39: =AC39-SUM(I39:K39) | M39: 18 | N39: =-17-M39 | O39: =-24-SUM(M39:N39) | P39: =AD39-SUM(M39:O39) | Q39: -44 | R39: =-64-Q39 | S39: =44-SUM(Q39:R39) | T39: =AE39-SUM(Q39:S39) | U39: -2 | V39: =35-U39 | W39: =479-SUM(U39:V39) | X39: =AF39-SUM(U39:W39) | Y39: 12 | Z39: =6-Y39 | AB39: =10-89 | AC39: =-27-27 | AD39: =-12-68 | AE39: =-50+90 | AF39: =-26+502 | AH39: =SUM(S39:V39) | AI39: =SUM(W39:Z39)
C40: Net change in derivative assets and liabilities | E40: 3 | F40: =-2-E40 | G40: =-1-SUM(E40:F40) | H40: =AB40-SUM(E40:G40) | I40: 7 | J40: =-6-I40 | K40: =-10-SUM(I40:J40) | L40: =AC40-SUM(I40:K40) | M40: 13 | N40: =22-M40 | O40: =16-SUM(M40:N40) | P40: =AD40-SUM(M40:O40) | Q40: 6 | R40: =6-Q40 | S40: =9-SUM(Q40:R40) | T40: =AE40-SUM(Q40:S40) | U40: 0 | V40: =-2-U40 | W40: =-1-SUM(U40:V40) | X40: =AF40-SUM(U40:W40) | AB40: 2 | AC40: -22 | AD40: 13 | AE40: 10 | AF40: -12 | AH40: =SUM(S40:V40) | AI40: =SUM(W40:Z40)
C41: Other operating, net | E41: -11 | F41: =-17-E41 | G41: =-10-SUM(E41:F41) | H41: =AB41-SUM(E41:G41) | I41: 5 | J41: =-9-I41 | K41: =-7-SUM(I41:J41) | L41: =AC41-SUM(I41:K41) | M41: 8 | N41: =-11-M41 | O41: =0-SUM(M41:N41) | P41: =AD41-SUM(M41:O41) | Q41: -5 | R41: =-7-Q41 | S41: =0-SUM(Q41:R41) | T41: =AE41-SUM(Q41:S41) | U41: 11 | V41: =28-U41 | W41: =46-SUM(U41:V41) | X41: =AF41-SUM(U41:W41) | Y41: -14 | Z41: =4-Y41 | AB41: -17 | AC41: 13 | AD41: 13 | AE41: -13 | AF41: 35 | AH41: =SUM(S41:V41) | AI41: =SUM(W41:Z41)
C42: Net cash provided by (used in) operating activities | E42: =SUM(E14:E41) | F42: =SUM(F14:F41) | G42: =SUM(G14:G41) | H42: =SUM(H14:H41) | I42: =SUM(I14:I41) | J42: =SUM(J14:J41) | K42: =SUM(K14:K41) | L42: =SUM(L14:L41) | ... Z42: =SUM(Z14:Z41) | AB42: =SUM(AB14:AB41) | AC42: =SUM(AC14:AC41) | AD42: =SUM(AD14:AD41) | AE42: =SUM(AE14:AE41) | AF42: =SUM(AF14:AF41) | AH42: =SUM(AH14:AH41) | AI42: =SUM(AI14:AI41)
C43: Net cash provided by (used in) operating activities | E43: 117 | F43: =331-117 | G43: =431-331 | H43: =629-431 | I43: 66 | J43: =-19-66 | K43: =-27-(-19) | L43: =159-(-27) | M43: 78 | N43: =173-78 | O43: =297-173 | P43: =686-297 | Q43: -79 | R43: =44-(-79) | S43: =160-44 | T43: =511-160 | U43: -89 | V43: =-100-(-89) | W43: =16-(-100) | X43: =224-16 | Y43: -144 | Z43: =-107-(-144) | AB43: 629 | AC43: 159 | AD43: 686 | AE43: 511 | AF43: 224 | AH43: =SUM(S43:V43) | AI43: =SUM(W43:Z43)
C44: Check | E44: =E42-E43 | F44: =F42-F43 | G44: =G42-G43 | H44: =H42-H43 | I44: =I42-I43 | J44: =J42-J43 | K44: =K42-K43 | L44: =L42-L43 | ... Z44: =Z42-Z43 | AB44: =AB42-AB43 | AC44: =AC42-AC43 | AD44: =AD42-AD43 | AE44: =AE42-AE43 | AF44: =AF42-AF43
...

Sheet Financial Statement Outputs >
A1: Financial Statements > | B1: ='Cover Page'!A1

Sheet Income Statement Output
A1: =C3 | B1: ='Cover Page'!A1
C3: Income Statement Summary | J3: Xerox Holdings Corporation
C4: All values in $ millions (USD)
A8: x | B8: x | C8: Income Statement Summary | D8: Fiscal Year Ended | I8: LTM
D9: 2021 | E9: 2022 | F9: 2023 | G9: 2024 | H9: 2025 | I9: LTM 2Q'25 | J9: LTM 2Q'26
C11: Sales | D11: ='Income Statement'!AA10 | E11: ='Income Statement'!AB10 | F11: ='Income Statement'!AC10 | G11: ='Income Statement'!AD10 | H11: ='Income Statement'!AE10 | I11: ='Income Statement'!AG10 | J11: ='Income Statement'!AH10
C12: Services, maintenance, rentals and other | D12: ='Income Statement'!AA11 | E12: ='Income Statement'!AB11 | F12: ='Income Statement'!AC11 | G12: ='Income Statement'!AD11 | H12: ='Income Statement'!AE11 | I12: ='Income Statement'!AG11 | J12: ='Income Statement'!AH11
C13: Total revenues | D13: =D11+D12 | E13: =E11+E12 | F13: =F11+F12 | G13: =G11+G12 | H13: =H11+H12 | I13: =I11+I12 | J13: =J11+J12
C14: Cost of revenues | D14: =-'Income Statement'!AA17 | E14: =-'Income Statement'!AB17 | F14: =-'Income Statement'!AC17 | G14: =-'Income Statement'!AD17 | H14: =-'Income Statement'!AE17 | I14: =-'Income Statement'!AG17 | J14: =-'Income Statement'!AH17
C15: Gross profit | D15: =D13+D14 | E15: =E13+E14 | F15: =F13+F14 | G15: =G13+G14 | H15: =H13+H14 | I15: =I13+I14 | J15: =J13+J14
C16: Research, development and engineering | D16: =-'Income Statement'!AA19 | E16: =-'Income Statement'!AB19 | F16: =-'Income Statement'!AC19 | G16: =-'Income Statement'!AD19 | H16: =-'Income Statement'!AE19 | I16: =-'Income Statement'!AG19 | J16: =-'Income Statement'!AH19
C17: Selling, administrative and general | D17: =-'Income Statement'!AA20 | E17: =-'Income Statement'!AB20 | F17: =-'Income Statement'!AC20 | G17: =-'Income Statement'!AD20 | H17: =-'Income Statement'!AE20 | I17: =-'Income Statement'!AG20 | J17: =-'Income Statement'!AH20
C18: Restructuring and related costs, net | D18: =-'Income Statement'!AA22 | E18: =-'Income Statement'!AB22 | F18: =-'Income Statement'!AC22 | G18: =-'Income Statement'!AD22 | H18: =-'Income Statement'!AE22 | I18: =-'Income Statement'!AG22 | J18: =-'Income Statement'!AH22
C19: Amortization of intangible assets | D19: =-'Income Statement'!AA23 | E19: =-'Income Statement'!AB23 | F19: =-'Income Statement'!AC23 | G19: =-'Income Statement'!AD23 | H19: =-'Income Statement'!AE23 | I19: =-'Income Statement'!AG23 | J19: =-'Income Statement'!AH23
C20: Divestitures | D20: =-'Income Statement'!AA24 | E20: =-'Income Statement'!AB24 | F20: =-'Income Statement'!AC24 | G20: =-'Income Statement'!AD24 | H20: =-'Income Statement'!AE24 | I20: =-'Income Statement'!AG24 | J20: =-'Income Statement'!AH24
C21: PARC donation | D21: =-'Income Statement'!AA25 | E21: =-'Income Statement'!AB25 | F21: =-'Income Statement'!AC25 | G21: =-'Income Statement'!AD25 | H21: =-'Income Statement'!AE25 | I21: =-'Income Statement'!AG25 | J21: =-'Income Statement'!AH25
C22: Depreciation and amortization (add-back) | D22: ='Income Statement'!AA43 | E22: ='Income Statement'!AB43 | F22: ='Income Statement'!AC43 | G22: ='Income Statement'!AD43 | H22: ='Income Statement'!AE43 | I22: ='Income Statement'!AG43 | J22: ='Income Statement'!AH43
C23: EBITDA | D23: =D15+SUM(D16:D22) | E23: =E15+SUM(E16:E22) | F23: =F15+SUM(F16:F22) | G23: =G15+SUM(G16:G22) | H23: =H15+SUM(H16:H22) | I23: =I15+SUM(I16:I22) | J23: =J15+SUM(J16:J22)
C24: Stock-based compensation | D24: ='Income Statement'!AA46 | E24: ='Income Statement'!AB46 | F24: ='Income Statement'!AC46 | G24: ='Income Statement'!AD46 | H24: ='Income Statement'!AE46 | I24: ='Income Statement'!AG46 | J24: ='Income Statement'!AH46
C25: Restructuring and related costs, net | D25: ='Income Statement'!AA22 | E25: ='Income Statement'!AB22 | F25: ='Income Statement'!AC22 | G25: ='Income Statement'!AD22 | H25: ='Income Statement'!AE22 | I25: ='Income Statement'!AG22 | J25: ='Income Statement'!AH22
C26: PARC donation | D26: ='Income Statement'!AA25 | E26: ='Income Statement'!AB25 | F26: ='Income Statement'!AC25 | G26: ='Income Statement'!AD25 | H26: ='Income Statement'!AE25 | I26: ='Income Statement'!AG25 | J26: ='Income Statement'!AH25
C27: Divestitures | D27: ='Income Statement'!AA24 | E27: ='Income Statement'!AB24 | F27: ='Income Statement'!AC24 | G27: ='Income Statement'!AD24 | H27: ='Income Statement'!AE24 | I27: ='Income Statement'!AG24 | J27: ='Income Statement'!AH24
C28: Transformation-related costs | D28: ='Income Statement'!AA50 | E28: ='Income Statement'!AB50 | F28: ='Income Statement'!AC50 | G28: ='Income Statement'!AD50 | H28: ='Income Statement'!AE50 | I28: ='Income Statement'!AG50 | J28: ='Income Statement'!AH50
C29: Transaction and related costs, net | D29: ='Income Statement'!AA51 | E29: ='Income Statement'!AB51 | F29: ='Income Statement'!AC51 | G29: ='Income Statement'!AD51 | H29: ='Income Statement'!AE51 | I29: ='Income Statement'!AG51 | J29: ='Income Statement'!AH51
C30: Inventory impact, exit of Production Print manufacturing | D30: ='Income Statement'!AA52 | E30: ='Income Statement'!AB52 | F30: ='Income Statement'!AC52 | G30: ='Income Statement'!AD52 | H30: ='Income Statement'!AE52 | I30: ='Income Statement'!AG52 | J30: ='Income Statement'!AH52
C31: Lexmark inventory purchase accounting adjustment | D31: ='Income Statement'!AA53 | E31: ='Income Statement'!AB53 | F31: ='Income Statement'!AC53 | G31: ='Income Statement'!AD53 | H31: ='Income Statement'!AE53 | I31: ='Income Statement'!AG53 | J31: ='Income Statement'!AH53
C32: Lexmark settlement of pre-existing employment agreements | D32: ='Income Statement'!AA54 | E32: ='Income Statement'!AB54 | F32: ='Income Statement'!AC54 | G32: ='Income Statement'!AD54 | H32: ='Income Statement'!AE54 | I32: ='Income Statement'!AG54 | J32: ='Income Statement'!AH54
C33: Adjusted EBITDA | D33: =D23+SUM(D24:D32) | E33: =E23+SUM(E24:E32) | F33: =F23+SUM(F24:F32) | G33: =G23+SUM(G24:G32) | H33: =H23+SUM(H24:H32) | I33: =I23+SUM(I24:I32) | J33: =J23+SUM(J24:J32)
C34: IS Adjusted EBITDA | D34: ='Income Statement'!AA55 | E34: ='Income Statement'!AB55 | F34: ='Income Statement'!AC55 | G34: ='Income Statement'!AD55 | H34: ='Income Statement'!AE55 | I34: ='Income Statement'!AG55 | J34: ='Income Statement'!AH55
C35: Check | D35: =D33-D34 | E35: =E33-E34 | F35: =F33-F34 | G35: =G33-G34 | H35: =H33-H34 | I35: =I33-I34 | J35: =J33-J34
C36: Less: IEEPA tariff refund benefit | D36: ='Income Statement'!AA56 | E36: ='Income Statement'!AB56 | F36: ='Income Statement'!AC56 | G36: ='Income Statement'!AD56 | H36: ='Income Statement'!AE56 | I36: ='Income Statement'!AG56 | J36: ='Income Statement'!AH56
B37: x | C37: Adjusted EBITDA excl. IEEPA tariff benefit | D37: =D33+D36 | E37: =E33+E36 | F37: =F33+F36 | G37: =G33+G36 | H37: =H33+H36 | I37: =I33+I36 | J37: =J33+J36
C39: Memo:
C40: Total revenue growth (YoY) | E40: =E13/D13-1 | F40: =F13/E13-1 | G40: =G13/F13-1 | H40: =H13/G13-1 | I40: ='Income Statement'!AG60 | J40: ='Income Statement'!AH60
C41: Gross margin % | D41: =D15/D13 | E41: =E15/E13 | F41: =F15/F13 | G41: =G15/G13 | H41: =H15/H13 | I41: =I15/I13 | J41: =J15/J13
C42: EBITDA margin % | D42: =D23/D13 | E42: =E23/E13 | F42: =F23/F13 | G42: =G23/G13 | H42: =H23/H13 | I42: =I23/I13 | J42: =J23/J13
C43: Adjusted EBITDA margin % | D43: =D33/D13 | E43: =E33/E13 | F43: =F33/F13 | G43: =G33/G13 | H43: =H33/H13 | I43: =I33/I13 | J43: =J33/J13
A44: x | B44: x | C44: Adjusted EBITDA excl. IEEPA margin % | D44: =D37/D13 | E44: =E37/E13 | F44: =F37/F13 | G44: =G37/G13 | H44: =H37/H13 | I44: =I37/I13 | J44: =J37/J13
A45: End

Sheet Balance Sheet Output
A1: =C3 | B1: ='Cover Page'!A1
C3: Balance Sheet Summary | J3: Xerox Holdings Corporation
C4: All values in $ millions (USD)
A7: x | B7: x | C7: Balance Sheet Summary | D7: Fiscal Year Ended December 31, | E7: Fiscal Year | I7: Quarter Ended
D9: 2021 | E9: 2022 | F9: 2023 | G9: 2024 | H9: 2025 | I9: 2Q'25 | J9: 2Q'26
C11: Cash and cash equivalents | D11: =SUMIFS('Balance Sheet'!$E$13:$AF$13,'Balance Sheet'!$E$10:$AF$10,D$9) | E11: =SUMIFS('Balance Sheet'!$E$13:$AF$13,'Balance Sheet'!$E$10:$AF$10,E$9) | F11: =SUMIFS('Balance Sheet'!$E$13:$AF$13,'Balance Sheet'!$E$10:$AF$10,F$9) | G11: =SUMIFS('Balance Sheet'!$E$13:$AF$13,'Balance Sheet'!$E$10:$AF$10,G$9) | H11: =SUMIFS('Balance Sheet'!$E$13:$AF$13,'Balance Sheet'!$E$10:$AF$10,H$9) | I11: =SUMIFS('Balance Sheet'!$E$13:$AF$13,'Balance Sheet'!$E$10:$AF$10,I$9) | J11: =SUMIFS('Balance Sheet'!$E$13:$AF$13,'Balance Sheet'!$E$10:$AF$10,J$9)
C12: Accounts receivable, net | D12: =SUMIFS('Balance Sheet'!$E$14:$AF$14,'Balance Sheet'!$E$10:$AF$10,D$9) | E12: =SUMIFS('Balance Sheet'!$E$14:$AF$14,'Balance Sheet'!$E$10:$AF$10,E$9) | F12: =SUMIFS('Balance Sheet'!$E$14:$AF$14,'Balance Sheet'!$E$10:$AF$10,F$9) | G12: =SUMIFS('Balance Sheet'!$E$14:$AF$14,'Balance Sheet'!$E$10:$AF$10,G$9) | H12: =SUMIFS('Balance Sheet'!$E$14:$AF$14,'Balance Sheet'!$E$10:$AF$10,H$9) | I12: =SUMIFS('Balance Sheet'!$E$14:$AF$14,'Balance Sheet'!$E$10:$AF$10,I$9) | J12: =SUMIFS('Balance Sheet'!$E$14:$AF$14,'Balance Sheet'!$E$10:$AF$10,J$9)
C13: Billed portion of finance receivables, net | D13: =SUMIFS('Balance Sheet'!$E$15:$AF$15,'Balance Sheet'!$E$10:$AF$10,D$9) | E13: =SUMIFS('Balance Sheet'!$E$15:$AF$15,'Balance Sheet'!$E$10:$AF$10,E$9) | F13: =SUMIFS('Balance Sheet'!$E$15:$AF$15,'Balance Sheet'!$E$10:$AF$10,F$9) | G13: =SUMIFS('Balance Sheet'!$E$15:$AF$15,'Balance Sheet'!$E$10:$AF$10,G$9) | H13: =SUMIFS('Balance Sheet'!$E$15:$AF$15,'Balance Sheet'!$E$10:$AF$10,H$9) | I13: =SUMIFS('Balance Sheet'!$E$15:$AF$15,'Balance Sheet'!$E$10:$AF$10,I$9) | J13: =SUMIFS('Balance Sheet'!$E$15:$AF$15,'Balance Sheet'!$E$10:$AF$10,J$9)
C14: Finance receivables, net | D14: =SUMIFS('Balance Sheet'!$E$16:$AF$16,'Balance Sheet'!$E$10:$AF$10,D$9) | E14: =SUMIFS('Balance Sheet'!$E$16:$AF$16,'Balance Sheet'!$E$10:$AF$10,E$9) | F14: =SUMIFS('Balance Sheet'!$E$16:$AF$16,'Balance Sheet'!$E$10:$AF$10,F$9) | G14: =SUMIFS('Balance Sheet'!$E$16:$AF$16,'Balance Sheet'!$E$10:$AF$10,G$9) | H14: =SUMIFS('Balance Sheet'!$E$16:$AF$16,'Balance Sheet'!$E$10:$AF$10,H$9) | I14: =SUMIFS('Balance Sheet'!$E$16:$AF$16,'Balance Sheet'!$E$10:$AF$10,I$9) | J14: =SUMIFS('Balance Sheet'!$E$16:$AF$16,'Balance Sheet'!$E$10:$AF$10,J$9)
C15: Inventories | D15: =SUMIFS('Balance Sheet'!$E$17:$AF$17,'Balance Sheet'!$E$10:$AF$10,D$9) | E15: =SUMIFS('Balance Sheet'!$E$17:$AF$17,'Balance Sheet'!$E$10:$AF$10,E$9) | F15: =SUMIFS('Balance Sheet'!$E$17:$AF$17,'Balance Sheet'!$E$10:$AF$10,F$9) | G15: =SUMIFS('Balance Sheet'!$E$17:$AF$17,'Balance Sheet'!$E$10:$AF$10,G$9) | H15: =SUMIFS('Balance Sheet'!$E$17:$AF$17,'Balance Sheet'!$E$10:$AF$10,H$9) | I15: =SUMIFS('Balance Sheet'!$E$17:$AF$17,'Balance Sheet'!$E$10:$AF$10,I$9) | J15: =SUMIFS('Balance Sheet'!$E$17:$AF$17,'Balance Sheet'!$E$10:$AF$10,J$9)
C16: Other current assets | D16: =SUMIFS('Balance Sheet'!$E$18:$AF$18,'Balance Sheet'!$E$10:$AF$10,D$9) | E16: =SUMIFS('Balance Sheet'!$E$18:$AF$18,'Balance Sheet'!$E$10:$AF$10,E$9) | F16: =SUMIFS('Balance Sheet'!$E$18:$AF$18,'Balance Sheet'!$E$10:$AF$10,F$9) | G16: =SUMIFS('Balance Sheet'!$E$18:$AF$18,'Balance Sheet'!$E$10:$AF$10,G$9) | H16: =SUMIFS('Balance Sheet'!$E$18:$AF$18,'Balance Sheet'!$E$10:$AF$10,H$9) | I16: =SUMIFS('Balance Sheet'!$E$18:$AF$18,'Balance Sheet'!$E$10:$AF$10,I$9) | J16: =SUMIFS('Balance Sheet'!$E$18:$AF$18,'Balance Sheet'!$E$10:$AF$10,J$9)
C17: Total current assets | D17: =SUM(D11:D16) | E17: =SUM(E11:E16) | F17: =SUM(F11:F16) | G17: =SUM(G11:G16) | H17: =SUM(H11:H16) | I17: =SUM(I11:I16) | J17: =SUM(J11:J16)
C18: Finance receivables due after one year, net | D18: =SUMIFS('Balance Sheet'!$E$22:$AF$22,'Balance Sheet'!$E$10:$AF$10,D$9) | E18: =SUMIFS('Balance Sheet'!$E$22:$AF$22,'Balance Sheet'!$E$10:$AF$10,E$9) | F18: =SUMIFS('Balance Sheet'!$E$22:$AF$22,'Balance Sheet'!$E$10:$AF$10,F$9) | G18: =SUMIFS('Balance Sheet'!$E$22:$AF$22,'Balance Sheet'!$E$10:$AF$10,G$9) | H18: =SUMIFS('Balance Sheet'!$E$22:$AF$22,'Balance Sheet'!$E$10:$AF$10,H$9) | I18: =SUMIFS('Balance Sheet'!$E$22:$AF$22,'Balance Sheet'!$E$10:$AF$10,I$9) | J18: =SUMIFS('Balance Sheet'!$E$22:$AF$22,'Balance Sheet'!$E$10:$AF$10,J$9)
C19: Equipment on operating leases, net | D19: =SUMIFS('Balance Sheet'!$E$23:$AF$23,'Balance Sheet'!$E$10:$AF$10,D$9) | E19: =SUMIFS('Balance Sheet'!$E$23:$AF$23,'Balance Sheet'!$E$10:$AF$10,E$9) | F19: =SUMIFS('Balance Sheet'!$E$23:$AF$23,'Balance Sheet'!$E$10:$AF$10,F$9) | G19: =SUMIFS('Balance Sheet'!$E$23:$AF$23,'Balance Sheet'!$E$10:$AF$10,G$9) | H19: =SUMIFS('Balance Sheet'!$E$23:$AF$23,'Balance Sheet'!$E$10:$AF$10,H$9) | I19: =SUMIFS('Balance Sheet'!$E$23:$AF$23,'Balance Sheet'!$E$10:$AF$10,I$9) | J19: =SUMIFS('Balance Sheet'!$E$23:$AF$23,'Balance Sheet'!$E$10:$AF$10,J$9)
C20: Land, buildings and equipment, net | D20: =SUMIFS('Balance Sheet'!$E$24:$AF$24,'Balance Sheet'!$E$10:$AF$10,D$9) | E20: =SUMIFS('Balance Sheet'!$E$24:$AF$24,'Balance Sheet'!$E$10:$AF$10,E$9) | F20: =SUMIFS('Balance Sheet'!$E$24:$AF$24,'Balance Sheet'!$E$10:$AF$10,F$9) | G20: =SUMIFS('Balance Sheet'!$E$24:$AF$24,'Balance Sheet'!$E$10:$AF$10,G$9) | H20: =SUMIFS('Balance Sheet'!$E$24:$AF$24,'Balance Sheet'!$E$10:$AF$10,H$9) | I20: =SUMIFS('Balance Sheet'!$E$24:$AF$24,'Balance Sheet'!$E$10:$AF$10,I$9) | J20: =SUMIFS('Balance Sheet'!$E$24:$AF$24,'Balance Sheet'!$E$10:$AF$10,J$9)
C21: Intangible assets, net | D21: =SUMIFS('Balance Sheet'!$E$25:$AF$25,'Balance Sheet'!$E$10:$AF$10,D$9) | E21: =SUMIFS('Balance Sheet'!$E$25:$AF$25,'Balance Sheet'!$E$10:$AF$10,E$9) | F21: =SUMIFS('Balance Sheet'!$E$25:$AF$25,'Balance Sheet'!$E$10:$AF$10,F$9) | G21: =SUMIFS('Balance Sheet'!$E$25:$AF$25,'Balance Sheet'!$E$10:$AF$10,G$9) | H21: =SUMIFS('Balance Sheet'!$E$25:$AF$25,'Balance Sheet'!$E$10:$AF$10,H$9) | I21: =SUMIFS('Balance Sheet'!$E$25:$AF$25,'Balance Sheet'!$E$10:$AF$10,I$9) | J21: =SUMIFS('Balance Sheet'!$E$25:$AF$25,'Balance Sheet'!$E$10:$AF$10,J$9)
C22: Goodwill, net | D22: =SUMIFS('Balance Sheet'!$E$26:$AF$26,'Balance Sheet'!$E$10:$AF$10,D$9) | E22: =SUMIFS('Balance Sheet'!$E$26:$AF$26,'Balance Sheet'!$E$10:$AF$10,E$9) | F22: =SUMIFS('Balance Sheet'!$E$26:$AF$26,'Balance Sheet'!$E$10:$AF$10,F$9) | G22: =SUMIFS('Balance Sheet'!$E$26:$AF$26,'Balance Sheet'!$E$10:$AF$10,G$9) | H22: =SUMIFS('Balance Sheet'!$E$26:$AF$26,'Balance Sheet'!$E$10:$AF$10,H$9) | I22: =SUMIFS('Balance Sheet'!$E$26:$AF$26,'Balance Sheet'!$E$10:$AF$10,I$9) | J22: =SUMIFS('Balance Sheet'!$E$26:$AF$26,'Balance Sheet'!$E$10:$AF$10,J$9)
C23: Deferred tax assets | D23: =SUMIFS('Balance Sheet'!$E$27:$AF$27,'Balance Sheet'!$E$10:$AF$10,D$9) | E23: =SUMIFS('Balance Sheet'!$E$27:$AF$27,'Balance Sheet'!$E$10:$AF$10,E$9) | F23: =SUMIFS('Balance Sheet'!$E$27:$AF$27,'Balance Sheet'!$E$10:$AF$10,F$9) | G23: =SUMIFS('Balance Sheet'!$E$27:$AF$27,'Balance Sheet'!$E$10:$AF$10,G$9) | H23: =SUMIFS('Balance Sheet'!$E$27:$AF$27,'Balance Sheet'!$E$10:$AF$10,H$9) | I23: =SUMIFS('Balance Sheet'!$E$27:$AF$27,'Balance Sheet'!$E$10:$AF$10,I$9) | J23: =SUMIFS('Balance Sheet'!$E$27:$AF$27,'Balance Sheet'!$E$10:$AF$10,J$9)
C24: Other long-term assets | D24: =SUMIFS('Balance Sheet'!$E$28:$AF$28,'Balance Sheet'!$E$10:$AF$10,D$9) | E24: =SUMIFS('Balance Sheet'!$E$28:$AF$28,'Balance Sheet'!$E$10:$AF$10,E$9) | F24: =SUMIFS('Balance Sheet'!$E$28:$AF$28,'Balance Sheet'!$E$10:$AF$10,F$9) | G24: =SUMIFS('Balance Sheet'!$E$28:$AF$28,'Balance Sheet'!$E$10:$AF$10,G$9) | H24: =SUMIFS('Balance Sheet'!$E$28:$AF$28,'Balance Sheet'!$E$10:$AF$10,H$9) | I24: =SUMIFS('Balance Sheet'!$E$28:$AF$28,'Balance Sheet'!$E$10:$AF$10,I$9) | J24: =SUMIFS('Balance Sheet'!$E$28:$AF$28,'Balance Sheet'!$E$10:$AF$10,J$9)
C25: Total assets | D25: =D17+SUM(D18:D24) | E25: =E17+SUM(E18:E24) | F25: =F17+SUM(F18:F24) | G25: =G17+SUM(G18:G24) | H25: =H17+SUM(H18:H24) | I25: =I17+SUM(I18:I24) | J25: =J17+SUM(J18:J24)
